Workbook

Sheet DE ( Tarik barang retur )
A1: requested_tracking_number | B1: global_shipper_id | C1: service_type | D1: reference.merchant_order_number | E1: service_level | F1: from.name | G1: from.phone_number | H1: from.address.address1 | I1: from.address.country | J1: to.name | K1: to.phone_number | L1: to.address.address1 | M1: to.address.country | N1: to.address.kecamatan | O1: to.address.city | P1: to.address.province | Q1: to.address.postcode | R1: parcel_job.delivery_instructions | S1: parcel_job.delivery_start_date | T1: parcel_job.delivery_timeslot.start_time | U1: parcel_job.delivery_timeslot.end_time | V1: parcel_job.delivery_timeslot.timezone | W1: parcel_job.dimensions.weight | X1: parcel_job.is_pickup_required | Y1: parcel_job.items.0.item_description | Z1: parcel_job.items.0.is_dangerous_good | AA1: b2b.documents_required | AB1: bundle_information.total_quantity | AC1: bundle_information.requested_piece_tracking_numbers | AD1: parcel_job.insured_value | AE1: corporate.branch_id | AF1: parcel_job.pickup_date | AG1: parcel_job.pickup_timeslot.start_time | AH1: parcel_job.pickup_timeslot.end_time | AI1: parcel_job.pickup_timeslot.timezone | AJ1: parcel_job.pickup_instructions
A2: AWBR-10859-2026-4-17 | B2: 11398423 | C2: Corporate B2B Bundle | D2: 26033013582985PgyfIVBK | E2: STANDARD | F2: Apotek Citayam Farma Bojong Pondok Terong Cipayung | G2: 6.28517e+17 | H2: Jl. Raya Cipayung No.1, RT.03/RW10, Desa/Kel. Bojong Pondok Terong, Kec. Cipayung, Kota Depok 16436 | I2: ID | J2: PT Teknologi Medika Pratama (SwipeRx) (B2BR) | K2: 87733785699 | L2: Jl. Tugu Raya, Tugu, Kec. Cimanggis, Kota Depok, Jawa Barat 16451,KUBIK LOGISTICS - Kompleks Pergudangan,Gudang E1 | M2: ID | N2: Cimanggis | O2: Depok | P2: Jawa barat | Q2: 16451 | R2: TMP-INV-2026/03/31/ 2586421SGM EKSPLOR GAIN OPTIGROW Sarihusada DUS, ALUMUNIUM FOIL @ 400 GTarik Barang Retur & Wajib bawa BA retur | S2: 46153 | T2: 0.375 | U2: 0.91666667 | V2: Asia/Jakarta | W2: 1 | X2: TRUE | Y2: OBAT | Z2: FALSE | AB2: 1 | AC2: AWBR-10859-2026-4-17-01 | AD2: 0 | AE2: 1 | AF2: 46153 | AG2: 0.375 | AH2: 0.91666667 | AI2: Asia/Jakarta | AJ2: Pickup Return, wajib bawa form BA Return. Bilang ke Apotek “mau tarik barang”. Jika tidak ada barang, tulis keterangan “tidak ada barang retur” di form BA
A3: AWBR-4606-2026-5-11-1 | B3: 11398423 | C3: Corporate B2B Bundle | D3: 25012410200620NHRbykaYKC | E3: STANDARD | F3: Apotek Singojuruh | G3: 6.2853e+16 | H3: Jl Aruji Kartawinata 02/02 Kel.Singojuruh Kec.Singojuruh Kab.Banyuwangi Jawa Timur 68464 | I3: ID | J3: PT Teknologi Medika Pratama (SwipeRx) (B2BR) | K3: 6.28514e+17 | L3: Jl. Rungkut Industri III No.12, Kutisari, Kec. Tenggilis Mejoyo, Surabaya, Jawa Timur 60291 | M3: ID | N3: Tenggilis Mejoyo | O3: Surabaya | P3: Jawa Timur | Q3: 60291 | R3: TMP-INV-2025/01/25/ 1305668 - CURVIT Soho SIRUP - Tarik Barang Retur | S3: 46155 | T3: 0.375 | U3: 0.91666667 | V3: Asia/Jakarta | W3: 1 | X3: TRUE | Y3: OBAT | Z3: FALSE | AB3: 1 | AC3: AWBR-4606-2026-5-11-1-01 | AD3: 0 | AE3: 1 | AF3: 46155 | AG3: 0.375 | AH3: 0.91666667 | AI3: Asia/Jakarta | AJ3: Pickup Return, wajib bawa form BA Return. Bilang ke Apotek “mau tarik barang”. Jika tidak ada barang, tulis keterangan “tidak ada barang retur” di form BA
A4: AWBR-12411-2026-5-16 | B4: 11398423 | C4: Corporate B2B Bundle | D4: 26042802052677jEINi46Brs | E4: STANDARD | F4: Apotek Bintang Sehat 1 Jayamulya Serang Baru | G4: 6.28199e+17 | H4: Perum Grand Vista Blok D1 RT 003 RW 009 Desa Jayamulya Kec. Serang Baru Kab. Bekasi | I4: ID | J4: PT Teknologi Medika Pratama (SwipeRx) (B2BR) | K4: 87733785699 | L4: Jl. Tugu Raya, Tugu, Kec. Cimanggis, Kota Depok, Jawa Barat 16451,KUBIK LOGISTICS - Kompleks Pergudangan,Gudang E1 | M4: ID | N4: Cimanggis | O4: Depok | P4: Jawa barat | Q4: 16451 | R4: TMP-INV-2026/04/28/ 2685534HERBORIST MINYAK ZAITUN Victoria Care BOTOL @ 75 MLTarik Barang Retur | S4: 46158 | T4: 0.375 | U4: 0.91666667 | V4: Asia/Jakarta | W4: 1 | X4: TRUE | Y4: OBAT | Z4: FALSE | AB4: 1 | AC4: AWBR-12411-2026-5-16-01 | AD4: 0 | AE4: 1 | AF4: 46158 | AG4: 0.375 | AH4: 0.91666667 | AI4: Asia/Jakarta | AJ4: Pickup Return, wajib bawa form BA Return. Bilang ke Apotek “mau tarik barang”. Jika tidak ada barang, tulis keterangan “tidak ada barang retur” di form BA
A5: AWBR-12377-2026-5-16 | B5: 11398423 | C5: Corporate B2B Bundle | D5: 26042002141604sR64H1lq | E5: STANDARD | F5: Apotek Bintang Sehat Sukaragam Serang Baru | G5: 6.28125e+17 | H5: Perum Mega Regency Blok H1 No. 30 Desa Sukaragam Kec. Serang Baru Kab. Bekasi | I5: ID | J5: PT Teknologi Medika Pratama (SwipeRx) (B2BR) | K5: 87733785699 | L5: Jl. Tugu Raya, Tugu, Kec. Cimanggis, Kota Depok, Jawa Barat 16451,KUBIK LOGISTICS - Kompleks Pergudangan,Gudang E1 | M5: ID | N5: Cimanggis | O5: Depok | P5: Jawa barat | Q5: 16451 | R5: TMP-INV-2026/04/20/ 2655815Tarik Barang Retur | S5: 46158 | T5: 0.375 | U5: 0.91666667 | V5: Asia/Jakarta | W5: 1 | X5: TRUE | Y5: OBAT | Z5: FALSE | AB5: 1 | AC5: AWBR-12377-2026-5-16-01 | AD5: 0 | AE5: 1 | AF5: 46158 | AG5: 0.375 | AH5: 0.91666667 | AI5: Asia/Jakarta | AJ5: Pickup Return, wajib bawa form BA Return. Bilang ke Apotek “mau tarik barang”. Jika tidak ada barang, tulis keterangan “tidak ada barang retur” di form BA
A6: AWBR-10720-2026-5-16 | B6: 11398423 | C6: Corporate B2B Bundle | D6: 26040605461503nMH7TsTY9j | E6: STANDARD | F6: Apotek K24 Sukasari Sukasari Serang Baru | G6: 81776481573 | H6: Ruko Serang-Cibarusah No. 3 Jl. Raya Serang Cibarusah Kp. Pasar Randu, Kel. Sukasari Kec. Serang Baru Kab. Bekasi 17330 | I6: ID | J6: PT Teknologi Medika Pratama (SwipeRx) (B2BR) | K6: 87733785699 | L6: Jl. Tugu Raya, Tugu, Kec. Cimanggis, Kota Depok, Jawa Barat 16451,KUBIK LOGISTICS - Kompleks Pergudangan,Gudang E1 | M6: ID | N6: Cimanggis | O6: Depok | P6: Jawa barat | Q6: 16451 | R6: TMP-INV-2026/04/07/ 2610048INTERLAC Interbat DROPS DUS, BOTOL KACA 5 MLTarik Barang Retur | S6: 46158 | T6: 0.375 | U6: 0.91666667 | V6: Asia/Jakarta | W6: 1 | X6: TRUE | Y6: OBAT | Z6: FALSE | AB6: 1 | AC6: AWBR-10720-2026-5-16-01 | AD6: 0 | AE6: 1 | AF6: 46158 | AG6: 0.375 | AH6: 0.91666667 | AI6: Asia/Jakarta | AJ6: Pickup Return, wajib bawa form BA Return. Bilang ke Apotek “mau tarik barang”. Jika tidak ada barang, tulis keterangan “tidak ada barang retur” di form BA
A7: AWBR-16863-2026-5-16 | B7: 11398423 | C7: Corporate B2B Bundle | D7: 26042707183212wZ262nubF | E7: STANDARD | F7: Apotek Enggal Waras Tiga Bojongpicung Bojongpicung | G7: 6.28213e+17 | H7: Kp. Bojongpicung RT. 001 RW. 003 Desa. Bojongpicung Kecamatan. Bojongpicung Kabupaten Cianjur | I7: ID | J7: PT Teknologi Medika Pratama (SwipeRx) (B2BR) | K7: 87733785699 | L7: Jl. Tugu Raya, Tugu, Kec. Cimanggis, Kota Depok, Jawa Barat 16451,KUBIK LOGISTICS - Kompleks Pergudangan,Gudang E1 | M7: ID | N7: Cimanggis | O7: Depok | P7: Jawa barat | Q7: 16451 | R7: TMP-INV-2026/04/28/ 2687857SGM LLM+ DUS, KARTON 400 GTarik Barang Retur | S7: 46158 | T7: 0.375 | U7: 0.91666667 | V7: Asia/Jakarta | W7: 1 | X7: TRUE | Y7: OBAT | Z7: FALSE | AB7: 1 | AC7: AWBR-16863-2026-5-16-01 | AD7: 0 | AE7: 1 | AF7: 46158 | AG7: 0.375 | AH7: 0.91666667 | AI7: Asia/Jakarta | AJ7: Pickup Return, wajib bawa form BA Return. Bilang ke Apotek “mau tarik barang”. Jika tidak ada barang, tulis keterangan “tidak ada barang retur” di form BA
A8: AWBR-8604-2026-5-16 | B8: 11398423 | C8: Corporate B2B Bundle | D8: 26042314484910WriHfjQo | E8: STANDARD | F8: Apotek Rahayu Farma Cinangka Bungursari | G8: 82216766044 | H8: Jl. Cinangka No.23 RT.05 RW.03, Kel. Cinangka, Kec. Bungursari, Kab. Purwakarta, 41181 | I8: ID | J8: PT Teknologi Medika Pratama (SwipeRx) (B2BR) | K8: 87733785699 | L8: Jl. Tugu Raya, Tugu, Kec. Cimanggis, Kota Depok, Jawa Barat 16451,KUBIK LOGISTICS - Kompleks Pergudangan,Gudang E1 | M8: ID | N8: Cimanggis | O8: Depok | P8: Jawa barat | Q8: 16451 | R8: TMP-INV-2026/04/24/ 2674250Semua Barang di Faktur TMP-INV-2026/04/24/ 2674250Tarik Barang Damaged | S8: 46158 | T8: 0.375 | U8: 0.91666667 | V8: Asia/Jakarta | W8: 1 | X8: TRUE | Y8: OBAT | Z8: FALSE | AB8: 1 | AC8: AWBR-8604-2026-5-16-01 | AD8: 0 | AE8: 1 | AF8: 46158 | AG8: 0.375 | AH8: 0.91666667 | AI8: Asia/Jakarta | AJ8: Pickup Return, wajib bawa form BA Return. Bilang ke Apotek “mau tarik barang”. Jika tidak ada barang, tulis keterangan “tidak ada barang retur” di form BA
A9: AWBR-10615-2026-5-16 | B9: 11398423 | C9: Corporate B2B Bundle | D9: 26042003281955evVhe58S | E9: STANDARD | F9: Apotek Cahaya Pratama Nagrak Gunung Putri | G9: 6.28121e+16 | H9: Perumahan Legenda Wisata Cibubur Blok U12 No. 12 Desa Nagrak Kecamatan Gunung Putri Kabupaten Bogor | I9: ID | J9: PT Teknologi Medika Pratama (SwipeRx) (B2BR) | K9: 87733785699 | L9: Jl. Tugu Raya, Tugu, Kec. Cimanggis, Kota Depok, Jawa Barat 16451,KUBIK LOGISTICS - Kompleks Pergudangan,Gudang E1 | M9: ID | N9: Cimanggis | O9: Depok | P9: Jawa barat | Q9: 16451 | R9: TMP-INV-2026/04/20/ 2657865 & ALERZIN 10 Sampharindo TABLET 10 MG DUS, 10 AMPLOP @ 1 STRIP @ 10 TABLET SALUT SELAPUT & ZITANID Novell TABLET 2 MG DUS, 3 STRIP @ 10 TABLETTarik Barang Retur | S9: 46158 | T9: 0.375 | U9: 0.91666667 | V9: Asia/Jakarta | W9: 1 | X9: TRUE | Y9: OBAT | Z9: FALSE | AB9: 1 | AC9: AWBR-10615-2026-5-16-01 | AD9: 0 | AE9: 1 | AF9: 46158 | AG9: 0.375 | AH9: 0.91666667 | AI9: Asia/Jakarta | AJ9: Pickup Return, wajib bawa form BA Return. Bilang ke Apotek “mau tarik barang”. Jika tidak ada barang, tulis keterangan “tidak ada barang retur” di form BA
A10: AWBR-16765-2026-5-16 | B10: 11398423 | C10: Corporate B2B Bundle | D10: 26042812441924lNfuzKSQr | E10: STANDARD | F10: Apotek Madison Sehat Ciangsana Gunung Putri | G10: 6.28121e+17 | H10: Ruko Downtown Madison Blok SHC 8/2, Desa/Kelurahan Ciangsana, Kec. Gunung Putri, Kab. Bogor | I10: ID | J10: PT Teknologi Medika Pratama (SwipeRx) (B2BR) | K10: 87733785699 | L10: Jl. Tugu Raya, Tugu, Kec. Cimanggis, Kota Depok, Jawa Barat 16451,KUBIK LOGISTICS - Kompleks Pergudangan,Gudang E1 | M10: ID | N10: Cimanggis | O10: Depok | P10: Jawa barat | Q10: 16451 | R10: TMP-INV-2026/04/29/ 2689820ROSUVASTATIN CALCIUM Novell TABLET 20 MG DUS, 2 STRIP @ 10 TABLET SALUT SELAPUTTarik Barang Retur | S10: 46158 | T10: 0.375 | U10: 0.91666667 | V10: Asia/Jakarta | W10: 1 | X10: TRUE | Y10: OBAT | Z10: FALSE | AB10: 1 | AC10: AWBR-16765-2026-5-16-01 | AD10: 0 | AE10: 1 | AF10: 46158 | AG10: 0.375 | AH10: 0.91666667 | AI10: Asia/Jakarta | AJ10: Pickup Return, wajib bawa form BA Return. Bilang ke Apotek “mau tarik barang”. Jika tidak ada barang, tulis keterangan “tidak ada barang retur” di form BA
A11: AWBR-1288-2026-5-16 | B11: 11398423 | C11: Corporate B2B Bundle | D11: 26050410225303b1fZxbejo | E11: STANDARD | F11: Apotek Sehat Utama | G11: 8128011014 | H11: Jalan Raya Narogong KM. 22 No. 62 RT 007 RW 005 Desa Cileungsi Kecamatan Cileungsi Kabupaten Bogor 16820 | I11: ID | J11: PT Teknologi Medika Pratama (SwipeRx) (B2BR) | K11: 87733785699 | L11: Jl. Tugu Raya, Tugu, Kec. Cimanggis, Kota Depok, Jawa Barat 16451,KUBIK LOGISTICS - Kompleks Pergudangan,Gudang E1 | M11: ID | N11: Cimanggis | O11: Depok | P11: Jawa barat | Q11: 16451 | R11: TMP-INV-2026/05/05/ 2711278GABAPENTIN Hexpharm KAPSUL 100 MG DUS, 10 STRIP @ 10 KAPSULTarik Barang Retur | S11: 46158 | T11: 0.375 | U11: 0.91666667 | V11: Asia/Jakarta | W11: 1 | X11: TRUE | Y11: OBAT | Z11: FALSE | AB11: 1 | AC11: AWBR-1288-2026-5-16-01 | AD11: 0 | AE11: 1 | AF11: 46158 | AG11: 0.375 | AH11: 0.91666667 | AI11: Asia/Jakarta | AJ11: Pickup Return, wajib bawa form BA Return. Bilang ke Apotek “mau tarik barang”. Jika tidak ada barang, tulis keterangan “tidak ada barang retur” di form BA
A12: AWBR-3040-2026-5-16 | B12: 11398423 | C12: Corporate B2B Bundle | D12: 260501001157611qk7q9kxV | E12: STANDARD | F12: Apotek Tasha Sehat | G12: 87808789981 | H12: Ruko Sentra Eropa Blok D No. 16 Desa Ciangsana Kecamatan Gunung Putri Kabupaten Bogor Provinsi Jawa Barat | I12: ID | J12: PT Teknologi Medika Pratama (SwipeRx) (B2BR) | K12: 87733785699 | L12: Jl. Tugu Raya, Tugu, Kec. Cimanggis, Kota Depok, Jawa Barat 16451,KUBIK LOGISTICS - Kompleks Pergudangan,Gudang E1 | M12: ID | N12: Cimanggis | O12: Depok | P12: Jawa barat | Q12: 16451 | R12: TMP-INV-2026/05/01/ 2697754 & TMP-INV-2026/05/01/ 2697911 HANSAPLAST FUN KAIN ELASTIS Beiersdorf DUS, 100 LEMBAR & L-BIO CAP Lapi KAPSUL DUS, 2 BOTOL PLASTIK @ 15 KAPSULTarik Barang Retur | S12: 46158 | T12: 0.375 | U12: 0.91666667 | V12: Asia/Jakarta | W12: 1 | X12: TRUE | Y12: OBAT | Z12: FALSE | AB12: 1 | AC12: AWBR-3040-2026-5-16-01 | AD12: 0 | AE12: 1 | AF12: 46158 | AG12: 0.375 | AH12: 0.91666667 | AI12: Asia/Jakarta | AJ12: Pickup Return, wajib bawa form BA Return. Bilang ke Apotek “mau tarik barang”. Jika tidak ada barang, tulis keterangan “tidak ada barang retur” di form BA
A13: AWBR-11570-2026-5-16 | B13: 11398423 | C13: Corporate B2B Bundle | D13: 260411030107043MpJcBo2H | E13: STANDARD | F13: Apotek Arjuna Pondok Benda Pamulang | G13: 6.28777e+17 | H13: Jl. Arjuna RT/RW 002/008 NO. 20, Desa/Kelurahan Pondok Benda, Kec. Pamulang, Kota Tangerang Selatan, Provinsi Banten | I13: ID | J13: PT Teknologi Medika Pratama (SwipeRx) (B2BR) | K13: 87733785699 | L13: Jl. Tugu Raya, Tugu, Kec. Cimanggis, Kota Depok, Jawa Barat 16451,KUBIK LOGISTICS - Kompleks Pergudangan,Gudang E1 | M13: ID | N13: Cimanggis | O13: Depok | P13: Jawa barat | Q13: 16451 | R13: TMP-INV-2026/04/11/ 2626726Semua Barang di Faktur TMP-INV-2026/04/11/ 2626726Tarik Barang Retur | S13: 46158 | T13: 0.375 | U13: 0.91666667 | V13: Asia/Jakarta | W13: 1 | X13: TRUE | Y13: OBAT | Z13: FALSE | AB13: 1 | AC13: AWBR-11570-2026-5-16-01 | AD13: 0 | AE13: 1 | AF13: 46158 | AG13: 0.375 | AH13: 0.91666667 | AI13: Asia/Jakarta | AJ13: Pickup Return, wajib bawa form BA Return. Bilang ke Apotek “mau tarik barang”. Jika tidak ada barang, tulis keterangan “tidak ada barang retur” di form BA
... A147: AWBR-3901-2026-5-25 | B147: 11398423 | C147: Corporate B2B Bundle | D147: 26052200495469Fj6vRwDZd | E147: STANDARD | F147: Apotek Syafiya Sengon Jombang | G147: 6.28226e+17 | H147: Jl. Pattimura No. 57, Desa/Kelurahan Sengon , Kec. Jombang, Kab. Jombang, Jawa Timur, 61418 | I147: ID | J147: PT Teknologi Medika Pratama (SwipeRx) (B2BR) | K147: 6.28514e+17 | L147: Jl. Rungkut Industri III No.12, Kutisari, Kec. Tenggilis Mejoyo, Surabaya, Jawa Timur 60291 | M147: ID | N147: Tenggilis Mejoyo | O147: Surabaya | P147: Jawa Timur | Q147: 60291 | R147: TMP-INV-2026/05/22/ 2774483 / BLACKMORES BIO D3 1000 IU Kalbe KAPSUL / Tarik barang retur | S147: 46167 | T147: 0.375 | U147: 0.91666667 | V147: Asia/Jakarta | W147: 1 | X147: TRUE | Y147: OBAT | Z147: FALSE | AB147: 1 | AC147: AWBR-3901-2026-5-25-01 | AD147: 0 | AE147: 1 | AF147: 46167 | AG147: 0.375 | AH147: 0.91666667 | AI147: Asia/Jakarta | AJ147: Pickup Return, wajib bawa form BA Return. Bilang ke Apotek “mau tarik barang”. Jika tidak ada barang, tulis keterangan “tidak ada barang retur” di form BA
A148: AWBR-5547-2026-5-26 | B148: 11398423 | C148: Corporate B2B Bundle | D148: 25072903080956JVg4q99snO | E148: STANDARD | F148: Apotek Asli | G148: 85647789448 | H148: Jalan Cipto Mangunkusumo No. 11 Temanggung 1 Kabupaten Temanggung, Jawa Tengah 56212 | I148: ID | J148: PT Teknologi Medika Pratama (SwipeRx) (B2BR) | K148: 85143002578 | L148: Jl. Rungkut Industri III No.12, Kutisari, Kec. Tenggilis Mejoyo, Surabaya, Jawa Timur 60291 | M148: ID | N148: Tenggilis Mejoyo | O148: Surabaya | P148: Jawa Timur | Q148: 60291 | R148: TMP-INV-2025/07/29/ 1781386 / ANDALAN NUTRIFEMME FOLAMOM Hermed KAPLET / Tarik Barang Retur | S148: 46170 | T148: 0.375 | U148: 0.91666667 | V148: Asia/Jakarta | W148: 1 | X148: TRUE | Y148: obat | Z148: FALSE | AB148: 1 | AC148: AWBR-5547-2026-5-26-01 | AD148: 0 | AE148: 1 | AF148: 46170 | AG148: 0.375 | AH148: 0.91666667 | AI148: Asia/Jakarta
A149: AWBR-12377-2026-5-26 | B149: 11398423 | C149: Corporate B2B Bundle | D149: 26051103405125kjdtr2v65x | E149: STANDARD | F149: Apotek Bintang Sehat Sukaragam Serang Baru | G149: 6.28125e+17 | H149: Perum Mega Regency Blok H1 No. 30 Desa Sukaragam Kec. Serang Baru Kab. Bekasi | I149: ID | J149: PT Teknologi Medika Pratama (SwipeRx) (B2BR) | K149: 87733785699 | L149: Jl. Tugu Raya, Tugu, Kec. Cimanggis, Kota Depok, Jawa Barat 16451,KUBIK LOGISTICS - Kompleks Pergudangan,Gudang E1 | M149: ID | N149: Cimanggis | O149: Depok | P149: Jawa Barat | Q149: 16451 | R149: TMP-INV-2026/05/11/ 2733082 / TMP-INV-2026/05/11/ 2732929SUPERHOID Triman SUPPOSITORIA DUS, 1 BLISTER @ 6 SUPPOSITORIA / VITAMIN B12 Holi TABLET DUS, 10 BLISTER @ 10 TABLETTarik Barang Retur | S149: 46170 | T149: 0.375 | U149: 0.91666667 | V149: Asia/Jakarta | W149: 1 | X149: TRUE | Y149: obat | Z149: FALSE | AB149: 1 | AC149: AWBR-12377-2026-5-26-01 | AD149: 0 | AE149: 1 | AF149: 46170 | AG149: 0.375 | AH149: 0.91666667 | AI149: Asia/Jakarta | AJ149: Pickup Return, wajib bawa form BA Return. Bilang ke Apotek “mau tarik barang”. Jika tidak ada barang, tulis keterangan “tidak ada barang retur” di form BA
A150: AWBR-11287-2026-5-26 | B150: 11398423 | C150: Corporate B2B Bundle | D150: 26042902473946TTTafzHiU7 | E150: STANDARD | F150: Apotek Cibarusah Farma Sukasari Serang Baru | G150: 6.2822e+16 | H150: Kp. Pasirandu RT/RW 06/03, Desa/Kelurahan Sukasari, Kec. Serang Baru, Kab. Bekasi, 17330 | I150: ID | J150: PT Teknologi Medika Pratama (SwipeRx) (B2BR) | K150: 87733785699 | L150: Jl. Tugu Raya, Tugu, Kec. Cimanggis, Kota Depok, Jawa Barat 16451,KUBIK LOGISTICS - Kompleks Pergudangan,Gudang E1 | M150: ID | N150: Cimanggis | O150: Depok | P150: Jawa Barat | Q150: 16451 | R150: TMP-INV-2026/04/29/ 2689765MOISDERM 20% Interbat KRIM DUS, TUBE @ 20 GRAMTarik Barang Retur | S150: 46170 | T150: 0.375 | U150: 0.91666667 | V150: Asia/Jakarta | W150: 1 | X150: TRUE | Y150: obat | Z150: FALSE | AB150: 1 | AC150: AWBR-11287-2026-5-26-01 | AD150: 0 | AE150: 1 | AF150: 46170 | AG150: 0.375 | AH150: 0.91666667 | AI150: Asia/Jakarta | AJ150: Pickup Return, wajib bawa form BA Return. Bilang ke Apotek “mau tarik barang”. Jika tidak ada barang, tulis keterangan “tidak ada barang retur” di form BA
A151: AWBR-10645-2026-5-26 | B151: 11398423 | C151: Corporate B2B Bundle | D151: 25072908423414K5fHejQYAG | E151: STANDARD | F151: Apotek Habiby Muktiwari Cibitung | G151: 6.28584e+17 | H151: Perumahan Permata Muktiwari Residence Blok A1 No. 05 Desa/Kelurahan Muktiwari, Kecamatan Cibitung, Kabupaten Bekasi, Jawa Barat 17519 | I151: ID | J151: PT Teknologi Medika Pratama (SwipeRx) (B2BR) | K151: 87733785699 | L151: Jl. Tugu Raya, Tugu, Kec. Cimanggis, Kota Depok, Jawa Barat 16451,KUBIK LOGISTICS - Kompleks Pergudangan,Gudang E1 | M151: ID | N151: Cimanggis | O151: Depok | P151: Jawa Barat | Q151: 16451 | R151: TMP-INV-2025/07/30/ 1784741FOROTIC Hexpharm TETES TELINGA 3 MG DUS, 1 BOTOL PLASTIK @ 5 MLTarik Barang Retur | S151: 46170 | T151: 0.375 | U151: 0.91666667 | V151: Asia/Jakarta | W151: 1 | X151: TRUE | Y151: obat | Z151: FALSE | AB151: 1 | AC151: AWBR-10645-2026-5-26-01 | AD151: 0 | AE151: 1 | AF151: 46170 | AG151: 0.375 | AH151: 0.91666667 | AI151: Asia/Jakarta | AJ151: Pickup Return, wajib bawa form BA Return. Bilang ke Apotek “mau tarik barang”. Jika tidak ada barang, tulis keterangan “tidak ada barang retur” di form BA
A152: AWBR-1249-2026-5-26 | B152: 11398423 | C152: Corporate B2B Bundle | D152: 26051109185867lMoCGmPTb | E152: STANDARD | F152: Apotek K24 Anggrek Cikarang Baru | G152: 87877209076 | H152: Jalan Anggrek Kaviling B1 No.23 Kelurahan Mekarmukti Kecamatan Cikarang Utara Kabupaten Bekasi 17530 | I152: ID | J152: PT Teknologi Medika Pratama (SwipeRx) (B2BR) | K152: 87733785699 | L152: Jl. Tugu Raya, Tugu, Kec. Cimanggis, Kota Depok, Jawa Barat 16451,KUBIK LOGISTICS - Kompleks Pergudangan,Gudang E1 | M152: ID | N152: Cimanggis | O152: Depok | P152: Jawa Barat | Q152: 16451 | R152: TMP-INV-2026/05/12/ 2736291THROMECON Etercon GEL 200 IU/g DUS @ TUBE 20 gTarik Barang Retur | S152: 46170 | T152: 0.375 | U152: 0.91666667 | V152: Asia/Jakarta | W152: 1 | X152: TRUE | Y152: obat | Z152: FALSE | AB152: 1 | AC152: AWBR-1249-2026-5-26-01 | AD152: 0 | AE152: 1 | AF152: 46170 | AG152: 0.375 | AH152: 0.91666667 | AI152: Asia/Jakarta | AJ152: Pickup Return, wajib bawa form BA Return. Bilang ke Apotek “mau tarik barang”. Jika tidak ada barang, tulis keterangan “tidak ada barang retur” di form BA
A153: AWBR-1090-2026-5-26 | B153: 11398423 | C153: Corporate B2B Bundle | D153: 26030606335954uBALwLjNxA | E153: STANDARD | F153: Apotek K24 Grand Permata City | G153: 85294437759 | H153: Ruko Grand Permata City Kav B1 No.10 Jalan Pilar Sukatani Kelurahan Karang Setia Kecamatan Karang Bahagia Cikarang Bekasi 17530 | I153: ID | J153: PT Teknologi Medika Pratama (SwipeRx) (B2BR) | K153: 87733785699 | L153: Jl. Tugu Raya, Tugu, Kec. Cimanggis, Kota Depok, Jawa Barat 16451,KUBIK LOGISTICS - Kompleks Pergudangan,Gudang E1 | M153: ID | N153: Cimanggis | O153: Depok | P153: Jawa Barat | Q153: 16451 | R153: TMP-INV-2026/03/06/ 2503942INLACTA GOLD DHA Interbat KAPSUL DUS, BOTOL PLASTIK @ 50 KAPSULTarik Barang Retur | S153: 46170 | T153: 0.375 | U153: 0.91666667 | V153: Asia/Jakarta | W153: 1 | X153: TRUE | Y153: obat | Z153: FALSE | AB153: 1 | AC153: AWBR-1090-2026-5-26-01 | AD153: 0 | AE153: 1 | AF153: 46170 | AG153: 0.375 | AH153: 0.91666667 | AI153: Asia/Jakarta | AJ153: Pickup Return, wajib bawa form BA Return. Bilang ke Apotek “mau tarik barang”. Jika tidak ada barang, tulis keterangan “tidak ada barang retur” di form BA
A154: AWBR-12839-2026-5-26 | B154: 11398423 | C154: Corporate B2B Bundle | D154: 26050214021595f80sXSqcnx | E154: STANDARD | F154: Apotek Ninda Farma Sirnajaya Serang Baru | G154: 6.28589e+17 | H154: Kp Cilangkara RT/RW 007/004 Desa Sirnajaya Kec. Serang Baru Kabupaten Bekasi | I154: ID | J154: PT Teknologi Medika Pratama (SwipeRx) (B2BR) | K154: 87733785699 | L154: Jl. Tugu Raya, Tugu, Kec. Cimanggis, Kota Depok, Jawa Barat 16451,KUBIK LOGISTICS - Kompleks Pergudangan,Gudang E1 | M154: ID | N154: Cimanggis | O154: Depok | P154: Jawa Barat | Q154: 16451 | R154: TMP-INV-2026/05/03/ 2702668ACICLOVIR Phapros TABLET 200 MG DUS, 5 STRIP @ 10 TABLETTarik Barang Retur | S154: 46170 | T154: 0.375 | U154: 0.91666667 | V154: Asia/Jakarta | W154: 1 | X154: TRUE | Y154: obat | Z154: FALSE | AB154: 1 | AC154: AWBR-12839-2026-5-26-01 | AD154: 0 | AE154: 1 | AF154: 46170 | AG154: 0.375 | AH154: 0.91666667 | AI154: Asia/Jakarta | AJ154: Pickup Return, wajib bawa form BA Return. Bilang ke Apotek “mau tarik barang”. Jika tidak ada barang, tulis keterangan “tidak ada barang retur” di form BA
A155: AWBR-2043-2026-5-26 | B155: 11398423 | C155: Corporate B2B Bundle | D155: 25040510300001GNyirqUm | E155: STANDARD | F155: Apotek Adzra | G155: 6281286536306 | H155: Jalan Boulevard Raya Ruko Milan Avenue Blok CE No. 25 RT 004 RW 008 Kelurahan Sawangan Kecamatan Sawangan Depok 16511 | I155: ID | J155: PT Teknologi Medika Pratama (SwipeRx) (B2BR) | K155: 87733785699 | L155: Jl. Tugu Raya, Tugu, Kec. Cimanggis, Kota Depok, Jawa Barat 16451,KUBIK LOGISTICS - Kompleks Pergudangan,Gudang E1 | M155: ID | N155: Cimanggis | O155: Depok | P155: Jawa Barat | Q155: 16451 | R155: TMP-INV-2025/04/06/ 1476842 / TMP-INV-2025/09/10/ 1914104 LIPROLAC BABY Kalbe DROPS DUS, BOTOL KACA 8 ML / BLACKMORES PREGNANCY & BREAST-FEEDING GOLD Kalbe KAPSUL BOTOL KACA @ 20 KAPSUL LUNAKTarik Barang Retur | S155: 46170 | T155: 0.375 | U155: 0.91666667 | V155: Asia/Jakarta | W155: 1 | X155: TRUE | Y155: obat | Z155: FALSE | AB155: 1 | AC155: AWBR-2043-2026-5-26-01 | AD155: 0 | AE155: 1 | AF155: 46170 | AG155: 0.375 | AH155: 0.91666667 | AI155: Asia/Jakarta | AJ155: Pickup Return, wajib bawa form BA Return. Bilang ke Apotek “mau tarik barang”. Jika tidak ada barang, tulis keterangan “tidak ada barang retur” di form BA
A156: AWBR-16836-2026-5-26 | B156: 11398423 | C156: Corporate B2B Bundle | D156: 26051502300020aTqkGQS8AW | E156: STANDARD | F156: Apotek Aura Jatibening Pondokgede | G156: 6.28122e+17 | H156: Jl. Raya Jatibening Estate No. 34, Kel.Jatibening, Kec. Pondok Gede, Kota Bekasi | I156: ID | J156: PT Teknologi Medika Pratama (SwipeRx) (B2BR) | K156: 87733785699 | L156: Jl. Tugu Raya, Tugu, Kec. Cimanggis, Kota Depok, Jawa Barat 16451,KUBIK LOGISTICS - Kompleks Pergudangan,Gudang E1 | M156: ID | N156: Cimanggis | O156: Depok | P156: Jawa Barat | Q156: 16451 | R156: TMP-INV-2026/05/15/ 2749210 / TMP-INV-2026/05/15/ 2749508 / MINYAK ANGIN CAP KAPAK Yahi Utama DUS, 12 BOTOL KACA @ 28 ML & 5 MLTarik Barang Retur | S156: 46170 | T156: 0.375 | U156: 0.91666667 | V156: Asia/Jakarta | W156: 1 | X156: TRUE | Y156: obat | Z156: FALSE | AB156: 1 | AC156: AWBR-16836-2026-5-26-01 | AD156: 0 | AE156: 1 | AF156: 46170 | AG156: 0.375 | AH156: 0.91666667 | AI156: Asia/Jakarta | AJ156: Pickup Return, wajib bawa form BA Return. Bilang ke Apotek “mau tarik barang”. Jika tidak ada barang, tulis keterangan “tidak ada barang retur” di form BA
A157: AWBR-11770-2026-5-26 | B157: 11398423 | C157: Corporate B2B Bundle | D157: 26051912345537knnZqNhld | E157: STANDARD | F157: Apotek Ayesa Farma Sukmajaya Sukmajaya | G157: 6.28786e+17 | H157: Jl. Kemang Raya No 5 Kel. Sukmajaya Kec. Sukmajaya Kota Depok | I157: ID | J157: PT Teknologi Medika Pratama (SwipeRx) (B2BR) | K157: 87733785699 | L157: Jl. Tugu Raya, Tugu, Kec. Cimanggis, Kota Depok, Jawa Barat 16451,KUBIK LOGISTICS - Kompleks Pergudangan,Gudang E1 | M157: ID | N157: Cimanggis | O157: Depok | P157: Jawa Barat | Q157: 16451 | R157: TMP-INV-2026/05/20/ 2766924VENTOLIN NEBULES Gsk CAIRAN INHALASI 2.5 MG DUS, 4X5 AMPUL PLASTIK (NEBULES) @ 2.5 MLTarik Barang Retur | S157: 46170 | T157: 0.375 | U157: 0.91666667 | V157: Asia/Jakarta | W157: 1 | X157: TRUE | Y157: obat | Z157: FALSE | AB157: 1 | AC157: AWBR-11770-2026-5-26-01 | AD157: 0 | AE157: 1 | AF157: 46170 | AG157: 0.375 | AH157: 0.91666667 | AI157: Asia/Jakarta | AJ157: Pickup Return, wajib bawa form BA Return. Bilang ke Apotek “mau tarik barang”. Jika tidak ada barang, tulis keterangan “tidak ada barang retur” di form BA
A158: AWBR-667-2026-5-26 | B158: 11398423 | C158: Corporate B2B Bundle | D158: 26052100114509I6yX698x8v | E158: STANDARD | F158: Apotek Berlian Farma | G158: 85374101944 | H158: Komplek Permata Jasindo Lestari Blok A6/14 RT.007 RW.004 Kelurahan Mekarsari, Kecamatan Cimanggis, Kota Depok 16452 | I158: ID | J158: PT Teknologi Medika Pratama (SwipeRx) (B2BR) | K158: 87733785699 | L158: Jl. Tugu Raya, Tugu, Kec. Cimanggis, Kota Depok, Jawa Barat 16451,KUBIK LOGISTICS - Kompleks Pergudangan,Gudang E1 | M158: ID | N158: Cimanggis | O158: Depok | P158: Jawa Barat | Q158: 16451 | R158: TMP-INV-2026/05/21/ 2770768HOLISTICARE SUPER ESTER C Indocare TABLET DUS, BOTOL PLASTIK @ 90 TABLETTarik Barang Retur | S158: 46170 | T158: 0.375 | U158: 0.91666667 | V158: Asia/Jakarta | W158: 1 | X158: TRUE | Y158: obat | Z158: FALSE | AB158: 1 | AC158: AWBR-667-2026-5-26-01 | AD158: 0 | AE158: 1 | AF158: 46170 | AG158: 0.375 | AH158: 0.91666667 | AI158: Asia/Jakarta | AJ158: Pickup Return, wajib bawa form BA Return. Bilang ke Apotek “mau tarik barang”. Jika tidak ada barang, tulis keterangan “tidak ada barang retur” di form BA
A159: AWBR-724-2026-5-26 | B159: 11398423 | C159: Corporate B2B Bundle | D159: 26051102481372bLFUaYo3p | E159: STANDARD | F159: Apotek Dewi Farma | G159: 85283705505 | H159: Jalan Mess AL Kranggan Wetan RT.001/RW.012, Kelurahan Jatirangga, Kecamatan Jatisampurna, Kota Bekasi 17434 | I159: ID | J159: PT Teknologi Medika Pratama (SwipeRx) (B2BR) | K159: 87733785699 | L159: Jl. Tugu Raya, Tugu, Kec. Cimanggis, Kota Depok, Jawa Barat 16451,KUBIK LOGISTICS - Kompleks Pergudangan,Gudang E1 | M159: ID | N159: Cimanggis | O159: Depok | P159: Jawa Barat | Q159: 16451 | R159: TMP-INV-2026/05/11/ 2734033DERMOVATE Gsk KRIM 0.05 % DUS, TUBE @ 10 GTarik Barang Retur | S159: 46170 | T159: 0.375 | U159: 0.91666667 | V159: Asia/Jakarta | W159: 1 | X159: TRUE | Y159: obat | Z159: FALSE | AB159: 1 | AC159: AWBR-724-2026-5-26-01 | AD159: 0 | AE159: 1 | AF159: 46170 | AG159: 0.375 | AH159: 0.91666667 | AI159: Asia/Jakarta | AJ159: Pickup Return, wajib bawa form BA Return. Bilang ke Apotek “mau tarik barang”. Jika tidak ada barang, tulis keterangan “tidak ada barang retur” di form BA
A160: AWBR-15419-2026-5-26 | B160: 11398423 | C160: Corporate B2B Bundle | D160: 26050208022602iYJJ8R0Hy | E160: STANDARD | F160: Apotek Farhana 2 Kelapa Dua Wetan Ciracas | G160: 6.28211e+17 | H160: Jl. Kelapa Dua Wetan Raya No.22 RT01 RW07 Kel. Kepala Dua Wetan Kec. Ciracas Kota Jakarta Timur | I160: ID | J160: PT Teknologi Medika Pratama (SwipeRx) (B2BR) | K160: 87733785699 | L160: Jl. Tugu Raya, Tugu, Kec. Cimanggis, Kota Depok, Jawa Barat 16451,KUBIK LOGISTICS - Kompleks Pergudangan,Gudang E1 | M160: ID | N160: Cimanggis | O160: Depok | P160: Jawa Barat | Q160: 16451 | R160: TMP-INV-2026/05/03/ 2703572HOTIN KOYO AROMATHERAPY Ultrasakti DUS, 12 SACHET @ 10 LEMBATarik Barang Retur | S160: 46170 | T160: 0.375 | U160: 0.91666667 | V160: Asia/Jakarta | W160: 1 | X160: TRUE | Y160: obat | Z160: FALSE | AB160: 1 | AC160: AWBR-15419-2026-5-26-01 | AD160: 0 | AE160: 1 | AF160: 46170 | AG160: 0.375 | AH160: 0.91666667 | AI160: Asia/Jakarta | AJ160: Pickup Return, wajib bawa form BA Return. Bilang ke Apotek “mau tarik barang”. Jika tidak ada barang, tulis keterangan “tidak ada barang retur” di form BA
... A338: AWBR-4773-2026-6-7 | B338: 11398423 | C338: Corporate B2B Bundle | D338: 26053012444027bh4dz9IwK | E338: STANDARD | F338: Apotekita | G338: 6.28191e+17 | H338: Ruko Elang Laut Boulevard Blok A-11, Jl. Pantai Indah Selatan, Kel. Kamal Muara, Kec. Penjaringan, Jakarta Utara, Provinsi DKI Jakarta,14470 | I338: ID | J338: PT Teknologi Medika Pratama (SwipeRx) (B2BR) | K338: 87733785699 | L338: Jl. Tugu Raya, Tugu, Kec. Cimanggis, Kota Depok, Jawa Barat 16451,KUBIK LOGISTICS - Kompleks Pergudangan,Gudang E1 | M338: ID | N338: Cimanggis | O338: Depok | P338: Jawa barat | Q338: 16451 | R338: TMP-INV-2026/06/01/ 2804721 SISTENOL Dexa Medica KAPLET 500/200 MG DUS, 6 DUS @ 1 BOTOL @ 10 KAPLET SALUT SELAPUT Tarik Barang Retur | S338: 46180 | T338: 0.375 | U338: 0.91666667 | V338: Asia/Jakarta | W338: 1 | X338: TRUE | Y338: OBAT | Z338: FALSE | AB338: 1 | AC338: AWBR-4773-2026-6-7-01 | AD338: 0 | AE338: 1 | AF338: 46180 | AG338: 0.375 | AH338: 0.91666667 | AI338: Asia/Jakarta | AJ338: Pickup Return, wajib bawa form BA Return. Bilang ke Apotek “mau tarik barang”. Jika tidak ada barang, tulis keterangan “tidak ada barang retur” di form BA TMP-INV-2026/06/01/ 2804721 SISTENOL Dexa Medica KAPLET 500/200 MG DUS, 6 DUS @ 1 BOTOL @ 10 KAPLET SALUT SELAPUT Tarik Barang Retur
A339: AWBR-13413-2026-6-9 | B339: 11398423 | C339: Corporate B2B Bundle | D339: 24122804284949gEohSApr | E339: STANDARD | F339: Apotek Anugerah Pasir Mukti Citeureup | G339: 6.28132e+17 | H339: Ruko Perumahan Puri Harmoni Pasir Mukti Blok H No. 40, Desa/Kelurahan Pasirmukti, Kec. Citeureup, Kab. Bogor | I339: ID | J339: PT Teknologi Medika Pratama (SwipeRx) (B2BR) | K339: 87733785699 | L339: Jl. Tugu Raya, Tugu, Kec. Cimanggis, Kota Depok, Jawa Barat 16451,KUBIK LOGISTICS - Kompleks Pergudangan,Gudang E1 | M339: ID | N339: Cimanggis | O339: Depok | P339: Jawa Barat | Q339: 16451 | R339: TMP-INV-2024/12/29/ 1239591 NELLCO SPESIAL OBH PE UNTUK ANAK-ANAK Nellco SIRUP RASA STRAWBERRY DUS, 1 BOTOL GELAS @ 55 ML Tarik Barang Retur | S339: 46182 | T339: 0.375 | U339: 0.91666667 | V339: Asia/Jakarta | W339: 1 | X339: TRUE | Y339: obat | Z339: FALSE | AB339: 1 | AC339: AWBR-13413-2026-6-9-01 | AD339: 0 | AE339: 1 | AF339: 46182 | AG339: 0.375 | AH339: 0.91666667 | AI339: Asia/Jakarta | AJ339: Pickup Return, wajib bawa form BA Return. Bilang ke Apotek “mau tarik barang”. Jika tidak ada barang, tulis keterangan “tidak ada barang retur” di form BA TMP-INV-2024/12/29/ 1239591 NELLCO SPESIAL OBH PE UNTUK ANAK-ANAK Nellco SIRUP RASA STRAWBERRY DUS, 1 BOTOL GELAS @ 55 ML Tarik Barang Retur | AL339: 46181
A340: AWBR-13708-2026-6-9 | B340: 11398423 | C340: Corporate B2B Bundle | D340: 250509072811426bGnxIt5Mj | E340: STANDARD | F340: Apotek Bahari Raya Mampang Tegal Parang Mampang Prapatan | G340: 6.2813e+16 | H340: Jalan Mampang Prapatan VII No 33 RT 010 RW 03, Desa/Kel. Tegal Parang, Kec. Mampang Prapatan, Kota Jakarta Selatan | I340: ID | J340: PT Teknologi Medika Pratama (SwipeRx) (B2BR) | K340: 87733785699 | L340: Jl. Tugu Raya, Tugu, Kec. Cimanggis, Kota Depok, Jawa Barat 16451,KUBIK LOGISTICS - Kompleks Pergudangan,Gudang E1 | M340: ID | N340: Cimanggis | O340: Depok | P340: Jawa Barat | Q340: 16451 | R340: TMP-INV-2025/05/10/ 1565368 HERBABLEND DAILY HEALTH Hermed SIRUP DUS, BOTOL PLASTIK @ 250 ML Tarik Barang Retur | S340: 46182 | T340: 0.375 | U340: 0.91666667 | V340: Asia/Jakarta | W340: 1 | X340: TRUE | Y340: obat | Z340: FALSE | AB340: 1 | AC340: AWBR-13708-2026-6-9-01 | AD340: 0 | AE340: 1 | AF340: 46182 | AG340: 0.375 | AH340: 0.91666667 | AI340: Asia/Jakarta | AJ340: Pickup Return, wajib bawa form BA Return. Bilang ke Apotek “mau tarik barang”. Jika tidak ada barang, tulis keterangan “tidak ada barang retur” di form BA TMP-INV-2025/05/10/ 1565368 HERBABLEND DAILY HEALTH Hermed SIRUP DUS, BOTOL PLASTIK @ 250 ML Tarik Barang Retur | AL340: 46181
A341: AWBR-12793-2026-6-9 | B341: 11398423 | C341: Corporate B2B Bundle | D341: 25101402135181piO4BdpBw | E341: STANDARD | F341: Apotek Ben Mrene Mustika Jaya Mustikajaya Mustika Jaya | G341: 6.28788e+17 | H341: Jalan Asem Jaya, KP. Ciketing Asem No.133 RT.002, RW 006 Kel. Mustikajaya Kec. Mustika Jaya Kota Bekasi | I341: ID | J341: PT Teknologi Medika Pratama (SwipeRx) (B2BR) | K341: 87733785699 | L341: Jl. Tugu Raya, Tugu, Kec. Cimanggis, Kota Depok, Jawa Barat 16451,KUBIK LOGISTICS - Kompleks Pergudangan,Gudang E1 | M341: ID | N341: Cimanggis | O341: Depok | P341: Jawa Barat | Q341: 16451 | R341: TMP-INV-2025/10/14/ 2025987 VENTOLIN INHALER CFC FREE Gsk 200 Doses DUS, 1 BOTOL @ 200 DOSIS Tarik Barang Retur | S341: 46182 | T341: 0.375 | U341: 0.91666667 | V341: Asia/Jakarta | W341: 1 | X341: TRUE | Y341: obat | Z341: FALSE | AB341: 1 | AC341: AWBR-12793-2026-6-9-01 | AD341: 0 | AE341: 1 | AF341: 46182 | AG341: 0.375 | AH341: 0.91666667 | AI341: Asia/Jakarta | AJ341: Pickup Return, wajib bawa form BA Return. Bilang ke Apotek “mau tarik barang”. Jika tidak ada barang, tulis keterangan “tidak ada barang retur” di form BA TMP-INV-2025/10/14/ 2025987 VENTOLIN INHALER CFC FREE Gsk 200 Doses DUS, 1 BOTOL @ 200 DOSIS Tarik Barang Retur | AL341: 46181
A342: AWBR-11489-2026-6-9 | B342: 11398423 | C342: Corporate B2B Bundle | D342: 260529105327588Er1LoDkGG | E342: STANDARD | F342: Apotek Bogor Asri Nanggewer Cibinong | G342: 6.28787e+17 | H342: Perumahan Bogor Asri Blok Ruko 4, Desa/Kel. Nanggewer, Kec. Cibinong, Kab. Bogor 16912 | I342: ID | J342: PT Teknologi Medika Pratama (SwipeRx) (B2BR) | K342: 87733785699 | L342: Jl. Tugu Raya, Tugu, Kec. Cimanggis, Kota Depok, Jawa Barat 16451,KUBIK LOGISTICS - Kompleks Pergudangan,Gudang E1 | M342: ID | N342: Cimanggis | O342: Depok | P342: Jawa Barat | Q342: 16451 | R342: TMP-INV-2026/05/30/ 2798679 OBAT BATUK IBU DAN ANAK Sinde Budi Sentosa BOTOL @ 75 ML Tarik Barang Damaged | S342: 46182 | T342: 0.375 | U342: 0.91666667 | V342: Asia/Jakarta | W342: 1 | X342: TRUE | Y342: obat | Z342: FALSE | AB342: 1 | AC342: AWBR-11489-2026-6-9-01 | AD342: 0 | AE342: 1 | AF342: 46182 | AG342: 0.375 | AH342: 0.91666667 | AI342: Asia/Jakarta | AJ342: Pickup Return, wajib bawa form BA Return. Bilang ke Apotek “mau tarik barang”. Jika tidak ada barang, tulis keterangan “tidak ada barang retur” di form BA TMP-INV-2026/05/30/ 2798679 OBAT BATUK IBU DAN ANAK Sinde Budi Sentosa BOTOL @ 75 ML Tarik Barang Damaged | AL342: 46181
A343: AWBR-115-2026-6-9 | B343: 11398423 | C343: Corporate B2B Bundle | D343: 26051304012337KidPBTMvLP | E343: STANDARD | F343: Apotek Budhi Pratama | G343: 85341917925 | H343: Jalan Raya Tengah No.26 RT.06 RW.01 Kel. Kampung Gedong Kec.Pasar Rebo Kodya - Jakarta Timur | I343: ID | J343: PT Teknologi Medika Pratama (SwipeRx) (B2BR) | K343: 87733785699 | L343: Jl. Tugu Raya, Tugu, Kec. Cimanggis, Kota Depok, Jawa Barat 16451,KUBIK LOGISTICS - Kompleks Pergudangan,Gudang E1 | M343: ID | N343: Cimanggis | O343: Depok | P343: Jawa Barat | Q343: 16451 | R343: TMP-INV-2026/05/14/ 2745230 BETADINE OBAT KUMUR ANTISEPTIK Mbf 1 % BOTOL PLASTIK @ 190 ML FORTID 1000 Darya Varia SIRUP DUS, BOTOL KACA @ 100 ML KALTROFEN Kalbe SUPPOSITORIA 100 MG DUS, 2 BLISTER @ 5 SUPPOSITORIA NEPHROLIT Kalbe KAPSUL DUS, 20 STRIP @ 5 KAPSUL SANMOL FORTE Sanbe SIRUP 250 MG/5 ML DUS, BOTOL @ 60 ML TEMPRA (RASA ANGGUR) Taisho SIRUP 2-6 Tahun DUS, 1 BOTOL PLASTIK @ 60 ML THROMBOGEL Tunggal Idaman GEL 200 IU/G DUS, 1 TUBE @ 10 G Tarik Barang Retur | S343: 46182 | T343: 0.375 | U343: 0.91666667 | V343: Asia/Jakarta | W343: 1 | X343: TRUE | Y343: obat | Z343: FALSE | AB343: 1 | AC343: AWBR-115-2026-6-9-01 | AD343: 0 | AE343: 1 | AF343: 46182 | AG343: 0.375 | AH343: 0.91666667 | AI343: Asia/Jakarta | AJ343: Pickup Return, wajib bawa form BA Return. Bilang ke Apotek “mau tarik barang”. Jika tidak ada barang, tulis keterangan “tidak ada barang retur” di form BA TMP-INV-2026/05/14/ 2745230 BETADINE OBAT KUMUR ANTISEPTIK Mbf 1 % BOTOL PLASTIK @ 190 ML FORTID 1000 Darya Varia SIRUP DUS, BOTOL KACA @ 100 ML KALTROFEN Kalbe SUPPOSITORIA 100 MG DUS, 2 BLISTER @ 5 SUPPOSITORIA NEPHROLIT Kalbe KAPSUL DUS, 20 STRIP @ 5 KAPSUL SANMOL FORTE Sanbe SIRUP 250 MG/5 ML DUS, BOTOL @ 60 ML TEMPRA (RASA ANGGUR) Taisho SIRUP 2-6 Tahun DUS, 1 BOTOL PLASTIK @ 60 ML THROMBOGEL Tunggal Idaman GEL 200 IU/G DUS, 1 TUBE @ 10 G Tarik Barang Retur | AL343: 46181
A344: AWBR-1130-2026-6-9 | B344: 11398423 | C344: Corporate B2B Bundle | D344: 26052503104092kLeMGQgnA | E344: STANDARD | F344: Apotek Bukit Asri | G344: 8128125437 | H344: Ruko Perumahan Bukit Asri Baru Blok A No.6 Kelurahan Pabuaran Kecamatan Cibinong Bogor 16916 | I344: ID | J344: PT Teknologi Medika Pratama (SwipeRx) (B2BR) | K344: 87733785699 | L344: Jl. Tugu Raya, Tugu, Kec. Cimanggis, Kota Depok, Jawa Barat 16451,KUBIK LOGISTICS - Kompleks Pergudangan,Gudang E1 | M344: ID | N344: Cimanggis | O344: Depok | P344: Jawa Barat | Q344: 16451 | R344: TMP-INV-2026/05/25/ 2782436 TRINORDIOL-28 Sunthi TABLET DUS, 2 BLISTER @ 28 TABLET SALUT GULA Tarik Barang Retur | S344: 46182 | T344: 0.375 | U344: 0.91666667 | V344: Asia/Jakarta | W344: 1 | X344: TRUE | Y344: obat | Z344: FALSE | AB344: 1 | AC344: AWBR-1130-2026-6-9-01 | AD344: 0 | AE344: 1 | AF344: 46182 | AG344: 0.375 | AH344: 0.91666667 | AI344: Asia/Jakarta | AJ344: Pickup Return, wajib bawa form BA Return. Bilang ke Apotek “mau tarik barang”. Jika tidak ada barang, tulis keterangan “tidak ada barang retur” di form BA TMP-INV-2026/05/25/ 2782436 TRINORDIOL-28 Sunthi TABLET DUS, 2 BLISTER @ 28 TABLET SALUT GULA Tarik Barang Retur | AL344: 46181
A345: AWBR-11148-2026-6-9 | B345: 11398423 | C345: Corporate B2B Bundle | D345: 24042502443933f2q2rdqbw3 | E345: STANDARD | F345: Apotek Celeste Citaringgul Babakan Madang | G345: 6.28139e+17 | H345: Pasar Sentul City Blok J No.16 Desa Citanggul Kecamatan Babakan Madang Kabupaten Bogor 16810 | I345: ID | J345: PT Teknologi Medika Pratama (SwipeRx) (B2BR) | K345: 87733785699 | L345: Jl. Tugu Raya, Tugu, Kec. Cimanggis, Kota Depok, Jawa Barat 16451,KUBIK LOGISTICS - Kompleks Pergudangan,Gudang E1 | M345: ID | N345: Cimanggis | O345: Depok | P345: Jawa Barat | Q345: 16451 | R345: TMP-INV-2024/04/25/ 747467 VITALIFE C+D3+ZN Bintang Kupu-Kupu KAPSUL DUS, BOTOL PLASTIK @ 30 KAPSUL Tarik Barang Retur | S345: 46182 | T345: 0.375 | U345: 0.91666667 | V345: Asia/Jakarta | W345: 1 | X345: TRUE | Y345: obat | Z345: FALSE | AB345: 1 | AC345: AWBR-11148-2026-6-9-01 | AD345: 0 | AE345: 1 | AF345: 46182 | AG345: 0.375 | AH345: 0.91666667 | AI345: Asia/Jakarta | AJ345: Pickup Return, wajib bawa form BA Return. Bilang ke Apotek “mau tarik barang”. Jika tidak ada barang, tulis keterangan “tidak ada barang retur” di form BA TMP-INV-2024/04/25/ 747467 VITALIFE C+D3+ZN Bintang Kupu-Kupu KAPSUL DUS, BOTOL PLASTIK @ 30 KAPSUL Tarik Barang Retur | AL345: 46181
A346: AWBR-13287-2026-6-9 | B346: 11398423 | C346: Corporate B2B Bundle | D346: 25032812361818PcDwohxE | E346: STANDARD | F346: Apotek Emha Cibubur Ciracas | G346: 6.28528e+17 | H346: Jalan Raya Lapangan Tembak No. 04 RT 005 RW 001, Desa/Kel. Cibubur, Kec. Ciracas, Kota Jakarta Timur | I346: ID | J346: PT Teknologi Medika Pratama (SwipeRx) (B2BR) | K346: 87733785699 | L346: Jl. Tugu Raya, Tugu, Kec. Cimanggis, Kota Depok, Jawa Barat 16451,KUBIK LOGISTICS - Kompleks Pergudangan,Gudang E1 | M346: ID | N346: Cimanggis | O346: Depok | P346: Jawa Barat | Q346: 16451 | R346: TMP-INV-2025/03/29/ 1464928 CANESTEN Bayer KRIM 1 % DUS, TUBE @ 5 G Tarik Barang Retur | S346: 46182 | T346: 0.375 | U346: 0.91666667 | V346: Asia/Jakarta | W346: 1 | X346: TRUE | Y346: obat | Z346: FALSE | AB346: 1 | AC346: AWBR-13287-2026-6-9-01 | AD346: 0 | AE346: 1 | AF346: 46182 | AG346: 0.375 | AH346: 0.91666667 | AI346: Asia/Jakarta | AJ346: Pickup Return, wajib bawa form BA Return. Bilang ke Apotek “mau tarik barang”. Jika tidak ada barang, tulis keterangan “tidak ada barang retur” di form BA TMP-INV-2025/03/29/ 1464928 CANESTEN Bayer KRIM 1 % DUS, TUBE @ 5 G Tarik Barang Retur | AL346: 46181
A347: AWBR-13617-2026-6-9 | B347: 11398423 | C347: Corporate B2B Bundle | D347: 25022702372132FQs8rXWIY | E347: STANDARD | F347: Apotek Fit Pondok Pinang Kebayoran Lama | G347: 6.28219e+17 | H347: Jl. Bukit Hijau 1 No. 15, Desa/Kel. Pondok Pinang, Kec. KebayoranLama, Kota Jakarta Selatan | I347: ID | J347: PT Teknologi Medika Pratama (SwipeRx) (B2BR) | K347: 87733785699 | L347: Jl. Tugu Raya, Tugu, Kec. Cimanggis, Kota Depok, Jawa Barat 16451,KUBIK LOGISTICS - Kompleks Pergudangan,Gudang E1 | M347: ID | N347: Cimanggis | O347: Depok | P347: Jawa Barat | Q347: 16451 | R347: TMP-INV-2025/02/27/ 1385964 GASTIN FORCE Soho SIRUP DUS, BOTOL 100 ML Tarik Barang Retur | S347: 46182 | T347: 0.375 | U347: 0.91666667 | V347: Asia/Jakarta | W347: 1 | X347: TRUE | Y347: obat | Z347: FALSE | AB347: 1 | AC347: AWBR-13617-2026-6-9-01 | AD347: 0 | AE347: 1 | AF347: 46182 | AG347: 0.375 | AH347: 0.91666667 | AI347: Asia/Jakarta | AJ347: Pickup Return, wajib bawa form BA Return. Bilang ke Apotek “mau tarik barang”. Jika tidak ada barang, tulis keterangan “tidak ada barang retur” di form BA TMP-INV-2025/02/27/ 1385964 GASTIN FORCE Soho SIRUP DUS, BOTOL 100 ML Tarik Barang Retur | AL347: 46181
A348: AWBR-15624-2026-6-9 | B348: 11398423 | C348: Corporate B2B Bundle | D348: 25081002022309jrpf9xS0k4 | E348: STANDARD | F348: Apotek Harma 2 Waluya Cikarang Utara | G348: 6.28151e+17 | H348: Jl. Arjuna Raya Perum bumi Citra Lestari Blok B 01/01 RT 00/RW 00 Desa Waluya, Kec. Cikarang Utara, Kabupaten Bekasi | I348: ID | J348: PT Teknologi Medika Pratama (SwipeRx) (B2BR) | K348: 87733785699 | L348: Jl. Tugu Raya, Tugu, Kec. Cimanggis, Kota Depok, Jawa Barat 16451,KUBIK LOGISTICS - Kompleks Pergudangan,Gudang E1 | M348: ID | N348: Cimanggis | O348: Depok | P348: Jawa Barat | Q348: 16451 | R348: TMP-INV-2025/08/10/ 1818240 YOUVIT MULTIVITAMIN GUMMY RASA STRAWBERRY, GOJIBERRY, CANBERRY, RASPBERRY, BLUEBERRY Yupi - DUS DUS, 6 SACHET @ 7 GUMMIES 28 G Tarik Barang Retur | S348: 46182 | T348: 0.375 | U348: 0.91666667 | V348: Asia/Jakarta | W348: 1 | X348: TRUE | Y348: obat | Z348: FALSE | AB348: 1 | AC348: AWBR-15624-2026-6-9-01 | AD348: 0 | AE348: 1 | AF348: 46182 | AG348: 0.375 | AH348: 0.91666667 | AI348: Asia/Jakarta | AJ348: Pickup Return, wajib bawa form BA Return. Bilang ke Apotek “mau tarik barang”. Jika tidak ada barang, tulis keterangan “tidak ada barang retur” di form BA TMP-INV-2025/08/10/ 1818240 YOUVIT MULTIVITAMIN GUMMY RASA STRAWBERRY, GOJIBERRY, CANBERRY, RASPBERRY, BLUEBERRY Yupi - DUS DUS, 6 SACHET @ 7 GUMMIES 28 G Tarik Barang Retur | AL348: 46181
A349: AWBR-8621-2026-6-9 | B349: 11398423 | C349: Corporate B2B Bundle | D349: 2605300029074806s38tzqt | E349: STANDARD | F349: Apotek Ilham Karangsatria Tambun Utara | G349: 85888674498 | H349: Villa Mutiara Gading 2, Kav D10 No. 03A Desa Karang Satria Kec. Tambun Utara Kab. Bekasi 17510 | I349: ID | J349: PT Teknologi Medika Pratama (SwipeRx) (B2BR) | K349: 87733785699 | L349: Jl. Tugu Raya, Tugu, Kec. Cimanggis, Kota Depok, Jawa Barat 16451,KUBIK LOGISTICS - Kompleks Pergudangan,Gudang E1 | M349: ID | N349: Cimanggis | O349: Depok | P349: Jawa Barat | Q349: 16451 | R349: TMP-INV-2026/05/30/ 2798961 BUFACOMB Bufa KRIM DUS, 1 TUBE @ 5 GRAM Tarik Barang Retur | S349: 46182 | T349: 0.375 | U349: 0.91666667 | V349: Asia/Jakarta | W349: 1 | X349: TRUE | Y349: obat | Z349: FALSE | AB349: 1 | AC349: AWBR-8621-2026-6-9-01 | AD349: 0 | AE349: 1 | AF349: 46182 | AG349: 0.375 | AH349: 0.91666667 | AI349: Asia/Jakarta | AJ349: Pickup Return, wajib bawa form BA Return. Bilang ke Apotek “mau tarik barang”. Jika tidak ada barang, tulis keterangan “tidak ada barang retur” di form BA TMP-INV-2026/05/30/ 2798961 BUFACOMB Bufa KRIM DUS, 1 TUBE @ 5 GRAM Tarik Barang Retur | AL349: 46181
A350: AWBR-14021-2026-6-9 | B350: 11398423 | C350: Corporate B2B Bundle | D350: 26042407152473M3cV3Ptkhv | E350: STANDARD | F350: Apotek Inofarma Kebagusan | G350: 62859-2661-1060 | H350: Jl. Kebagusan Raya RT 007 RW 06, Kel. Kebagusan, Kec. Pasar Minggu, Jakarta Selatan | I350: ID | J350: PT Teknologi Medika Pratama (SwipeRx) (B2BR) | K350: 87733785699 | L350: Jl. Tugu Raya, Tugu, Kec. Cimanggis, Kota Depok, Jawa Barat 16451,KUBIK LOGISTICS - Kompleks Pergudangan,Gudang E1 | M350: ID | N350: Cimanggis | O350: Depok | P350: Jawa Barat | Q350: 16451 | R350: TMP-INV-2026/04/25/ 2678001 EPISAN Sanbe SUSPENSI DUS, 1 BOTOL @ 200 ML Tarik Barang Damaged | S350: 46182 | T350: 0.375 | U350: 0.91666667 | V350: Asia/Jakarta | W350: 1 | X350: TRUE | Y350: obat | Z350: FALSE | AB350: 1 | AC350: AWBR-14021-2026-6-9-01 | AD350: 0 | AE350: 1 | AF350: 46182 | AG350: 0.375 | AH350: 0.91666667 | AI350: Asia/Jakarta | AJ350: Pickup Return, wajib bawa form BA Return. Bilang ke Apotek “mau tarik barang”. Jika tidak ada barang, tulis keterangan “tidak ada barang retur” di form BA TMP-INV-2026/04/25/ 2678001 EPISAN Sanbe SUSPENSI DUS, 1 BOTOL @ 200 ML Tarik Barang Damaged | AL350: 46181
...

Sheet Pivot Table 1

Sheet Pending Pickup
A1: Tracking ID | B1: Nama Apotek | C1: No telp Apotek | D1: Alamat Apotek | E1: No Faktur | F1: Pickup Instruction | G1: Order Creation | H1: Inbound Date | I1: Completed Date | J1: Status | K1: Remarks tim FM | M1: City | N1: Province | O1: Area | S1: COUNTA of Tracking ID | T1: Order Creation
A2: AWBR-17160-2026-4-24-01 | B2: Apotek Jonathan Sukarame Sukarame | C2: =+6282281904329 -> 6282281904329 | D2: Jl. Karimun Jawa Blok C No.6 Kel. Sukarame Kec. Sukarame Kota Bandar Lampung | E2: 26032517134675jMJFzUcwlD | F2: RENOVIT GOLD Konimex KAPLET DUS, 25 CATCH COVER @ 1 STRIP @ 4 KAPLET SALUT SELAPUT -Tarik Barang Retur - wajib bawa BA retur | G2: 46138 | J2: Cancelled | M2: =GET_LOCATION(D2,"city") -> Kota Bandar Lampung | N2: =GET_LOCATION(D2,"province") -> Lampung | O2: =VLOOKUP(M2,'Mapping Area'!A:C,3,0) -> #N/A | S2: Status | T2: 46180 | U2: 46182 | V2: 46183 | W2: 46184 | X2: 46185 | Y2: 46186 | Z2: 46188 | AA2: Grand Total
A3: AWBR-10608-2026-4-27-01 | B3: Apotek Dayu Tunggorono Jombang | C3: =+6285881133907 -> 6285881133907 | D3: Jalan Mayjen Sungkono No. 12, Desa/Kelurahan Tunggorono, Kecamatan Jombang, Kabupaten Jombang, Jawa Timur 61419 | E3: 26042402354067Wq97J4YybZ | F3: SGM ANANDA GAIN 100 Sarihusada - Tarik barang retur - Wajib Bawa BA retur | G3: 46140 | H3: 46163 | I3: 46165 | J3: Completed | S3: Arrived at Sorting Hub | V3: 3 | X3: 1 | Y3: 2 | Z3: 1 | AA3: 7
A4: AWBR-12839-2026-4-28-01 | B4: Apotek Ninda Farma Sirnajaya Serang Baru | C4: =+6285888841288 -> 6285888841288 | D4: Kp Cilangkara RT/RW 007/004 Desa Sirnajaya Kec. Serang Baru Kabupaten Bekasi | E4: 26042312050185UKAhj736c | F4: TRINORDIOL-28 Sunthi TABLET DUS, 2 BLISTER @ 28 TABLET SALUT GULA Tarik Barang Retur Wajib Bawa BA Retur | G4: 46140 | H4: 46166 | I4: 46166 | J4: Completed | S4: Cancelled | V4: 7 | W4: 1 | AA4: 8
A5: AWBR-12478-2026-4-28-01 | B5: Apotek Inofarma Asmawi Beji Beji | C5: =+6282266622264 -> 6282266622264 | D5: Jl. Haji Asmawi No.62A RT 004 RW 005 Kel. Beji Kec. Beji Kota Depok | E5: 26042403293758ZgkhbjiVk | F5: DIPROGENTA Organon SALEP DUS, TUBE @ 10 G Tarik Barang Retur Wajib Bawa BA Retur | G5: 46140 | H5: 46180 | I5: 46182 | J5: Completed | S5: Completed | T5: 14 | U5: 18 | V5: 227 | W5: 74 | X5: 58 | Y5: 33 | Z5: 16 | AA5: 440
A6: AWBR-6702-2026-4-28-01 | B6: Apotek Rejeki 6702 | C6: =+6281222221342 -> 6281222221342 | D6: Perum Ruko Perumahan Imanan Residence Blok A No.6 RT 005 RW 02 Desa Serang Kec. Cikarang Selatan Kab. Bekasi 17530 | E6: 26042603050491W0Zjm1cqxT | F6: CALADINE BABY LIQUID SOAP WITH ANTI IRRITANT Galenium BOTOL, 200 ML Tarik Barang Retur Wajib Bawa BA Retur | G6: 46140 | H6: 46179 | I6: 46180 | J6: Completed | S6: On Hold | V6: 4 | X6: 1 | AA6: 5
A7: AWBR-6702-2026-4-30-01 | B7: Apotek Rejeki 6702 | C7: =+6281222221342 -> 6281222221342 | D7: Perum Ruko Perumahan Imanan Residence Blok A No.6 RT 005 RW 02 Desa Serang Kec. Cikarang Selatan Kab. Bekasi 17530 | E7: 260319014933855Fxmui8w1 | F7: TMP-INV-2026/03/19/ 2551381 HUFAGRIPP FLU dan BATUK Gratia SUSPENSI DUS, 1 BOTOL @ 60 ML LACOLDIN Lapi SIRUP DUS, 1 BOTOL @ 60 ML LAPIFED Lapi SIRUP DUS, 1 BOTOL @ 60 ML Tarik Barang Retur & Tarik Barang Damage / wajib bawa BA retur | G7: 46141 | H7: 46179 | I7: 46180 | J7: Completed | S7: Grand Total | T7: 14 | U7: 18 | V7: 241 | W7: 75 | X7: 60 | Y7: 35 | Z7: 17 | AA7: 460
A8: AWBR-12013-2026-4-29-01 | B8: Apotek K24 Cinere Cinere Cinere | C8: =+6285265442622 -> 6285265442622 | D8: Jalan Cinere Raya, Desa/Kelurahan Cinere,Kecamatan Cinere, Kota Depok,Jawa Barat,16514 | E8: 26032605202031Co34llD0hn | F8: LIPOSIN Prima Medika SALEP DUS, 1 TUBE @ 10 G Tarik Barang Damaged / wajib bawa BA retur | G8: 46141 | H8: 46180 | I8: 46182 | J8: Completed
A9: AWBR-10720-2026-4-29-01 | B9: Apotek K24 Sukasari Sukasari Serang Baru | C9: =+6281776481573 -> 6281776481573 | D9: Ruko Serang-Cibarusah No. 3 Jl. Raya Serang Cibarusah Kp. Pasar Randu, Kel. Sukasari Kec. Serang Baru Kab. Bekasi 17330 | E9: 26031103015717lzHpXz5sVb | F9: EPEXOL Sanbe SIRUP 15 MG/5 ML DUS, 1 BOTOL @ 120 ML LERZIN Ifars DROPS DUS, 1 BOTOL @ 15 ML Tarik Barang Damaged / wajib bawa BA retur | G9: 46141 | H9: 46179 | I9: 46180 | J9: Completed
A10: AWBR-17026-2026-4-29-01 | B10: Apotek Qta Farma Jatinunggal Pawenang | C10: =+6283173217844 -> 6283173217844 | D10: Dusun Sukahurip RT 001 RW 005 , Kel. Pawenang, Kec. Jatinunggal, Kab. Sumedang | E10: 26031701023459JO2QQm4E81 | F10: FARSIFEN FORTE Ifars SUSPENSI DUS, 1 BOTOL @ 60 ML / ITAMOL Bmf SIRUP DUS, 1 BOTOL PLASTIK @ 60 ML / PECTORIN Itrasal SIRUP DUS, 1 BOTOL @ 120 ML /SUCRALFATE Dexa Medica SUSPENSI BOTOL PLASTIK 100 ML Tarik Barang Damaged / wajib bawa BA retur | G10: 46141 | H10: 46180 | I10: 46181 | J10: Completed
A11: AWBR-10645-2026-4-22-01 | B11: Apotek Habiby Muktiwari Cibitung | C11: =+6285842895083 -> 6285842895083 | D11: Perumahan Permata Muktiwari Residence Blok A1 No. 05 Desa/Kelurahan Muktiwari, Kecamatan Cibitung, Kabupaten Bekasi, Jawa Barat 17519 | E11: 26041516304160yNDdqvj7ZM | F11: TMP-INV-2026/04/16/ 2642229ETORICOXIB Interbat TABLET 90 MG DUS, 3 STRIP @ 10 TABLET SALUT SELAPUTTarik Barang Retur | G11: 46146 | H11: 46166 | I11: 46166 | J11: Completed
A12: AWBR-11437-2026-4-22-01 | B12: Apotek Berlian Farma Rasamala Bakti Jaya Sukmajaya | C12: =+6285374101944 -> 6285374101944 | D12: Jl. Rasamala Raya No. 423 Kel. Baktijaya Kec. Sukmajaya Kota Depok 16418 | E12: 26040703362888orT7BEepo | F12: TMP-INV-2026/04/07/ 2611993MINYAK ANGIN CAP KAPAK Yahi Utama DUS, 12 BOTOL KACA @ 28 MLTarik Barang Retur | G12: 46146 | H12: 46163 | I12: 46164 | J12: Completed
A13: AWBR-334-2026-4-22-01 | B13: Apotek Merapi | C13: 2177833109 | D13: Jalan Kejayaan Blok X No. 9 RT 006/ RW 012 Kelurahan Abadijaya, Kecamatan Sukmajaya Kota Depok 16417 | E13: 26040503513880l4vMvC2w3 | F13: TMP-INV-2026/04/05/ 2603566ATORVASTATIN CALCIUM Hexpharm TABLET 10 MG DUS, 5 BLISTER @ 10 TABLET SALUT SELAPUTTarik Barang Retur | G13: 46146 | H13: 46170 | I13: 46171 | J13: Completed | S13: Area | T13: COUNTA of Tracking ID
A14: AWBR-3992-2026-4-22-01 | B14: Apotek Ar Razaaq | C14: =+6285710003495 -> 6285710003495 | D14: Ruko Villa Wanasari Jalan Bosih Raya Desa Wanasari Kecamatan Cibitung Kabupaten Bekasi 17520 | E14: 26040604372767jcfthTOP | F14: TMP-INV-2026/04/07/ 2610263BETASON Kimia Farma KRIM DUS, 24 DUS @ 1 TUBE @ 5 GRAM KOOLFEVER UNTUK BAYI DUS, 12 SACHET @ 1 LEMBARTarik Barang Retur | G14: 46146 | H14: 46179 | I14: 46179 | J14: Completed | S14: EJ | T14: 1
A15: AWBR-15825-2026-4-25-01 | B15: Apotek MMK24 Abadi Jaya Sukmajaya | C15: =+6281252592024 -> 6281252592024 | D15: Jl. Kejayaan Blok 10 No. 10, Desa/Kelurahan Abadi Jaya, Kec.Sukmajaya, Kota Depok, | E15: 251105054313146VUv03RgXN | F15: TMP-INV-2025/11/06/ 2097981REDOXON FORTIMUN Bayer TABLET EFFERVESCENT DUS, TUBE @ 10 TABLET EFFERVESCENTTarik Barang Retur | G15: 46146 | H15: 46180 | I15: 46182 | J15: Completed | S15: Grand Total | T15: 1
A16: AWBR-12159-2026-4-25-01 | B16: Apotek Pharmasena Cinere Cinere | C16: =+6282260047002 -> 6282260047002 | D16: Jl. Bukit Cinere No.5E RT/RW.001/008, Desa/Kel. Cinere, Kec. Cinere, Kota Depok | E16: 25022408432111Dc2tT0bG7a | F16: TMP-INV-2025/02/25/ 1380838IMBOOST KIDS Soho SIRUP DUS, BOTOL KACA @ 120 ML SANGOBION BABY Merck CAIRAN ORAL DUS, BOTOL KACA @ 30 ML ALOCLAIR PLUS MOUTHWASH Enseval OBAT KUMUR BOTOL 60 MLTarik Barang Retur | G16: 46146 | H16: 46180 | I16: 46182 | J16: Completed
A17: AWBR-17267-2026-4-25-01 | B17: Apotek Prisma Farma Jatiwangi Cikarang Barat | C17: =+6285882293179 -> 6285882293179 | D17: Kampung Cibarengkong RT 002 RW 002 Desa Jatiwangi Kecamatan Cikarang Barat Kabupaten Bekasi | E17: 26040706080761QvCmuuUtmQ | F17: TMP-INV-2026/04/08/ 2614456TRINORDIOL-28 Sunthi TABLET DUS, 2 BLISTER @ 28 TABLET SALUT GULATarik Barang Retur | G17: 46147 | H17: 46182 | I17: 46183 | J17: Completed
A18: AWBR-13267-2026-4-24-01 | B18: Apotek Sehat Milenial Sukamaju Baru Tapos | C18: =+6289620265220 -> 6289620265220 | D18: Ruko De���Khirani Village 2 T5, Kp. Sindangkarsa RT. 004 RW.006,Desa/Kelurahan Sukamaju Baru,Kecamatan Tapos,Kota Depok,Jawa Barat, | E18: 250910004336181695hzhlE | F18: TMP-INV-2025/09/10/ 1916397FIESTA INTIM COOL Dkt GEL DUS, TUBE 70 MLTarik Barang Retur | G18: 46147 | H18: 46153 | I18: 46154 | J18: Completed | K18: -
A19: AWBR-15825-2026-4-24-01 | B19: Apotek MMK24 Abadi Jaya Sukmajaya | C19: =+6281252592024 -> 6281252592024 | D19: Jl. Kejayaan Blok 10 No. 10, Desa/Kelurahan Abadi Jaya, Kec.Sukmajaya, Kota Depok, | E19: 25110404205461GN7qe8ABk | F19: TMP-INV-2025/11/05/ 2094477REDOXON FORTIMUN Bayer TABLET EFFERVESCENT DUS, TUBE @ 10 TABLET EFFERVESCENTTarik Barang Retur | G19: 46147 | H19: 46180 | I19: 46182 | J19: Completed
A20: AWBR-13718-2026-4-24-01 | B20: Apotek Kejayaan Abadijaya Sukmajaya | C20: =+6281281385101 -> 6281281385101 | D20: Jl. Kejayaan No. 1 RT. 001 RW. 008,Desa/Kelurahan Abadijaya,Kecamatan Sukmajaya,Kota Depok,Jawa Barat,16417 | E20: 260421125257368N2dPSudq | F20: TMP-INV-2026/04/22/ 2666502BROCHIFAR PLUS Ifars KAPLET DUS, 10 AMPLOP @ 1 STRIP @ 10 KAPLET TUZALOS Sanbe KAPLET DUS, 25 CATCH COVER @ 1 STRIP @ 4 KAPLETTarik Barang Retur | G20: 46147 | H20: 46163 | I20: 46164 | J20: Completed
A21: AWBR-15525-2026-4-24-01 | B21: Apotek Universitas Pelita Harapan Bencongan Indah Kelapa Dua | C21: =+6282341638251 -> 6282341638251 | D21: Gedung GBFK, Lantai G, Universitas Pelita Harapan, Jl. Boulevard Jend. Sudirman No. 20 Desa/Kel. Bencongan Kec. Kelapa Dua Kabupaten Tangerang | E21: 2604170024544043v1EoP3 | F21: TMP-INV-2026/04/17/ 2648056LIFREE POPOK PEREKAT UK. L PLASTIK @ 7 PCSTarik Barang Retur | G21: 46147 | H21: 46157 | I21: 46158 | J21: Completed | K21: -
A22: AWBR-12527-2026-4-24-01 | B22: Apotek Kembar Jaya Farma Jayasampurna Serang Baru | C22: =+6285819228710 -> 6285819228710 | D22: Kp Pagadungan RT 03 RW 04 Desa Jayasampurna Kec. Serang Baru Kab. Bekasi | E22: 26042003380460KYrLrNU4E4 | F22: TMP-INV-2026/04/20/ 2657208COMBIVENT UDV Tunggal Idaman CAIRAN INHALASI DUS, 20 VIAL @ 2,5 MLTarik Barang Retur | G22: 46147 | H22: 46179 | I22: 46180 | J22: Completed
A23: AWBR-12377-2026-4-24-01 | B23: Apotek Bintang Sehat Sukaragam Serang Baru | C23: =+6281250004669 -> 6281250004669 | D23: Perum Mega Regency Blok H1 No. 30 Desa Sukaragam Kec. Serang Baru Kab. Bekasi | E23: 26042002141604e15pNv5Lp6 | F23: TMP-INV-2026/04/20/ 2656989FARSIFEN FORTE Ifars SUSPENSI DUS, 1 BOTOL @ 60 ML / MEZINEX EXPECTORANT Ifars SIRUP DUS, 1 BOTOL @ 60 MLTarik Barang Retur | G23: 46147 | H23: 46179 | I23: 46179 | J23: Completed
A24: AWBR-1043-202-4-22-01 | B24: Apotek Agrata | C24: =+6287808713439 -> 6287808713439 | D24: Kampung Ciakar RT 002 RW 004 Desa Cicalengka Kecamatan Pagedangan Kabupaten Tangerang 15336 | E24: 26040108511968kPnAh8mMCb | F24: TMP-INV-2026/04/02/ 2593356CURCUMA FORCE Soho TABLET DUS, 10 BLISTER @ 12 TABLET SALUT SELAPUTTarik Barang Retur / wajib bawa BA retur | G24: 46150 | H24: 46153 | I24: 46155 | J24: Completed | K24: -
A25: ='DE ( Tarik barang retur )'!AC2 -> AWBR-10859-2026-4-17-01 | B25: ='DE ( Tarik barang retur )'!F2 -> Apotek Citayam Farma Bojong Pondok Terong Cipayung | C25: ='DE ( Tarik barang retur )'!G2 -> 6.28517e+17 | D25: ='DE ( Tarik barang retur )'!H2 -> Jl. Raya Cipayung No.1, RT.03/RW10, Desa/Kel. Bojong Pondok Terong, Kec. Cipayung, Kota Depok 16436 | E25: ='DE ( Tarik barang retur )'!D2 -> 26033013582985PgyfIVBK | F25: ='DE ( Tarik barang retur )'!R2 -> TMP-INV-2026/03/31/ 2586421SGM EKSPLOR GAIN OPTIGROW Sarihusada DUS, ALUMUNIUM FOIL @ 400 GTarik Barang Retur & Wajib bawa BA retur | G25: ='DE ( Tarik barang retur )'!AF2 -> 46153 | H25: 46153 | I25: 46154 | J25: Completed | K25: -
A26: ='DE ( Tarik barang retur )'!AC3 -> AWBR-4606-2026-5-11-1-01 | B26: ='DE ( Tarik barang retur )'!F3 -> Apotek Singojuruh | C26: ='DE ( Tarik barang retur )'!G3 -> 6.2853e+16 | D26: ='DE ( Tarik barang retur )'!H3 -> Jl Aruji Kartawinata 02/02 Kel.Singojuruh Kec.Singojuruh Kab.Banyuwangi Jawa Timur 68464 | E26: ='DE ( Tarik barang retur )'!D3 -> 25012410200620NHRbykaYKC | F26: ='DE ( Tarik barang retur )'!R3 -> TMP-INV-2025/01/25/ 1305668 - CURVIT Soho SIRUP - Tarik Barang Retur | G26: ='DE ( Tarik barang retur )'!AF3 -> 46155 | H26: 46157 | I26: 46157 | J26: Completed | K26: -
A27: ='DE ( Tarik barang retur )'!AC4 -> AWBR-12411-2026-5-16-01 | B27: ='DE ( Tarik barang retur )'!F4 -> Apotek Bintang Sehat 1 Jayamulya Serang Baru | C27: ='DE ( Tarik barang retur )'!G4 -> 6.28199e+17 | D27: ='DE ( Tarik barang retur )'!H4 -> Perum Grand Vista Blok D1 RT 003 RW 009 Desa Jayamulya Kec. Serang Baru Kab. Bekasi | E27: ='DE ( Tarik barang retur )'!D4 -> 26042802052677jEINi46Brs | F27: ='DE ( Tarik barang retur )'!R4 -> TMP-INV-2026/04/28/ 2685534HERBORIST MINYAK ZAITUN Victoria Care BOTOL @ 75 MLTarik Barang Retur | G27: ='DE ( Tarik barang retur )'!AF4 -> 46158 | H27: 46182 | I27: 46183 | J27: Completed
A28: ='DE ( Tarik barang retur )'!AC5 -> AWBR-12377-2026-5-16-01 | B28: ='DE ( Tarik barang retur )'!F5 -> Apotek Bintang Sehat Sukaragam Serang Baru | C28: ='DE ( Tarik barang retur )'!G5 -> 6.28125e+17 | D28: ='DE ( Tarik barang retur )'!H5 -> Perum Mega Regency Blok H1 No. 30 Desa Sukaragam Kec. Serang Baru Kab. Bekasi | E28: ='DE ( Tarik barang retur )'!D5 -> 26042002141604sR64H1lq | F28: ='DE ( Tarik barang retur )'!R5 -> TMP-INV-2026/04/20/ 2655815Tarik Barang Retur | G28: ='DE ( Tarik barang retur )'!AF5 -> 46158 | H28: 46179 | I28: 46179 | J28: Completed
