Workbook

Sheet Petunjuk
B1: Konverter TMP SwipeRx -> Upload OC Ninja Van
B2: Tanpa makro. Cukup tempel data TMP dan pilih layanan â€” kolom otomatis terisi rumus.
B4: CARA PAKAI
B5: 1. Buka file TMP dari SwipeRx (file '[Template Swipe ...] TMP Batch'). Pilih SELURUH Sheet1 (Ctrl+A), Copy.
B6: 2. Ke sheet 'TMP Paste', tempel di sel A1 (Paste Values boleh). Data mulai baris 2 (1 baris judul).
B7: 3. Ke sheet 'Config' (sel kuning): pilih Layanan (S1/S2/S3), atur tanggal kirim dan gudang asal.
B8: 4. Buka sheet 'OC Upload'. Baris terisi otomatis. Salin kolom A sampai AE + semua baris terisi, tempel ke sistem Ninja Van.
B9: (Kolom setelah AE hanya bantuan/CEK â€” JANGAN ikut di-upload.)
B11: STRUKTUR OUTPUT (acuan: template tech team 'Bulk_Upload_MPS_RDO')
B12: • SATU BARIS = SATU SwipeAWB (satu MPS order). Bukan satu baris per PO.
B13: • A requested_tracking_number = SwipeAWB (MPS Tracking ID) = D merchant_order_number. 1 WP = 1 MPS TRID = 1 SwipeAWB.
B14: • AC = seluruh TRID anak milik MPS tsb, prefix Nomor PO, nomor urut BERJALAN lintas AWB, dipisah ', '. Contoh AWB dgn 3 PO (PO1 = 2 koli):
... B23: Baris PO lanjutan hanya berisi E..M (A/B/C kosong). Jika SwipeRx mengubah urutan kolom lagi, rumus harus disesuaikan.

Sheet Config
A1: CONFIG â€” atur sebelum baca OC Upload
A3: Layanan (pilih) | B3: S1 - Regular (STANDARD) | D3: Layanan | E3: service_level | F3: branch | G3: pickup
A4: Tanggal kirim | B4: =TODAY() | D4: S1 - Regular (STANDARD) | E4: STANDARD | F4: 1 | G4: FALSE
D5: S2 - Sameday (SAMEDAY) | E5: SAMEDAY | F5: 3 | G5: FALSE
D6: S3 - POD Return | E6: STANDARD | F6: 2 | G6: TRUE
A8: GUDANG ASAL (from.*) | D8: REFERENSI SHIPPER ID (info — B selalu master 11398423)
A9: from.name (F) | B9: PT Teknologi Medika Pratama (SwipeRx) (B2BR) | D9: Shipper ID | E9: Shipper Name | F9: Layanan / Branch
A10: from.phone_number (G) | B10: 087733785699 | D10: 11398423 | E10: PT Teknologi Medika Pratama (B2BR) | F10: MASTER — selalu di kolom B
A11: from.address.address1 (H) | B11: Jl. Tugu Raya, Tugu, Kec. Cimanggis, Kota Depok, Jawa Barat 16451,KUBIK LOGISTICS - Kompleks Pergudangan,Gudang E1 | D11: 11398224 | E11: PT Teknologi Medika Pratama HW (B2BR) | F11: S1 Regular — branch 1
D12: 11549046 | E12: PT Teknologi Medika Pratama Sameday CTM (B2BR) | F12: S2 Sameday — branch 3
A13: KONSTANTA TERKUNCI (jangan diubah) | D13: 11398434 | E13: PT Teknologi Medika Pratama HW - RTS Account (B2BR) | F13: S3 Return/POD — branch 2
A14: global_shipper_id (B) master | B14: 11398423
A15: service_type (C) | B15: Corporate B2B Bundle
A16: country (I / M) | B16: ID
A17: timeslot mulai (T) | B17: 09:00
A18: timeslot selesai (U) | B18: 22:00
A19: timezone (V) | B19: Asia/Jakarta
A20: (cadangan)
A21: is_dangerous_good (Z) | B21: FALSE
A22: documents_required (AA) | B22: RDO
A23: insured_value (AD) | B23: 0
A24: Teks instruksi RDO (R) | B24: Delivery Note wajib ada nama penerima, ditandatangani dan distempel penerima. Jika di label tertera "SP Manual", maka dokumen SP Manual harus diminta ke penerima sesuai dengan jumlah PO yang butuh SP Manual. Apabila ada retur, catat di Delivery Note dan update ke IC
A27: service_level (E) | B27: =VLOOKUP($B$3,$D$4:$G$6,2,FALSE)
A28: branch_id (AE) | B28: =VLOOKUP($B$3,$D$4:$G$6,3,FALSE)
A29: is_pickup_required (X) | B29: =VLOOKUP($B$3,$D$4:$G$6,4,FALSE)

Sheet TMP Paste
A1: Pharmacy Name | B1: SwipeAWB | C1: Total Weight per AWB (kg) | D1: Total Volume per AWB (m3) | E1: PO Number | F1: Pharmacy's Id | G1: Note's | H1: Picking Priority | I1: Pharmacy's Id - Address | J1: Zip Code | K1: City | L1: Phone | M1: Koli
A2: Apotek Afia | B2: AWB02WJVH | C2: 0.3 | D2: 0.001423 | E2: 26072713473538DTjozNXFa | F2: 3062 | G2: 26072713473538DTjozNXFa | H2: P4N | I2: 3062-Jalan MI Ridwan Rais No.3 RT 002 RW 006 Kelurahan Beji Timur Kecamatan Beji Kota Depok 16422 | J2: 16422 | K2: Kota Depok | L2: 895808010200 | M2: 1
A3: Apotek Alam Sehat Farma | B3: AWB02WJ90 | C3: 1.2 | D3: 0.002902 | E3: 26072707484936JExQscwbq | F3: 836 | G3: 26072707484936JExQscwbq | H3: P4N | I3: 836-Jalan Anggrek Raya No. 27-28 RT 002/004 Kelurahan Depok Jaya Kecamatan Pancoran Mas 16432 | J3: 16432 | K3: Kota Depok | L3: 81382701345 | M3: 1
A4: Apotek Ben Waras 19 | B4: AWB02WL4S | C4: 0.46 | D4: 0.001794 | E4: 26072802143715UaH54d1OD | F4: 903 | G4: 26072802143715UaH54d1OD | H4: P4N | I4: 903-Jalan Karya Ruko Tugu Bedahan No. 10 RT.001 RW.16 Kelurahan Bedahan, Kecamatan Sawangan, Kota Depok, Jawa Barat 16519 | J4: 16519 | K4: Kota Depok | L4: 6289510341165 | M4: 1
A5: Apotek Berkah 9 | B5: AWB02WKTT | C5: 3.04 | D5: 0.009864 | E5: 26072801412330Cygue4Ku6 | F5: 3479 | G5: 26072801412330Cygue4Ku6-26072802554064GKk0wdiYh-26072802554064ljldqS88pC | H5: P4N | I5: 3479-Jalan Raya Pasir Putih Ruko Cahaya Garuda No. 6 RT 005 RW 009 Sawangan Permai Kelurahan Pasir Putih Kecamatan Sawangan Kota Depok 16519 | J5: 16519 | K5: Kota Depok | L5: 8979743443 | M5: 1
E6: 26072802554064GKk0wdiYh | M6: 1
E7: 26072802554064ljldqS88pC | M7: 1
A8: Apotek Berlian Farma | B8: AWB02WKFU | C8: 7.9 | D8: 0.023541 | E8: 26072800444949VmLEmOlB9 | F8: 667 | G8: 26072800444949VmLEmOlB9-260728010345500SexiSn1Av-26072801034550trixNIPaR-26072801473602jTFSiKfF | H8: P4N | I8: 667-Komplek Permata Jasindo Lestari Blok A6/14 RT.007 RW.004 Kelurahan Mekarsari, Kecamatan Cimanggis, Kota Depok 16452 | J8: 16452 | K8: Kota Depok | L8: 85374101944 | M8: 1
E9: 260728010345500SexiSn1Av | M9: 1
E10: 26072801034550trixNIPaR | M10: 1
E11: 26072801473602jTFSiKfF | M11: 1
A12: Apotek Berlian Farma Rasamala Bakti Jaya Sukmajaya | B12: AWB02WGVD | C12: 7.4 | D12: 0.023336 | E12: 26072703245809wQimRVF1 | F12: 11437 | G12: 26072703245809wQimRVF1-26072802522246IUjxQvWbh-26072802592265RiGBF708N-26072802592265wqZCVet0V | H12: P4N | I12: 11437-Jl. Rasamala Raya No. 423 Kel. Baktijaya Kec. Sukmajaya Kota Depok 16418 | J12: 16418 | K12: Kota Depok | L12: 6285374101944 | M12: 1
E13: 26072802522246IUjxQvWbh | M13: 1
E14: 26072802592265RiGBF708N | M14: 1
E15: 26072802592265wqZCVet0V | M15: 1
A16: Apotek Bersama Plus Jatimulya Cilodong | B16: AWB02WJRN | C16: 7.31 | D16: 0.035554 | E16: 26072712475211w4O3Py9yv | F16: 15120 | G16: 26072712475211w4O3Py9yv-260727124752122dYBQKGDe-26072712475212Ec78WQpCrD-26072712475212XTxGNiHixm | H16: P4N | I16: 15120-Jalan Pondok Rajeg RT 01 RW 01 NO 79, Desa/Kelurahan Jatimulya, Kec. Cilodong, Kota Depok, Provinsi Jawa Barat, | J16: 16413 | K16: Kota Depok | L16: 6285282565256 | M16: 1
E17: 260727124752122dYBQKGDe | M17: 1
E18: 26072712475212Ec78WQpCrD | M18: 1
E19: 26072712475212XTxGNiHixm | M19: 1
A20: Apotek Bersama Pondok Ranggon Cipayung | B20: AWB02WKH1 | C20: 0.53 | D20: 0.001416 | E20: 26072800513343zU8ph3SKJ | F20: 12430 | G20: 26072800513343zU8ph3SKJ | H20: P4N | I20: 12430-Jl Raya Pondok Ranggon RT 006 RW 004 Kel. Pondok Ranggon Kec. Cipayung, Jakarta Timur | J20: 13860 | K20: Kota Jakarta Timur | L20: 6289529655094 | M20: 1
A21: Apotek Bumi Sehat Serua Bojongsari | B21: AWB02WJ9B | C21: 0.44 | D21: 0.002296 | E21: 26072707523848Dhpuftwa | F21: 11084 | G21: 26072707523848Dhpuftwa | H21: P4N | I21: 11084-Jl. Serua Raya, Kel Serua Kec. Bojongsari, Kota Depok, 16517 | J21: 16517 | K21: Kota Depok | L21: 6281934028112 | M21: 1
A22: Apotek Bunda Bedahan Sawangan | B22: AWB02WJJX | C22: 1.05 | D22: 0.002578 | E22: 26072710184801AQgMPUJcI | F22: 13593 | G22: 26072710184801AQgMPUJcI | H22: P4N | I22: 13593-Jl. H. Sulaiman No.06, RT004/RW007, Desa/Kelurahan Bedahan, Kec. Sawangan, Kota Depok | J22: 16519 | K22: Kota Depok | L22: 6281382843554 | M22: 1
A23: Apotek Cipayung 1 | B23: AWB02WKTX | C23: 9.89 | D23: 0.035966 | E23: 260728014140360ppVZvbV | F23: 8251 | G23: 260728014140360ppVZvbV-26072801414037XH6dCj30sh-260728015619662gr5Ce0Coa-26072801561966LCCsOJtss | H23: P4N | I23: 8251-Jl. Raya Jembatan Serong Blok Sawo No. 115 RT. 002 RW. 003 Kel. Cipayung Kec. Cipayung Kota Depok | J23: 16437 | K23: Kota Depok | L23: 81264043044 | M23: 1
E24: 26072801414037XH6dCj30sh | M24: 1
E25: 260728015619662gr5Ce0Coa | M25: 1
E26: 26072801561966LCCsOJtss | M26: 1
A27: Apotek Cita Sehat Curug Bojongsari | B27: AWB02WJMZ | C27: 7.39 | D27: 0.035216 | E27: 26072711371829bD90OfAG | F27: 13096 | G27: 26072711371829bD90OfAG-26072711371829hZImrWHPpe-26072711371829MedkSjEjj | H27: P4N | I27: 13096-Jl. Raya Curug Ciputat RT 001 RW 002 Kel. Curug Kec. Bojongsari Kota Depok | J27: 16517 | K27: Kota Depok | L27: 6285220978760 | M27: 1
E28: 26072711371829hZImrWHPpe | M28: 1
E29: 26072711371829MedkSjEjj | M29: 1
A30: Apotek Clara Jaya | B30: AWB02WJ03 | C30: 0.21 | D30: 0.001617 | E30: 260727060846087GrvfxYt | F30: 2649 | G30: 260727060846087GrvfxYt | H30: P4N | I30: 2649-Jalan Monumen Pancasila Sakti RT 007 RW 002 Kelurahan Lubang Buaya Kecamatan Cipayung Jakarta Timur 13810 | J30: 13810 | K30: Kota Jakarta Timur | L30: 6285748601748 | M30: 1
A31: Apotek Dafa Cipayung Cipayung | B31: AWB02WJ9T | C31: 11.51 | D31: 0.040022 | E31: 26072707560190rhBnVpiLi | F31: 13177 | G31: 26072707560190rhBnVpiLi-26072707560190ymqgVdWPi | H31: P4N | I31: 13177-Jl. Jembatan Serong RT 006 RW 002 Kel. Cipayung Kec. Cipayung Kota Depok | J31: 16437 | K31: Kota Depok | L31: 6282364343108 | M31: 2
E32: 26072707560190ymqgVdWPi | M32: 1
A33: Apotek Damai | B33: AWB02WJC8 | C33: 0.25 | D33: 0.00168 | E33: 26072708294775X2jgOh7r | F33: 317 | G33: 26072708294775X2jgOh7r | H33: P4N | I33: 317-Jl. Menpor No. 12, Palsigunung, RT. 007 / RW. 003, Kelurahan Tugu, Kecamatan Cimanggis, Depok, Jawa Barat 16451 | J33: 16451 | K33: Kota Depok | L33: 81296144347 | M33: 1
A34: Apotek Dewi Farma | B34: AWB02WJ7E | C34: 3.67 | D34: 0.009967 | E34: 26072707241110QJcTk8YNC | F34: 724 | G34: 26072707241110QJcTk8YNC | H34: P4N | I34: 724-Jalan Mess AL Kranggan Wetan RT.001/RW.012, Kelurahan Jatirangga, Kecamatan Jatisampurna, Kota Bekasi 17434 | J34: 17434 | K34: Kota Bekasi | L34: 85283705505 | M34: 2
A35: Apotek Faisal | B35: AWB02WKEL | C35: 1.11 | D35: 0.003461 | E35: 26072800322508vKhc2TWx9 | F35: 1442 | G35: 26072800322508vKhc2TWx9 | H35: P4N | I35: 1442-Jalan Tawangmangu Raya Blok C2 No. 4 RT 19 RW 07 Kelurahan Jati Cempaka Kecamatan Pondok Gede Kota Bekasi 17411 | J35: 17411 | K35: Kota Bekasi | L35: 87773506955 | M35: 1
A36: Apotek FarmaDok Jatiranggon Jatisampurna | B36: AWB02WJT2 | C36: 9.39 | D36: 0.031097 | E36: 260727130541123P9fwqGX8k | F36: 17703 | G36: 260727130541123P9fwqGX8k-26072713054112jKXG2Pgb2D-26072713054112VQ5BgPLP | H36: P4N | I36: 17703-Jl. Raya Kranggan No. 93 RT.006/RW.005, Desa/Kelurahan Jatiranggon, Kec. Jatisampurna, Kota Bekasi | J36: 17432 | K36: Kota Bekasi | L36: 6285885477255 | M36: 1
E37: 26072713054112jKXG2Pgb2D | M37: 2
E38: 26072713054112VQ5BgPLP | M38: 1
A39: Apotek Fatih Jatibening Baru Pondok Gede | B39: AWB02WJMV | C39: 9.83 | D39: 0.021641 | E39: 26072711350898koIZhWruw | F39: 16587 | G39: 26072711350898koIZhWruw-26072711350899gtRmMQ5NSR-26072711471783EBYJf2XQ8B-26072711471783v1Ybwtvm | H39: P4N | I39: 16587-Jl. Lampiri Raya No.108 B Desa/Kelurahan Jatibening Baru,Kecamatan Pondok Gede, Kota Bekasi, Jawa Barat, 17412 | J39: 17412 | K39: Kota Bekasi | L39: 6281214148920 | M39: 1
E40: 26072711350899gtRmMQ5NSR | M40: 1
...

Sheet OC Upload
A1: requested_tracking_number | B1: global_shipper_id | C1: service_type | D1: reference.merchant_order_number | E1: service_level | F1: from.name | G1: from.phone_number | H1: from.address.address1 | I1: from.address.country | J1: to.name | K1: to.phone_number | L1: to.address.address1 | M1: to.address.country | N1: to.address.kecamatan | O1: to.address.city | P1: to.address.province | Q1: to.address.postcode | R1: parcel_job.delivery_instructions | S1: parcel_job.delivery_start_date | T1: parcel_job.delivery_timeslot.start_time | U1: parcel_job.delivery_timeslot.end_time | V1: parcel_job.delivery_timeslot.timezone | W1: parcel_job.dimensions.weight | X1: parcel_job.is_pickup_required | Y1: parcel_job.items.0.item_description | Z1: parcel_job.items.0.is_dangerous_good | AA1: b2b.documents_required | AB1: bundle_information.total_quantity | AC1: bundle_information.requested_piece_tracking_numbers | AD1: parcel_job.insured_value | AE1: corporate.branch_id | AQ1: CEK (jangan upload)
A2: =IF($AG2="","",INDEX('TMP Paste'!$B$2:$B$1601,$AG2)) | B2: =IF($AG2="","",Config!$B$14) | C2: =IF($AG2="","",Config!$B$15) | D2: =IF($AG2="","",INDEX('TMP Paste'!$B$2:$B$1601,$AG2)) | E2: =IF($AG2="","",Config!$B$27) | F2: =IF($AG2="","",Config!$B$9) | G2: =IF($AG2="","",Config!$B$10) | H2: =IF($AG2="","",Config!$B$11) | I2: =IF($AG2="","",Config!$B$16) | J2: =IF($AG2="","",INDEX('TMP Paste'!$A$2:$A$1601,$AG2)) | K2: =IF($AG2="","",INDEX('TMP Paste'!$L$2:$L$1601,$AG2)) | L2: =IF($AG2="","",INDEX('TMP Paste'!$I$2:$I$1601,$AG2)) | M2: =IF($AG2="","",Config!$B$16) | N2: =IF($AG2="","","") | O2: =IF($AG2="","",INDEX('TMP Paste'!$K$2:$K$1601,$AG2)) | P2: =IF($AG2="","","") | Q2: =IF($AG2="","",INDEX('TMP Paste'!$J$2:$J$1601,$AG2)) | R2: =IF($AG2="","",Config!$B$24) | S2: =IF($AG2="","",TEXT(Config!$B$4,"yyyy-mm-dd")) | T2: =IF($AG2="","",Config!$B$17) | U2: =IF($AG2="","",Config!$B$18) | V2: =IF($AG2="","",Config!$B$19) | W2: =IF($AG2="","",INDEX('TMP Paste'!$C$2:$C$1601,$AG2)) | X2: =IF($AG2="","",Config!$B$29) | Y2: =IF($AH2="","",INDEX(Calc!$I$2:$I$1601,$AH2)&" - "&INDEX(Calc!$D$2:$D$1601,$AH2)&" koli") | Z2: =IF($AG2="","",Config!$B$21) | AA2: =IF($AG2="","",Config!$B$22) | AB2: =IF($AH2="","",INDEX(Calc!$D$2:$D$1601,$AH2)) | AC2: =IF($AH2="","",INDEX(Calc!$G$2:$G$1601,$AH2)) | AD2: =IF($AG2="","",Config!$B$23) | AE2: =IF($AG2="","",Config!$B$28) | AG2: =IFERROR(MATCH(ROW()-1,Calc!$J$2:$J$1601,0),"") | AH2: =IFERROR(MATCH(ROW()-1,Calc!$K$2:$K$1601,0),"") | AI2: =IF($AG2="","",SUMIF($AG$2:$AG2,$AG2,$AH$2:$AH2)) | AJ2: =IF('TMP Paste'!$F2="","",IF('TMP Paste'!$B2="",$AJ1,'TMP Paste'!$B2)) | AK2: =IF('TMP Paste'!$F2="","",N('TMP Paste'!$G2)) | AL2: =IF('TMP Paste'!$F2="","",IF('TMP Paste'!$M2="",$AL1,'TMP Paste'!$M2)) | AM2: =IF('TMP Paste'!$F2="","",IF('TMP Paste'!$N2="",$AM1,'TMP Paste'!$N2)) | AN2: =IF('TMP Paste'!$F2="","",IF('TMP Paste'!$O2="",$AN1,'TMP Paste'!$O2)) | AO2: =IF('TMP Paste'!$F2="","",IF('TMP Paste'!$P2="",$AO1,'TMP Paste'!$P2)) | AP2: =IF($AG2="","",LEN($R2)) | AQ2: =IF($AG2="","",TRIM(IF(COUNTIFS(Calc!$B$2:$B$1601,ROW()-1,Calc!$C$2:$C$1601,"<1")>0,"Ada PO tanpa Koli - cek TMP. ","")&IF(LEN($R2)>500,"R > 500 karakter.","")))
A3: =IF($AG3="","",INDEX('TMP Paste'!$B$2:$B$1601,$AG3)) | B3: =IF($AG3="","",Config!$B$14) | C3: =IF($AG3="","",Config!$B$15) | D3: =IF($AG3="","",INDEX('TMP Paste'!$B$2:$B$1601,$AG3)) | E3: =IF($AG3="","",Config!$B$27) | F3: =IF($AG3="","",Config!$B$9) | G3: =IF($AG3="","",Config!$B$10) | H3: =IF($AG3="","",Config!$B$11) | I3: =IF($AG3="","",Config!$B$16) | J3: =IF($AG3="","",INDEX('TMP Paste'!$A$2:$A$1601,$AG3)) | K3: =IF($AG3="","",INDEX('TMP Paste'!$L$2:$L$1601,$AG3)) | L3: =IF($AG3="","",INDEX('TMP Paste'!$I$2:$I$1601,$AG3)) | M3: =IF($AG3="","",Config!$B$16) | N3: =IF($AG3="","","") | O3: =IF($AG3="","",INDEX('TMP Paste'!$K$2:$K$1601,$AG3)) | P3: =IF($AG3="","","") | Q3: =IF($AG3="","",INDEX('TMP Paste'!$J$2:$J$1601,$AG3)) | R3: =IF($AG3="","",Config!$B$24) | S3: =IF($AG3="","",TEXT(Config!$B$4,"yyyy-mm-dd")) | T3: =IF($AG3="","",Config!$B$17) | U3: =IF($AG3="","",Config!$B$18) | V3: =IF($AG3="","",Config!$B$19) | W3: =IF($AG3="","",INDEX('TMP Paste'!$C$2:$C$1601,$AG3)) | X3: =IF($AG3="","",Config!$B$29) | Y3: =IF($AH3="","",INDEX(Calc!$I$2:$I$1601,$AH3)&" - "&INDEX(Calc!$D$2:$D$1601,$AH3)&" koli") | Z3: =IF($AG3="","",Config!$B$21) | AA3: =IF($AG3="","",Config!$B$22) | AB3: =IF($AH3="","",INDEX(Calc!$D$2:$D$1601,$AH3)) | AC3: =IF($AH3="","",INDEX(Calc!$G$2:$G$1601,$AH3)) | AD3: =IF($AG3="","",Config!$B$23) | AE3: =IF($AG3="","",Config!$B$28) | AG3: =IFERROR(MATCH(ROW()-1,Calc!$J$2:$J$1601,0),"") | AH3: =IFERROR(MATCH(ROW()-1,Calc!$K$2:$K$1601,0),"") | AI3: =IF($AG3="","",SUMIF($AG$2:$AG3,$AG3,$AH$2:$AH3)) | AJ3: =IF('TMP Paste'!$F3="","",IF('TMP Paste'!$B3="",$AJ2,'TMP Paste'!$B3)) | AK3: =IF('TMP Paste'!$F3="","",N('TMP Paste'!$G3)) | AL3: =IF('TMP Paste'!$F3="","",IF('TMP Paste'!$M3="",$AL2,'TMP Paste'!$M3)) | AM3: =IF('TMP Paste'!$F3="","",IF('TMP Paste'!$N3="",$AM2,'TMP Paste'!$N3)) | AN3: =IF('TMP Paste'!$F3="","",IF('TMP Paste'!$O3="",$AN2,'TMP Paste'!$O3)) | AO3: =IF('TMP Paste'!$F3="","",IF('TMP Paste'!$P3="",$AO2,'TMP Paste'!$P3)) | AP3: =IF($AG3="","",LEN($R3)) | AQ3: =IF($AG3="","",TRIM(IF(COUNTIFS(Calc!$B$2:$B$1601,ROW()-1,Calc!$C$2:$C$1601,"<1")>0,"Ada PO tanpa Koli - cek TMP. ","")&IF(LEN($R3)>500,"R > 500 karakter.","")))
A4: =IF($AG4="","",INDEX('TMP Paste'!$B$2:$B$1601,$AG4)) | B4: =IF($AG4="","",Config!$B$14) | C4: =IF($AG4="","",Config!$B$15) | D4: =IF($AG4="","",INDEX('TMP Paste'!$B$2:$B$1601,$AG4)) | E4: =IF($AG4="","",Config!$B$27) | F4: =IF($AG4="","",Config!$B$9) | G4: =IF($AG4="","",Config!$B$10) | H4: =IF($AG4="","",Config!$B$11) | I4: =IF($AG4="","",Config!$B$16) | J4: =IF($AG4="","",INDEX('TMP Paste'!$A$2:$A$1601,$AG4)) | K4: =IF($AG4="","",INDEX('TMP Paste'!$L$2:$L$1601,$AG4)) | L4: =IF($AG4="","",INDEX('TMP Paste'!$I$2:$I$1601,$AG4)) | M4: =IF($AG4="","",Config!$B$16) | N4: =IF($AG4="","","") | O4: =IF($AG4="","",INDEX('TMP Paste'!$K$2:$K$1601,$AG4)) | P4: =IF($AG4="","","") | Q4: =IF($AG4="","",INDEX('TMP Paste'!$J$2:$J$1601,$AG4)) | R4: =IF($AG4="","",Config!$B$24) | S4: =IF($AG4="","",TEXT(Config!$B$4,"yyyy-mm-dd")) | T4: =IF($AG4="","",Config!$B$17) | U4: =IF($AG4="","",Config!$B$18) | V4: =IF($AG4="","",Config!$B$19) | W4: =IF($AG4="","",INDEX('TMP Paste'!$C$2:$C$1601,$AG4)) | X4: =IF($AG4="","",Config!$B$29) | Y4: =IF($AH4="","",INDEX(Calc!$I$2:$I$1601,$AH4)&" - "&INDEX(Calc!$D$2:$D$1601,$AH4)&" koli") | Z4: =IF($AG4="","",Config!$B$21) | AA4: =IF($AG4="","",Config!$B$22) | AB4: =IF($AH4="","",INDEX(Calc!$D$2:$D$1601,$AH4)) | AC4: =IF($AH4="","",INDEX(Calc!$G$2:$G$1601,$AH4)) | AD4: =IF($AG4="","",Config!$B$23) | AE4: =IF($AG4="","",Config!$B$28) | AG4: =IFERROR(MATCH(ROW()-1,Calc!$J$2:$J$1601,0),"") | AH4: =IFERROR(MATCH(ROW()-1,Calc!$K$2:$K$1601,0),"") | AI4: =IF($AG4="","",SUMIF($AG$2:$AG4,$AG4,$AH$2:$AH4)) | AJ4: =IF('TMP Paste'!$F4="","",IF('TMP Paste'!$B4="",$AJ3,'TMP Paste'!$B4)) | AK4: =IF('TMP Paste'!$F4="","",N('TMP Paste'!$G4)) | AL4: =IF('TMP Paste'!$F4="","",IF('TMP Paste'!$M4="",$AL3,'TMP Paste'!$M4)) | AM4: =IF('TMP Paste'!$F4="","",IF('TMP Paste'!$N4="",$AM3,'TMP Paste'!$N4)) | AN4: =IF('TMP Paste'!$F4="","",IF('TMP Paste'!$O4="",$AN3,'TMP Paste'!$O4)) | AO4: =IF('TMP Paste'!$F4="","",IF('TMP Paste'!$P4="",$AO3,'TMP Paste'!$P4)) | AP4: =IF($AG4="","",LEN($R4)) | AQ4: =IF($AG4="","",TRIM(IF(COUNTIFS(Calc!$B$2:$B$1601,ROW()-1,Calc!$C$2:$C$1601,"<1")>0,"Ada PO tanpa Koli - cek TMP. ","")&IF(LEN($R4)>500,"R > 500 karakter.","")))
A5: =IF($AG5="","",INDEX('TMP Paste'!$B$2:$B$1601,$AG5)) | B5: =IF($AG5="","",Config!$B$14) | C5: =IF($AG5="","",Config!$B$15) | D5: =IF($AG5="","",INDEX('TMP Paste'!$B$2:$B$1601,$AG5)) | E5: =IF($AG5="","",Config!$B$27) | F5: =IF($AG5="","",Config!$B$9) | G5: =IF($AG5="","",Config!$B$10) | H5: =IF($AG5="","",Config!$B$11) | I5: =IF($AG5="","",Config!$B$16) | J5: =IF($AG5="","",INDEX('TMP Paste'!$A$2:$A$1601,$AG5)) | K5: =IF($AG5="","",INDEX('TMP Paste'!$L$2:$L$1601,$AG5)) | L5: =IF($AG5="","",INDEX('TMP Paste'!$I$2:$I$1601,$AG5)) | M5: =IF($AG5="","",Config!$B$16) | N5: =IF($AG5="","","") | O5: =IF($AG5="","",INDEX('TMP Paste'!$K$2:$K$1601,$AG5)) | P5: =IF($AG5="","","") | Q5: =IF($AG5="","",INDEX('TMP Paste'!$J$2:$J$1601,$AG5)) | R5: =IF($AG5="","",Config!$B$24) | S5: =IF($AG5="","",TEXT(Config!$B$4,"yyyy-mm-dd")) | T5: =IF($AG5="","",Config!$B$17) | U5: =IF($AG5="","",Config!$B$18) | V5: =IF($AG5="","",Config!$B$19) | W5: =IF($AG5="","",INDEX('TMP Paste'!$C$2:$C$1601,$AG5)) | X5: =IF($AG5="","",Config!$B$29) | Y5: =IF($AH5="","",INDEX(Calc!$I$2:$I$1601,$AH5)&" - "&INDEX(Calc!$D$2:$D$1601,$AH5)&" koli") | Z5: =IF($AG5="","",Config!$B$21) | AA5: =IF($AG5="","",Config!$B$22) | AB5: =IF($AH5="","",INDEX(Calc!$D$2:$D$1601,$AH5)) | AC5: =IF($AH5="","",INDEX(Calc!$G$2:$G$1601,$AH5)) | AD5: =IF($AG5="","",Config!$B$23) | AE5: =IF($AG5="","",Config!$B$28) | AG5: =IFERROR(MATCH(ROW()-1,Calc!$J$2:$J$1601,0),"") | AH5: =IFERROR(MATCH(ROW()-1,Calc!$K$2:$K$1601,0),"") | AI5: =IF($AG5="","",SUMIF($AG$2:$AG5,$AG5,$AH$2:$AH5)) | AJ5: =IF('TMP Paste'!$F5="","",IF('TMP Paste'!$B5="",$AJ4,'TMP Paste'!$B5)) | AK5: =IF('TMP Paste'!$F5="","",N('TMP Paste'!$G5)) | AL5: =IF('TMP Paste'!$F5="","",IF('TMP Paste'!$M5="",$AL4,'TMP Paste'!$M5)) | AM5: =IF('TMP Paste'!$F5="","",IF('TMP Paste'!$N5="",$AM4,'TMP Paste'!$N5)) | AN5: =IF('TMP Paste'!$F5="","",IF('TMP Paste'!$O5="",$AN4,'TMP Paste'!$O5)) | AO5: =IF('TMP Paste'!$F5="","",IF('TMP Paste'!$P5="",$AO4,'TMP Paste'!$P5)) | AP5: =IF($AG5="","",LEN($R5)) | AQ5: =IF($AG5="","",TRIM(IF(COUNTIFS(Calc!$B$2:$B$1601,ROW()-1,Calc!$C$2:$C$1601,"<1")>0,"Ada PO tanpa Koli - cek TMP. ","")&IF(LEN($R5)>500,"R > 500 karakter.","")))
A6: =IF($AG6="","",INDEX('TMP Paste'!$B$2:$B$1601,$AG6)) | B6: =IF($AG6="","",Config!$B$14) | C6: =IF($AG6="","",Config!$B$15) | D6: =IF($AG6="","",INDEX('TMP Paste'!$B$2:$B$1601,$AG6)) | E6: =IF($AG6="","",Config!$B$27) | F6: =IF($AG6="","",Config!$B$9) | G6: =IF($AG6="","",Config!$B$10) | H6: =IF($AG6="","",Config!$B$11) | I6: =IF($AG6="","",Config!$B$16) | J6: =IF($AG6="","",INDEX('TMP Paste'!$A$2:$A$1601,$AG6)) | K6: =IF($AG6="","",INDEX('TMP Paste'!$L$2:$L$1601,$AG6)) | L6: =IF($AG6="","",INDEX('TMP Paste'!$I$2:$I$1601,$AG6)) | M6: =IF($AG6="","",Config!$B$16) | N6: =IF($AG6="","","") | O6: =IF($AG6="","",INDEX('TMP Paste'!$K$2:$K$1601,$AG6)) | P6: =IF($AG6="","","") | Q6: =IF($AG6="","",INDEX('TMP Paste'!$J$2:$J$1601,$AG6)) | R6: =IF($AG6="","",Config!$B$24) | S6: =IF($AG6="","",TEXT(Config!$B$4,"yyyy-mm-dd")) | T6: =IF($AG6="","",Config!$B$17) | U6: =IF($AG6="","",Config!$B$18) | V6: =IF($AG6="","",Config!$B$19) | W6: =IF($AG6="","",INDEX('TMP Paste'!$C$2:$C$1601,$AG6)) | X6: =IF($AG6="","",Config!$B$29) | Y6: =IF($AH6="","",INDEX(Calc!$I$2:$I$1601,$AH6)&" - "&INDEX(Calc!$D$2:$D$1601,$AH6)&" koli") | Z6: =IF($AG6="","",Config!$B$21) | AA6: =IF($AG6="","",Config!$B$22) | AB6: =IF($AH6="","",INDEX(Calc!$D$2:$D$1601,$AH6)) | AC6: =IF($AH6="","",INDEX(Calc!$G$2:$G$1601,$AH6)) | AD6: =IF($AG6="","",Config!$B$23) | AE6: =IF($AG6="","",Config!$B$28) | AG6: =IFERROR(MATCH(ROW()-1,Calc!$J$2:$J$1601,0),"") | AH6: =IFERROR(MATCH(ROW()-1,Calc!$K$2:$K$1601,0),"") | AI6: =IF($AG6="","",SUMIF($AG$2:$AG6,$AG6,$AH$2:$AH6)) | AJ6: =IF('TMP Paste'!$F6="","",IF('TMP Paste'!$B6="",$AJ5,'TMP Paste'!$B6)) | AK6: =IF('TMP Paste'!$F6="","",N('TMP Paste'!$G6)) | AL6: =IF('TMP Paste'!$F6="","",IF('TMP Paste'!$M6="",$AL5,'TMP Paste'!$M6)) | AM6: =IF('TMP Paste'!$F6="","",IF('TMP Paste'!$N6="",$AM5,'TMP Paste'!$N6)) | AN6: =IF('TMP Paste'!$F6="","",IF('TMP Paste'!$O6="",$AN5,'TMP Paste'!$O6)) | AO6: =IF('TMP Paste'!$F6="","",IF('TMP Paste'!$P6="",$AO5,'TMP Paste'!$P6)) | AP6: =IF($AG6="","",LEN($R6)) | AQ6: =IF($AG6="","",TRIM(IF(COUNTIFS(Calc!$B$2:$B$1601,ROW()-1,Calc!$C$2:$C$1601,"<1")>0,"Ada PO tanpa Koli - cek TMP. ","")&IF(LEN($R6)>500,"R > 500 karakter.","")))
A7: =IF($AG7="","",INDEX('TMP Paste'!$B$2:$B$1601,$AG7)) | B7: =IF($AG7="","",Config!$B$14) | C7: =IF($AG7="","",Config!$B$15) | D7: =IF($AG7="","",INDEX('TMP Paste'!$B$2:$B$1601,$AG7)) | E7: =IF($AG7="","",Config!$B$27) | F7: =IF($AG7="","",Config!$B$9) | G7: =IF($AG7="","",Config!$B$10) | H7: =IF($AG7="","",Config!$B$11) | I7: =IF($AG7="","",Config!$B$16) | J7: =IF($AG7="","",INDEX('TMP Paste'!$A$2:$A$1601,$AG7)) | K7: =IF($AG7="","",INDEX('TMP Paste'!$L$2:$L$1601,$AG7)) | L7: =IF($AG7="","",INDEX('TMP Paste'!$I$2:$I$1601,$AG7)) | M7: =IF($AG7="","",Config!$B$16) | N7: =IF($AG7="","","") | O7: =IF($AG7="","",INDEX('TMP Paste'!$K$2:$K$1601,$AG7)) | P7: =IF($AG7="","","") | Q7: =IF($AG7="","",INDEX('TMP Paste'!$J$2:$J$1601,$AG7)) | R7: =IF($AG7="","",Config!$B$24) | S7: =IF($AG7="","",TEXT(Config!$B$4,"yyyy-mm-dd")) | T7: =IF($AG7="","",Config!$B$17) | U7: =IF($AG7="","",Config!$B$18) | V7: =IF($AG7="","",Config!$B$19) | W7: =IF($AG7="","",INDEX('TMP Paste'!$C$2:$C$1601,$AG7)) | X7: =IF($AG7="","",Config!$B$29) | Y7: =IF($AH7="","",INDEX(Calc!$I$2:$I$1601,$AH7)&" - "&INDEX(Calc!$D$2:$D$1601,$AH7)&" koli") | Z7: =IF($AG7="","",Config!$B$21) | AA7: =IF($AG7="","",Config!$B$22) | AB7: =IF($AH7="","",INDEX(Calc!$D$2:$D$1601,$AH7)) | AC7: =IF($AH7="","",INDEX(Calc!$G$2:$G$1601,$AH7)) | AD7: =IF($AG7="","",Config!$B$23) | AE7: =IF($AG7="","",Config!$B$28) | AG7: =IFERROR(MATCH(ROW()-1,Calc!$J$2:$J$1601,0),"") | AH7: =IFERROR(MATCH(ROW()-1,Calc!$K$2:$K$1601,0),"") | AI7: =IF($AG7="","",SUMIF($AG$2:$AG7,$AG7,$AH$2:$AH7)) | AJ7: =IF('TMP Paste'!$F7="","",IF('TMP Paste'!$B7="",$AJ6,'TMP Paste'!$B7)) | AK7: =IF('TMP Paste'!$F7="","",N('TMP Paste'!$G7)) | AL7: =IF('TMP Paste'!$F7="","",IF('TMP Paste'!$M7="",$AL6,'TMP Paste'!$M7)) | AM7: =IF('TMP Paste'!$F7="","",IF('TMP Paste'!$N7="",$AM6,'TMP Paste'!$N7)) | AN7: =IF('TMP Paste'!$F7="","",IF('TMP Paste'!$O7="",$AN6,'TMP Paste'!$O7)) | AO7: =IF('TMP Paste'!$F7="","",IF('TMP Paste'!$P7="",$AO6,'TMP Paste'!$P7)) | AP7: =IF($AG7="","",LEN($R7)) | AQ7: =IF($AG7="","",TRIM(IF(COUNTIFS(Calc!$B$2:$B$1601,ROW()-1,Calc!$C$2:$C$1601,"<1")>0,"Ada PO tanpa Koli - cek TMP. ","")&IF(LEN($R7)>500,"R > 500 karakter.","")))
A8: =IF($AG8="","",INDEX('TMP Paste'!$B$2:$B$1601,$AG8)) | B8: =IF($AG8="","",Config!$B$14) | C8: =IF($AG8="","",Config!$B$15) | D8: =IF($AG8="","",INDEX('TMP Paste'!$B$2:$B$1601,$AG8)) | E8: =IF($AG8="","",Config!$B$27) | F8: =IF($AG8="","",Config!$B$9) | G8: =IF($AG8="","",Config!$B$10) | H8: =IF($AG8="","",Config!$B$11) | I8: =IF($AG8="","",Config!$B$16) | J8: =IF($AG8="","",INDEX('TMP Paste'!$A$2:$A$1601,$AG8)) | K8: =IF($AG8="","",INDEX('TMP Paste'!$L$2:$L$1601,$AG8)) | L8: =IF($AG8="","",INDEX('TMP Paste'!$I$2:$I$1601,$AG8)) | M8: =IF($AG8="","",Config!$B$16) | N8: =IF($AG8="","","") | O8: =IF($AG8="","",INDEX('TMP Paste'!$K$2:$K$1601,$AG8)) | P8: =IF($AG8="","","") | Q8: =IF($AG8="","",INDEX('TMP Paste'!$J$2:$J$1601,$AG8)) | R8: =IF($AG8="","",Config!$B$24) | S8: =IF($AG8="","",TEXT(Config!$B$4,"yyyy-mm-dd")) | T8: =IF($AG8="","",Config!$B$17) | U8: =IF($AG8="","",Config!$B$18) | V8: =IF($AG8="","",Config!$B$19) | W8: =IF($AG8="","",INDEX('TMP Paste'!$C$2:$C$1601,$AG8)) | X8: =IF($AG8="","",Config!$B$29) | Y8: =IF($AH8="","",INDEX(Calc!$I$2:$I$1601,$AH8)&" - "&INDEX(Calc!$D$2:$D$1601,$AH8)&" koli") | Z8: =IF($AG8="","",Config!$B$21) | AA8: =IF($AG8="","",Config!$B$22) | AB8: =IF($AH8="","",INDEX(Calc!$D$2:$D$1601,$AH8)) | AC8: =IF($AH8="","",INDEX(Calc!$G$2:$G$1601,$AH8)) | AD8: =IF($AG8="","",Config!$B$23) | AE8: =IF($AG8="","",Config!$B$28) | AG8: =IFERROR(MATCH(ROW()-1,Calc!$J$2:$J$1601,0),"") | AH8: =IFERROR(MATCH(ROW()-1,Calc!$K$2:$K$1601,0),"") | AI8: =IF($AG8="","",SUMIF($AG$2:$AG8,$AG8,$AH$2:$AH8)) | AJ8: =IF('TMP Paste'!$F8="","",IF('TMP Paste'!$B8="",$AJ7,'TMP Paste'!$B8)) | AK8: =IF('TMP Paste'!$F8="","",N('TMP Paste'!$G8)) | AL8: =IF('TMP Paste'!$F8="","",IF('TMP Paste'!$M8="",$AL7,'TMP Paste'!$M8)) | AM8: =IF('TMP Paste'!$F8="","",IF('TMP Paste'!$N8="",$AM7,'TMP Paste'!$N8)) | AN8: =IF('TMP Paste'!$F8="","",IF('TMP Paste'!$O8="",$AN7,'TMP Paste'!$O8)) | AO8: =IF('TMP Paste'!$F8="","",IF('TMP Paste'!$P8="",$AO7,'TMP Paste'!$P8)) | AP8: =IF($AG8="","",LEN($R8)) | AQ8: =IF($AG8="","",TRIM(IF(COUNTIFS(Calc!$B$2:$B$1601,ROW()-1,Calc!$C$2:$C$1601,"<1")>0,"Ada PO tanpa Koli - cek TMP. ","")&IF(LEN($R8)>500,"R > 500 karakter.","")))
A9: =IF($AG9="","",INDEX('TMP Paste'!$B$2:$B$1601,$AG9)) | B9: =IF($AG9="","",Config!$B$14) | C9: =IF($AG9="","",Config!$B$15) | D9: =IF($AG9="","",INDEX('TMP Paste'!$B$2:$B$1601,$AG9)) | E9: =IF($AG9="","",Config!$B$27) | F9: =IF($AG9="","",Config!$B$9) | G9: =IF($AG9="","",Config!$B$10) | H9: =IF($AG9="","",Config!$B$11) | I9: =IF($AG9="","",Config!$B$16) | J9: =IF($AG9="","",INDEX('TMP Paste'!$A$2:$A$1601,$AG9)) | K9: =IF($AG9="","",INDEX('TMP Paste'!$L$2:$L$1601,$AG9)) | L9: =IF($AG9="","",INDEX('TMP Paste'!$I$2:$I$1601,$AG9)) | M9: =IF($AG9="","",Config!$B$16) | N9: =IF($AG9="","","") | O9: =IF($AG9="","",INDEX('TMP Paste'!$K$2:$K$1601,$AG9)) | P9: =IF($AG9="","","") | Q9: =IF($AG9="","",INDEX('TMP Paste'!$J$2:$J$1601,$AG9)) | R9: =IF($AG9="","",Config!$B$24) | S9: =IF($AG9="","",TEXT(Config!$B$4,"yyyy-mm-dd")) | T9: =IF($AG9="","",Config!$B$17) | U9: =IF($AG9="","",Config!$B$18) | V9: =IF($AG9="","",Config!$B$19) | W9: =IF($AG9="","",INDEX('TMP Paste'!$C$2:$C$1601,$AG9)) | X9: =IF($AG9="","",Config!$B$29) | Y9: =IF($AH9="","",INDEX(Calc!$I$2:$I$1601,$AH9)&" - "&INDEX(Calc!$D$2:$D$1601,$AH9)&" koli") | Z9: =IF($AG9="","",Config!$B$21) | AA9: =IF($AG9="","",Config!$B$22) | AB9: =IF($AH9="","",INDEX(Calc!$D$2:$D$1601,$AH9)) | AC9: =IF($AH9="","",INDEX(Calc!$G$2:$G$1601,$AH9)) | AD9: =IF($AG9="","",Config!$B$23) | AE9: =IF($AG9="","",Config!$B$28) | AG9: =IFERROR(MATCH(ROW()-1,Calc!$J$2:$J$1601,0),"") | AH9: =IFERROR(MATCH(ROW()-1,Calc!$K$2:$K$1601,0),"") | AI9: =IF($AG9="","",SUMIF($AG$2:$AG9,$AG9,$AH$2:$AH9)) | AJ9: =IF('TMP Paste'!$F9="","",IF('TMP Paste'!$B9="",$AJ8,'TMP Paste'!$B9)) | AK9: =IF('TMP Paste'!$F9="","",N('TMP Paste'!$G9)) | AL9: =IF('TMP Paste'!$F9="","",IF('TMP Paste'!$M9="",$AL8,'TMP Paste'!$M9)) | AM9: =IF('TMP Paste'!$F9="","",IF('TMP Paste'!$N9="",$AM8,'TMP Paste'!$N9)) | AN9: =IF('TMP Paste'!$F9="","",IF('TMP Paste'!$O9="",$AN8,'TMP Paste'!$O9)) | AO9: =IF('TMP Paste'!$F9="","",IF('TMP Paste'!$P9="",$AO8,'TMP Paste'!$P9)) | AP9: =IF($AG9="","",LEN($R9)) | AQ9: =IF($AG9="","",TRIM(IF(COUNTIFS(Calc!$B$2:$B$1601,ROW()-1,Calc!$C$2:$C$1601,"<1")>0,"Ada PO tanpa Koli - cek TMP. ","")&IF(LEN($R9)>500,"R > 500 karakter.","")))
A10: =IF($AG10="","",INDEX('TMP Paste'!$B$2:$B$1601,$AG10)) | B10: =IF($AG10="","",Config!$B$14) | C10: =IF($AG10="","",Config!$B$15) | D10: =IF($AG10="","",INDEX('TMP Paste'!$B$2:$B$1601,$AG10)) | E10: =IF($AG10="","",Config!$B$27) | F10: =IF($AG10="","",Config!$B$9) | G10: =IF($AG10="","",Config!$B$10) | H10: =IF($AG10="","",Config!$B$11) | I10: =IF($AG10="","",Config!$B$16) | J10: =IF($AG10="","",INDEX('TMP Paste'!$A$2:$A$1601,$AG10)) | K10: =IF($AG10="","",INDEX('TMP Paste'!$L$2:$L$1601,$AG10)) | L10: =IF($AG10="","",INDEX('TMP Paste'!$I$2:$I$1601,$AG10)) | M10: =IF($AG10="","",Config!$B$16) | N10: =IF($AG10="","","") | O10: =IF($AG10="","",INDEX('TMP Paste'!$K$2:$K$1601,$AG10)) | P10: =IF($AG10="","","") | Q10: =IF($AG10="","",INDEX('TMP Paste'!$J$2:$J$1601,$AG10)) | R10: =IF($AG10="","",Config!$B$24) | S10: =IF($AG10="","",TEXT(Config!$B$4,"yyyy-mm-dd")) | T10: =IF($AG10="","",Config!$B$17) | U10: =IF($AG10="","",Config!$B$18) | V10: =IF($AG10="","",Config!$B$19) | W10: =IF($AG10="","",INDEX('TMP Paste'!$C$2:$C$1601,$AG10)) | X10: =IF($AG10="","",Config!$B$29) | Y10: =IF($AH10="","",INDEX(Calc!$I$2:$I$1601,$AH10)&" - "&INDEX(Calc!$D$2:$D$1601,$AH10)&" koli") | Z10: =IF($AG10="","",Config!$B$21) | AA10: =IF($AG10="","",Config!$B$22) | AB10: =IF($AH10="","",INDEX(Calc!$D$2:$D$1601,$AH10)) | AC10: =IF($AH10="","",INDEX(Calc!$G$2:$G$1601,$AH10)) | AD10: =IF($AG10="","",Config!$B$23) | AE10: =IF($AG10="","",Config!$B$28) | AG10: =IFERROR(MATCH(ROW()-1,Calc!$J$2:$J$1601,0),"") | AH10: =IFERROR(MATCH(ROW()-1,Calc!$K$2:$K$1601,0),"") | AI10: =IF($AG10="","",SUMIF($AG$2:$AG10,$AG10,$AH$2:$AH10)) | AJ10: =IF('TMP Paste'!$F10="","",IF('TMP Paste'!$B10="",$AJ9,'TMP Paste'!$B10)) | AK10: =IF('TMP Paste'!$F10="","",N('TMP Paste'!$G10)) | AL10: =IF('TMP Paste'!$F10="","",IF('TMP Paste'!$M10="",$AL9,'TMP Paste'!$M10)) | AM10: =IF('TMP Paste'!$F10="","",IF('TMP Paste'!$N10="",$AM9,'TMP Paste'!$N10)) | AN10: =IF('TMP Paste'!$F10="","",IF('TMP Paste'!$O10="",$AN9,'TMP Paste'!$O10)) | AO10: =IF('TMP Paste'!$F10="","",IF('TMP Paste'!$P10="",$AO9,'TMP Paste'!$P10)) | AP10: =IF($AG10="","",LEN($R10)) | AQ10: =IF($AG10="","",TRIM(IF(COUNTIFS(Calc!$B$2:$B$1601,ROW()-1,Calc!$C$2:$C$1601,"<1")>0,"Ada PO tanpa Koli - cek TMP. ","")&IF(LEN($R10)>500,"R > 500 karakter.","")))
A11: =IF($AG11="","",INDEX('TMP Paste'!$B$2:$B$1601,$AG11)) | B11: =IF($AG11="","",Config!$B$14) | C11: =IF($AG11="","",Config!$B$15) | D11: =IF($AG11="","",INDEX('TMP Paste'!$B$2:$B$1601,$AG11)) | E11: =IF($AG11="","",Config!$B$27) | F11: =IF($AG11="","",Config!$B$9) | G11: =IF($AG11="","",Config!$B$10) | H11: =IF($AG11="","",Config!$B$11) | I11: =IF($AG11="","",Config!$B$16) | J11: =IF($AG11="","",INDEX('TMP Paste'!$A$2:$A$1601,$AG11)) | K11: =IF($AG11="","",INDEX('TMP Paste'!$L$2:$L$1601,$AG11)) | L11: =IF($AG11="","",INDEX('TMP Paste'!$I$2:$I$1601,$AG11)) | M11: =IF($AG11="","",Config!$B$16) | N11: =IF($AG11="","","") | O11: =IF($AG11="","",INDEX('TMP Paste'!$K$2:$K$1601,$AG11)) | P11: =IF($AG11="","","") | Q11: =IF($AG11="","",INDEX('TMP Paste'!$J$2:$J$1601,$AG11)) | R11: =IF($AG11="","",Config!$B$24) | S11: =IF($AG11="","",TEXT(Config!$B$4,"yyyy-mm-dd")) | T11: =IF($AG11="","",Config!$B$17) | U11: =IF($AG11="","",Config!$B$18) | V11: =IF($AG11="","",Config!$B$19) | W11: =IF($AG11="","",INDEX('TMP Paste'!$C$2:$C$1601,$AG11)) | X11: =IF($AG11="","",Config!$B$29) | Y11: =IF($AH11="","",INDEX(Calc!$I$2:$I$1601,$AH11)&" - "&INDEX(Calc!$D$2:$D$1601,$AH11)&" koli") | Z11: =IF($AG11="","",Config!$B$21) | AA11: =IF($AG11="","",Config!$B$22) | AB11: =IF($AH11="","",INDEX(Calc!$D$2:$D$1601,$AH11)) | AC11: =IF($AH11="","",INDEX(Calc!$G$2:$G$1601,$AH11)) | AD11: =IF($AG11="","",Config!$B$23) | AE11: =IF($AG11="","",Config!$B$28) | AG11: =IFERROR(MATCH(ROW()-1,Calc!$J$2:$J$1601,0),"") | AH11: =IFERROR(MATCH(ROW()-1,Calc!$K$2:$K$1601,0),"") | AI11: =IF($AG11="","",SUMIF($AG$2:$AG11,$AG11,$AH$2:$AH11)) | AJ11: =IF('TMP Paste'!$F11="","",IF('TMP Paste'!$B11="",$AJ10,'TMP Paste'!$B11)) | AK11: =IF('TMP Paste'!$F11="","",N('TMP Paste'!$G11)) | AL11: =IF('TMP Paste'!$F11="","",IF('TMP Paste'!$M11="",$AL10,'TMP Paste'!$M11)) | AM11: =IF('TMP Paste'!$F11="","",IF('TMP Paste'!$N11="",$AM10,'TMP Paste'!$N11)) | AN11: =IF('TMP Paste'!$F11="","",IF('TMP Paste'!$O11="",$AN10,'TMP Paste'!$O11)) | AO11: =IF('TMP Paste'!$F11="","",IF('TMP Paste'!$P11="",$AO10,'TMP Paste'!$P11)) | AP11: =IF($AG11="","",LEN($R11)) | AQ11: =IF($AG11="","",TRIM(IF(COUNTIFS(Calc!$B$2:$B$1601,ROW()-1,Calc!$C$2:$C$1601,"<1")>0,"Ada PO tanpa Koli - cek TMP. ","")&IF(LEN($R11)>500,"R > 500 karakter.","")))
A12: =IF($AG12="","",INDEX('TMP Paste'!$B$2:$B$1601,$AG12)) | B12: =IF($AG12="","",Config!$B$14) | C12: =IF($AG12="","",Config!$B$15) | D12: =IF($AG12="","",INDEX('TMP Paste'!$B$2:$B$1601,$AG12)) | E12: =IF($AG12="","",Config!$B$27) | F12: =IF($AG12="","",Config!$B$9) | G12: =IF($AG12="","",Config!$B$10) | H12: =IF($AG12="","",Config!$B$11) | I12: =IF($AG12="","",Config!$B$16) | J12: =IF($AG12="","",INDEX('TMP Paste'!$A$2:$A$1601,$AG12)) | K12: =IF($AG12="","",INDEX('TMP Paste'!$L$2:$L$1601,$AG12)) | L12: =IF($AG12="","",INDEX('TMP Paste'!$I$2:$I$1601,$AG12)) | M12: =IF($AG12="","",Config!$B$16) | N12: =IF($AG12="","","") | O12: =IF($AG12="","",INDEX('TMP Paste'!$K$2:$K$1601,$AG12)) | P12: =IF($AG12="","","") | Q12: =IF($AG12="","",INDEX('TMP Paste'!$J$2:$J$1601,$AG12)) | R12: =IF($AG12="","",Config!$B$24) | S12: =IF($AG12="","",TEXT(Config!$B$4,"yyyy-mm-dd")) | T12: =IF($AG12="","",Config!$B$17) | U12: =IF($AG12="","",Config!$B$18) | V12: =IF($AG12="","",Config!$B$19) | W12: =IF($AG12="","",INDEX('TMP Paste'!$C$2:$C$1601,$AG12)) | X12: =IF($AG12="","",Config!$B$29) | Y12: =IF($AH12="","",INDEX(Calc!$I$2:$I$1601,$AH12)&" - "&INDEX(Calc!$D$2:$D$1601,$AH12)&" koli") | Z12: =IF($AG12="","",Config!$B$21) | AA12: =IF($AG12="","",Config!$B$22) | AB12: =IF($AH12="","",INDEX(Calc!$D$2:$D$1601,$AH12)) | AC12: =IF($AH12="","",INDEX(Calc!$G$2:$G$1601,$AH12)) | AD12: =IF($AG12="","",Config!$B$23) | AE12: =IF($AG12="","",Config!$B$28) | AG12: =IFERROR(MATCH(ROW()-1,Calc!$J$2:$J$1601,0),"") | AH12: =IFERROR(MATCH(ROW()-1,Calc!$K$2:$K$1601,0),"") | AI12: =IF($AG12="","",SUMIF($AG$2:$AG12,$AG12,$AH$2:$AH12)) | AJ12: =IF('TMP Paste'!$F12="","",IF('TMP Paste'!$B12="",$AJ11,'TMP Paste'!$B12)) | AK12: =IF('TMP Paste'!$F12="","",N('TMP Paste'!$G12)) | AL12: =IF('TMP Paste'!$F12="","",IF('TMP Paste'!$M12="",$AL11,'TMP Paste'!$M12)) | AM12: =IF('TMP Paste'!$F12="","",IF('TMP Paste'!$N12="",$AM11,'TMP Paste'!$N12)) | AN12: =IF('TMP Paste'!$F12="","",IF('TMP Paste'!$O12="",$AN11,'TMP Paste'!$O12)) | AO12: =IF('TMP Paste'!$F12="","",IF('TMP Paste'!$P12="",$AO11,'TMP Paste'!$P12)) | AP12: =IF($AG12="","",LEN($R12)) | AQ12: =IF($AG12="","",TRIM(IF(COUNTIFS(Calc!$B$2:$B$1601,ROW()-1,Calc!$C$2:$C$1601,"<1")>0,"Ada PO tanpa Koli - cek TMP. ","")&IF(LEN($R12)>500,"R > 500 karakter.","")))
A13: =IF($AG13="","",INDEX('TMP Paste'!$B$2:$B$1601,$AG13)) | B13: =IF($AG13="","",Config!$B$14) | C13: =IF($AG13="","",Config!$B$15) | D13: =IF($AG13="","",INDEX('TMP Paste'!$B$2:$B$1601,$AG13)) | E13: =IF($AG13="","",Config!$B$27) | F13: =IF($AG13="","",Config!$B$9) | G13: =IF($AG13="","",Config!$B$10) | H13: =IF($AG13="","",Config!$B$11) | I13: =IF($AG13="","",Config!$B$16) | J13: =IF($AG13="","",INDEX('TMP Paste'!$A$2:$A$1601,$AG13)) | K13: =IF($AG13="","",INDEX('TMP Paste'!$L$2:$L$1601,$AG13)) | L13: =IF($AG13="","",INDEX('TMP Paste'!$I$2:$I$1601,$AG13)) | M13: =IF($AG13="","",Config!$B$16) | N13: =IF($AG13="","","") | O13: =IF($AG13="","",INDEX('TMP Paste'!$K$2:$K$1601,$AG13)) | P13: =IF($AG13="","","") | Q13: =IF($AG13="","",INDEX('TMP Paste'!$J$2:$J$1601,$AG13)) | R13: =IF($AG13="","",Config!$B$24) | S13: =IF($AG13="","",TEXT(Config!$B$4,"yyyy-mm-dd")) | T13: =IF($AG13="","",Config!$B$17) | U13: =IF($AG13="","",Config!$B$18) | V13: =IF($AG13="","",Config!$B$19) | W13: =IF($AG13="","",INDEX('TMP Paste'!$C$2:$C$1601,$AG13)) | X13: =IF($AG13="","",Config!$B$29) | Y13: =IF($AH13="","",INDEX(Calc!$I$2:$I$1601,$AH13)&" - "&INDEX(Calc!$D$2:$D$1601,$AH13)&" koli") | Z13: =IF($AG13="","",Config!$B$21) | AA13: =IF($AG13="","",Config!$B$22) | AB13: =IF($AH13="","",INDEX(Calc!$D$2:$D$1601,$AH13)) | AC13: =IF($AH13="","",INDEX(Calc!$G$2:$G$1601,$AH13)) | AD13: =IF($AG13="","",Config!$B$23) | AE13: =IF($AG13="","",Config!$B$28) | AG13: =IFERROR(MATCH(ROW()-1,Calc!$J$2:$J$1601,0),"") | AH13: =IFERROR(MATCH(ROW()-1,Calc!$K$2:$K$1601,0),"") | AI13: =IF($AG13="","",SUMIF($AG$2:$AG13,$AG13,$AH$2:$AH13)) | AJ13: =IF('TMP Paste'!$F13="","",IF('TMP Paste'!$B13="",$AJ12,'TMP Paste'!$B13)) | AK13: =IF('TMP Paste'!$F13="","",N('TMP Paste'!$G13)) | AL13: =IF('TMP Paste'!$F13="","",IF('TMP Paste'!$M13="",$AL12,'TMP Paste'!$M13)) | AM13: =IF('TMP Paste'!$F13="","",IF('TMP Paste'!$N13="",$AM12,'TMP Paste'!$N13)) | AN13: =IF('TMP Paste'!$F13="","",IF('TMP Paste'!$O13="",$AN12,'TMP Paste'!$O13)) | AO13: =IF('TMP Paste'!$F13="","",IF('TMP Paste'!$P13="",$AO12,'TMP Paste'!$P13)) | AP13: =IF($AG13="","",LEN($R13)) | AQ13: =IF($AG13="","",TRIM(IF(COUNTIFS(Calc!$B$2:$B$1601,ROW()-1,Calc!$C$2:$C$1601,"<1")>0,"Ada PO tanpa Koli - cek TMP. ","")&IF(LEN($R13)>500,"R > 500 karakter.","")))
... A1501: =IF($AG1501="","",INDEX('TMP Paste'!$B$2:$B$1601,$AG1501)) | B1501: =IF($AG1501="","",Config!$B$14) | C1501: =IF($AG1501="","",Config!$B$15) | D1501: =IF($AG1501="","",INDEX('TMP Paste'!$B$2:$B$1601,$AG1501)) | E1501: =IF($AG1501="","",Config!$B$27) | F1501: =IF($AG1501="","",Config!$B$9) | G1501: =IF($AG1501="","",Config!$B$10) | H1501: =IF($AG1501="","",Config!$B$11) | I1501: =IF($AG1501="","",Config!$B$16) | J1501: =IF($AG1501="","",INDEX('TMP Paste'!$A$2:$A$1601,$AG1501)) | K1501: =IF($AG1501="","",INDEX('TMP Paste'!$L$2:$L$1601,$AG1501)) | L1501: =IF($AG1501="","",INDEX('TMP Paste'!$I$2:$I$1601,$AG1501)) | M1501: =IF($AG1501="","",Config!$B$16) | N1501: =IF($AG1501="","","") | O1501: =IF($AG1501="","",INDEX('TMP Paste'!$K$2:$K$1601,$AG1501)) | P1501: =IF($AG1501="","","") | Q1501: =IF($AG1501="","",INDEX('TMP Paste'!$J$2:$J$1601,$AG1501)) | R1501: =IF($AG1501="","",Config!$B$24) | S1501: =IF($AG1501="","",TEXT(Config!$B$4,"yyyy-mm-dd")) | T1501: =IF($AG1501="","",Config!$B$17) | U1501: =IF($AG1501="","",Config!$B$18) | V1501: =IF($AG1501="","",Config!$B$19) | W1501: =IF($AG1501="","",INDEX('TMP Paste'!$C$2:$C$1601,$AG1501)) | X1501: =IF($AG1501="","",Config!$B$29) | Y1501: =IF($AH1501="","",INDEX(Calc!$I$2:$I$1601,$AH1501)&" - "&INDEX(Calc!$D$2:$D$1601,$AH1501)&" koli") | Z1501: =IF($AG1501="","",Config!$B$21) | AA1501: =IF($AG1501="","",Config!$B$22) | AB1501: =IF($AH1501="","",INDEX(Calc!$D$2:$D$1601,$AH1501)) | AC1501: =IF($AH1501="","",INDEX(Calc!$G$2:$G$1601,$AH1501)) | AD1501: =IF($AG1501="","",Config!$B$23) | AE1501: =IF($AG1501="","",Config!$B$28) | AG1501: =IFERROR(MATCH(ROW()-1,Calc!$J$2:$J$1601,0),"") | AH1501: =IFERROR(MATCH(ROW()-1,Calc!$K$2:$K$1601,0),"") | AI1501: =IF($AG1501="","",SUMIF($AG$2:$AG1501,$AG1501,$AH$2:$AH1501)) | AJ1501: =IF('TMP Paste'!$F1501="","",IF('TMP Paste'!$B1501="",$AJ1500,'TMP Paste'!$B1501)) | AK1501: =IF('TMP Paste'!$F1501="","",N('TMP Paste'!$G1501)) | AL1501: =IF('TMP Paste'!$F1501="","",IF('TMP Paste'!$M1501="",$AL1500,'TMP Paste'!$M1501)) | AM1501: =IF('TMP Paste'!$F1501="","",IF('TMP Paste'!$N1501="",$AM1500,'TMP Paste'!$N1501)) | AN1501: =IF('TMP Paste'!$F1501="","",IF('TMP Paste'!$O1501="",$AN1500,'TMP Paste'!$O1501)) | AO1501: =IF('TMP Paste'!$F1501="","",IF('TMP Paste'!$P1501="",$AO1500,'TMP Paste'!$P1501)) | AP1501: =IF($AG1501="","",LEN($R1501)) | AQ1501: =IF($AG1501="","",TRIM(IF(COUNTIFS(Calc!$B$2:$B$1601,ROW()-1,Calc!$C$2:$C$1601,"<1")>0,"Ada PO tanpa Koli - cek TMP. ","")&IF(LEN($R1501)>500,"R > 500 karakter.","")))
A1502: =IF($AG1502="","",INDEX('TMP Paste'!$B$2:$B$1601,$AG1502)) | B1502: =IF($AG1502="","",Config!$B$14) | C1502: =IF($AG1502="","",Config!$B$15) | D1502: =IF($AG1502="","",INDEX('TMP Paste'!$B$2:$B$1601,$AG1502)) | E1502: =IF($AG1502="","",Config!$B$27) | F1502: =IF($AG1502="","",Config!$B$9) | G1502: =IF($AG1502="","",Config!$B$10) | H1502: =IF($AG1502="","",Config!$B$11) | I1502: =IF($AG1502="","",Config!$B$16) | J1502: =IF($AG1502="","",INDEX('TMP Paste'!$A$2:$A$1601,$AG1502)) | K1502: =IF($AG1502="","",INDEX('TMP Paste'!$L$2:$L$1601,$AG1502)) | L1502: =IF($AG1502="","",INDEX('TMP Paste'!$I$2:$I$1601,$AG1502)) | M1502: =IF($AG1502="","",Config!$B$16) | N1502: =IF($AG1502="","","") | O1502: =IF($AG1502="","",INDEX('TMP Paste'!$K$2:$K$1601,$AG1502)) | P1502: =IF($AG1502="","","") | Q1502: =IF($AG1502="","",INDEX('TMP Paste'!$J$2:$J$1601,$AG1502)) | R1502: =IF($AG1502="","",Config!$B$24) | S1502: =IF($AG1502="","",TEXT(Config!$B$4,"yyyy-mm-dd")) | T1502: =IF($AG1502="","",Config!$B$17) | U1502: =IF($AG1502="","",Config!$B$18) | V1502: =IF($AG1502="","",Config!$B$19) | W1502: =IF($AG1502="","",INDEX('TMP Paste'!$C$2:$C$1601,$AG1502)) | X1502: =IF($AG1502="","",Config!$B$29) | Y1502: =IF($AH1502="","",INDEX(Calc!$I$2:$I$1601,$AH1502)&" - "&INDEX(Calc!$D$2:$D$1601,$AH1502)&" koli") | Z1502: =IF($AG1502="","",Config!$B$21) | AA1502: =IF($AG1502="","",Config!$B$22) | AB1502: =IF($AH1502="","",INDEX(Calc!$D$2:$D$1601,$AH1502)) | AC1502: =IF($AH1502="","",INDEX(Calc!$G$2:$G$1601,$AH1502)) | AD1502: =IF($AG1502="","",Config!$B$23) | AE1502: =IF($AG1502="","",Config!$B$28) | AG1502: =IFERROR(MATCH(ROW()-1,Calc!$J$2:$J$1601,0),"") | AH1502: =IFERROR(MATCH(ROW()-1,Calc!$K$2:$K$1601,0),"") | AQ1502: =IF($AG1502="","",TRIM(IF(COUNTIFS(Calc!$B$2:$B$1601,ROW()-1,Calc!$C$2:$C$1601,"<1")>0,"Ada PO tanpa Koli - cek TMP. ","")&IF(LEN($R1502)>500,"R > 500 karakter.","")))
A1503: =IF($AG1503="","",INDEX('TMP Paste'!$B$2:$B$1601,$AG1503)) | B1503: =IF($AG1503="","",Config!$B$14) | C1503: =IF($AG1503="","",Config!$B$15) | D1503: =IF($AG1503="","",INDEX('TMP Paste'!$B$2:$B$1601,$AG1503)) | E1503: =IF($AG1503="","",Config!$B$27) | F1503: =IF($AG1503="","",Config!$B$9) | G1503: =IF($AG1503="","",Config!$B$10) | H1503: =IF($AG1503="","",Config!$B$11) | I1503: =IF($AG1503="","",Config!$B$16) | J1503: =IF($AG1503="","",INDEX('TMP Paste'!$A$2:$A$1601,$AG1503)) | K1503: =IF($AG1503="","",INDEX('TMP Paste'!$L$2:$L$1601,$AG1503)) | L1503: =IF($AG1503="","",INDEX('TMP Paste'!$I$2:$I$1601,$AG1503)) | M1503: =IF($AG1503="","",Config!$B$16) | N1503: =IF($AG1503="","","") | O1503: =IF($AG1503="","",INDEX('TMP Paste'!$K$2:$K$1601,$AG1503)) | P1503: =IF($AG1503="","","") | Q1503: =IF($AG1503="","",INDEX('TMP Paste'!$J$2:$J$1601,$AG1503)) | R1503: =IF($AG1503="","",Config!$B$24) | S1503: =IF($AG1503="","",TEXT(Config!$B$4,"yyyy-mm-dd")) | T1503: =IF($AG1503="","",Config!$B$17) | U1503: =IF($AG1503="","",Config!$B$18) | V1503: =IF($AG1503="","",Config!$B$19) | W1503: =IF($AG1503="","",INDEX('TMP Paste'!$C$2:$C$1601,$AG1503)) | X1503: =IF($AG1503="","",Config!$B$29) | Y1503: =IF($AH1503="","",INDEX(Calc!$I$2:$I$1601,$AH1503)&" - "&INDEX(Calc!$D$2:$D$1601,$AH1503)&" koli") | Z1503: =IF($AG1503="","",Config!$B$21) | AA1503: =IF($AG1503="","",Config!$B$22) | AB1503: =IF($AH1503="","",INDEX(Calc!$D$2:$D$1601,$AH1503)) | AC1503: =IF($AH1503="","",INDEX(Calc!$G$2:$G$1601,$AH1503)) | AD1503: =IF($AG1503="","",Config!$B$23) | AE1503: =IF($AG1503="","",Config!$B$28) | AG1503: =IFERROR(MATCH(ROW()-1,Calc!$J$2:$J$1601,0),"") | AH1503: =IFERROR(MATCH(ROW()-1,Calc!$K$2:$K$1601,0),"") | AQ1503: =IF($AG1503="","",TRIM(IF(COUNTIFS(Calc!$B$2:$B$1601,ROW()-1,Calc!$C$2:$C$1601,"<1")>0,"Ada PO tanpa Koli - cek TMP. ","")&IF(LEN($R1503)>500,"R > 500 karakter.","")))
A1504: =IF($AG1504="","",INDEX('TMP Paste'!$B$2:$B$1601,$AG1504)) | B1504: =IF($AG1504="","",Config!$B$14) | C1504: =IF($AG1504="","",Config!$B$15) | D1504: =IF($AG1504="","",INDEX('TMP Paste'!$B$2:$B$1601,$AG1504)) | E1504: =IF($AG1504="","",Config!$B$27) | F1504: =IF($AG1504="","",Config!$B$9) | G1504: =IF($AG1504="","",Config!$B$10) | H1504: =IF($AG1504="","",Config!$B$11) | I1504: =IF($AG1504="","",Config!$B$16) | J1504: =IF($AG1504="","",INDEX('TMP Paste'!$A$2:$A$1601,$AG1504)) | K1504: =IF($AG1504="","",INDEX('TMP Paste'!$L$2:$L$1601,$AG1504)) | L1504: =IF($AG1504="","",INDEX('TMP Paste'!$I$2:$I$1601,$AG1504)) | M1504: =IF($AG1504="","",Config!$B$16) | N1504: =IF($AG1504="","","") | O1504: =IF($AG1504="","",INDEX('TMP Paste'!$K$2:$K$1601,$AG1504)) | P1504: =IF($AG1504="","","") | Q1504: =IF($AG1504="","",INDEX('TMP Paste'!$J$2:$J$1601,$AG1504)) | R1504: =IF($AG1504="","",Config!$B$24) | S1504: =IF($AG1504="","",TEXT(Config!$B$4,"yyyy-mm-dd")) | T1504: =IF($AG1504="","",Config!$B$17) | U1504: =IF($AG1504="","",Config!$B$18) | V1504: =IF($AG1504="","",Config!$B$19) | W1504: =IF($AG1504="","",INDEX('TMP Paste'!$C$2:$C$1601,$AG1504)) | X1504: =IF($AG1504="","",Config!$B$29) | Y1504: =IF($AH1504="","",INDEX(Calc!$I$2:$I$1601,$AH1504)&" - "&INDEX(Calc!$D$2:$D$1601,$AH1504)&" koli") | Z1504: =IF($AG1504="","",Config!$B$21) | AA1504: =IF($AG1504="","",Config!$B$22) | AB1504: =IF($AH1504="","",INDEX(Calc!$D$2:$D$1601,$AH1504)) | AC1504: =IF($AH1504="","",INDEX(Calc!$G$2:$G$1601,$AH1504)) | AD1504: =IF($AG1504="","",Config!$B$23) | AE1504: =IF($AG1504="","",Config!$B$28) | AG1504: =IFERROR(MATCH(ROW()-1,Calc!$J$2:$J$1601,0),"") | AH1504: =IFERROR(MATCH(ROW()-1,Calc!$K$2:$K$1601,0),"") | AQ1504: =IF($AG1504="","",TRIM(IF(COUNTIFS(Calc!$B$2:$B$1601,ROW()-1,Calc!$C$2:$C$1601,"<1")>0,"Ada PO tanpa Koli - cek TMP. ","")&IF(LEN($R1504)>500,"R > 500 karakter.","")))
A1505: =IF($AG1505="","",INDEX('TMP Paste'!$B$2:$B$1601,$AG1505)) | B1505: =IF($AG1505="","",Config!$B$14) | C1505: =IF($AG1505="","",Config!$B$15) | D1505: =IF($AG1505="","",INDEX('TMP Paste'!$B$2:$B$1601,$AG1505)) | E1505: =IF($AG1505="","",Config!$B$27) | F1505: =IF($AG1505="","",Config!$B$9) | G1505: =IF($AG1505="","",Config!$B$10) | H1505: =IF($AG1505="","",Config!$B$11) | I1505: =IF($AG1505="","",Config!$B$16) | J1505: =IF($AG1505="","",INDEX('TMP Paste'!$A$2:$A$1601,$AG1505)) | K1505: =IF($AG1505="","",INDEX('TMP Paste'!$L$2:$L$1601,$AG1505)) | L1505: =IF($AG1505="","",INDEX('TMP Paste'!$I$2:$I$1601,$AG1505)) | M1505: =IF($AG1505="","",Config!$B$16) | N1505: =IF($AG1505="","","") | O1505: =IF($AG1505="","",INDEX('TMP Paste'!$K$2:$K$1601,$AG1505)) | P1505: =IF($AG1505="","","") | Q1505: =IF($AG1505="","",INDEX('TMP Paste'!$J$2:$J$1601,$AG1505)) | R1505: =IF($AG1505="","",Config!$B$24) | S1505: =IF($AG1505="","",TEXT(Config!$B$4,"yyyy-mm-dd")) | T1505: =IF($AG1505="","",Config!$B$17) | U1505: =IF($AG1505="","",Config!$B$18) | V1505: =IF($AG1505="","",Config!$B$19) | W1505: =IF($AG1505="","",INDEX('TMP Paste'!$C$2:$C$1601,$AG1505)) | X1505: =IF($AG1505="","",Config!$B$29) | Y1505: =IF($AH1505="","",INDEX(Calc!$I$2:$I$1601,$AH1505)&" - "&INDEX(Calc!$D$2:$D$1601,$AH1505)&" koli") | Z1505: =IF($AG1505="","",Config!$B$21) | AA1505: =IF($AG1505="","",Config!$B$22) | AB1505: =IF($AH1505="","",INDEX(Calc!$D$2:$D$1601,$AH1505)) | AC1505: =IF($AH1505="","",INDEX(Calc!$G$2:$G$1601,$AH1505)) | AD1505: =IF($AG1505="","",Config!$B$23) | AE1505: =IF($AG1505="","",Config!$B$28) | AG1505: =IFERROR(MATCH(ROW()-1,Calc!$J$2:$J$1601,0),"") | AH1505: =IFERROR(MATCH(ROW()-1,Calc!$K$2:$K$1601,0),"") | AQ1505: =IF($AG1505="","",TRIM(IF(COUNTIFS(Calc!$B$2:$B$1601,ROW()-1,Calc!$C$2:$C$1601,"<1")>0,"Ada PO tanpa Koli - cek TMP. ","")&IF(LEN($R1505)>500,"R > 500 karakter.","")))
A1506: =IF($AG1506="","",INDEX('TMP Paste'!$B$2:$B$1601,$AG1506)) | B1506: =IF($AG1506="","",Config!$B$14) | C1506: =IF($AG1506="","",Config!$B$15) | D1506: =IF($AG1506="","",INDEX('TMP Paste'!$B$2:$B$1601,$AG1506)) | E1506: =IF($AG1506="","",Config!$B$27) | F1506: =IF($AG1506="","",Config!$B$9) | G1506: =IF($AG1506="","",Config!$B$10) | H1506: =IF($AG1506="","",Config!$B$11) | I1506: =IF($AG1506="","",Config!$B$16) | J1506: =IF($AG1506="","",INDEX('TMP Paste'!$A$2:$A$1601,$AG1506)) | K1506: =IF($AG1506="","",INDEX('TMP Paste'!$L$2:$L$1601,$AG1506)) | L1506: =IF($AG1506="","",INDEX('TMP Paste'!$I$2:$I$1601,$AG1506)) | M1506: =IF($AG1506="","",Config!$B$16) | N1506: =IF($AG1506="","","") | O1506: =IF($AG1506="","",INDEX('TMP Paste'!$K$2:$K$1601,$AG1506)) | P1506: =IF($AG1506="","","") | Q1506: =IF($AG1506="","",INDEX('TMP Paste'!$J$2:$J$1601,$AG1506)) | R1506: =IF($AG1506="","",Config!$B$24) | S1506: =IF($AG1506="","",TEXT(Config!$B$4,"yyyy-mm-dd")) | T1506: =IF($AG1506="","",Config!$B$17) | U1506: =IF($AG1506="","",Config!$B$18) | V1506: =IF($AG1506="","",Config!$B$19) | W1506: =IF($AG1506="","",INDEX('TMP Paste'!$C$2:$C$1601,$AG1506)) | X1506: =IF($AG1506="","",Config!$B$29) | Y1506: =IF($AH1506="","",INDEX(Calc!$I$2:$I$1601,$AH1506)&" - "&INDEX(Calc!$D$2:$D$1601,$AH1506)&" koli") | Z1506: =IF($AG1506="","",Config!$B$21) | AA1506: =IF($AG1506="","",Config!$B$22) | AB1506: =IF($AH1506="","",INDEX(Calc!$D$2:$D$1601,$AH1506)) | AC1506: =IF($AH1506="","",INDEX(Calc!$G$2:$G$1601,$AH1506)) | AD1506: =IF($AG1506="","",Config!$B$23) | AE1506: =IF($AG1506="","",Config!$B$28) | AG1506: =IFERROR(MATCH(ROW()-1,Calc!$J$2:$J$1601,0),"") | AH1506: =IFERROR(MATCH(ROW()-1,Calc!$K$2:$K$1601,0),"") | AQ1506: =IF($AG1506="","",TRIM(IF(COUNTIFS(Calc!$B$2:$B$1601,ROW()-1,Calc!$C$2:$C$1601,"<1")>0,"Ada PO tanpa Koli - cek TMP. ","")&IF(LEN($R1506)>500,"R > 500 karakter.","")))
A1507: =IF($AG1507="","",INDEX('TMP Paste'!$B$2:$B$1601,$AG1507)) | B1507: =IF($AG1507="","",Config!$B$14) | C1507: =IF($AG1507="","",Config!$B$15) | D1507: =IF($AG1507="","",INDEX('TMP Paste'!$B$2:$B$1601,$AG1507)) | E1507: =IF($AG1507="","",Config!$B$27) | F1507: =IF($AG1507="","",Config!$B$9) | G1507: =IF($AG1507="","",Config!$B$10) | H1507: =IF($AG1507="","",Config!$B$11) | I1507: =IF($AG1507="","",Config!$B$16) | J1507: =IF($AG1507="","",INDEX('TMP Paste'!$A$2:$A$1601,$AG1507)) | K1507: =IF($AG1507="","",INDEX('TMP Paste'!$L$2:$L$1601,$AG1507)) | L1507: =IF($AG1507="","",INDEX('TMP Paste'!$I$2:$I$1601,$AG1507)) | M1507: =IF($AG1507="","",Config!$B$16) | N1507: =IF($AG1507="","","") | O1507: =IF($AG1507="","",INDEX('TMP Paste'!$K$2:$K$1601,$AG1507)) | P1507: =IF($AG1507="","","") | Q1507: =IF($AG1507="","",INDEX('TMP Paste'!$J$2:$J$1601,$AG1507)) | R1507: =IF($AG1507="","",Config!$B$24) | S1507: =IF($AG1507="","",TEXT(Config!$B$4,"yyyy-mm-dd")) | T1507: =IF($AG1507="","",Config!$B$17) | U1507: =IF($AG1507="","",Config!$B$18) | V1507: =IF($AG1507="","",Config!$B$19) | W1507: =IF($AG1507="","",INDEX('TMP Paste'!$C$2:$C$1601,$AG1507)) | X1507: =IF($AG1507="","",Config!$B$29) | Y1507: =IF($AH1507="","",INDEX(Calc!$I$2:$I$1601,$AH1507)&" - "&INDEX(Calc!$D$2:$D$1601,$AH1507)&" koli") | Z1507: =IF($AG1507="","",Config!$B$21) | AA1507: =IF($AG1507="","",Config!$B$22) | AB1507: =IF($AH1507="","",INDEX(Calc!$D$2:$D$1601,$AH1507)) | AC1507: =IF($AH1507="","",INDEX(Calc!$G$2:$G$1601,$AH1507)) | AD1507: =IF($AG1507="","",Config!$B$23) | AE1507: =IF($AG1507="","",Config!$B$28) | AG1507: =IFERROR(MATCH(ROW()-1,Calc!$J$2:$J$1601,0),"") | AH1507: =IFERROR(MATCH(ROW()-1,Calc!$K$2:$K$1601,0),"") | AQ1507: =IF($AG1507="","",TRIM(IF(COUNTIFS(Calc!$B$2:$B$1601,ROW()-1,Calc!$C$2:$C$1601,"<1")>0,"Ada PO tanpa Koli - cek TMP. ","")&IF(LEN($R1507)>500,"R > 500 karakter.","")))
A1508: =IF($AG1508="","",INDEX('TMP Paste'!$B$2:$B$1601,$AG1508)) | B1508: =IF($AG1508="","",Config!$B$14) | C1508: =IF($AG1508="","",Config!$B$15) | D1508: =IF($AG1508="","",INDEX('TMP Paste'!$B$2:$B$1601,$AG1508)) | E1508: =IF($AG1508="","",Config!$B$27) | F1508: =IF($AG1508="","",Config!$B$9) | G1508: =IF($AG1508="","",Config!$B$10) | H1508: =IF($AG1508="","",Config!$B$11) | I1508: =IF($AG1508="","",Config!$B$16) | J1508: =IF($AG1508="","",INDEX('TMP Paste'!$A$2:$A$1601,$AG1508)) | K1508: =IF($AG1508="","",INDEX('TMP Paste'!$L$2:$L$1601,$AG1508)) | L1508: =IF($AG1508="","",INDEX('TMP Paste'!$I$2:$I$1601,$AG1508)) | M1508: =IF($AG1508="","",Config!$B$16) | N1508: =IF($AG1508="","","") | O1508: =IF($AG1508="","",INDEX('TMP Paste'!$K$2:$K$1601,$AG1508)) | P1508: =IF($AG1508="","","") | Q1508: =IF($AG1508="","",INDEX('TMP Paste'!$J$2:$J$1601,$AG1508)) | R1508: =IF($AG1508="","",Config!$B$24) | S1508: =IF($AG1508="","",TEXT(Config!$B$4,"yyyy-mm-dd")) | T1508: =IF($AG1508="","",Config!$B$17) | U1508: =IF($AG1508="","",Config!$B$18) | V1508: =IF($AG1508="","",Config!$B$19) | W1508: =IF($AG1508="","",INDEX('TMP Paste'!$C$2:$C$1601,$AG1508)) | X1508: =IF($AG1508="","",Config!$B$29) | Y1508: =IF($AH1508="","",INDEX(Calc!$I$2:$I$1601,$AH1508)&" - "&INDEX(Calc!$D$2:$D$1601,$AH1508)&" koli") | Z1508: =IF($AG1508="","",Config!$B$21) | AA1508: =IF($AG1508="","",Config!$B$22) | AB1508: =IF($AH1508="","",INDEX(Calc!$D$2:$D$1601,$AH1508)) | AC1508: =IF($AH1508="","",INDEX(Calc!$G$2:$G$1601,$AH1508)) | AD1508: =IF($AG1508="","",Config!$B$23) | AE1508: =IF($AG1508="","",Config!$B$28) | AG1508: =IFERROR(MATCH(ROW()-1,Calc!$J$2:$J$1601,0),"") | AH1508: =IFERROR(MATCH(ROW()-1,Calc!$K$2:$K$1601,0),"") | AQ1508: =IF($AG1508="","",TRIM(IF(COUNTIFS(Calc!$B$2:$B$1601,ROW()-1,Calc!$C$2:$C$1601,"<1")>0,"Ada PO tanpa Koli - cek TMP. ","")&IF(LEN($R1508)>500,"R > 500 karakter.","")))
A1509: =IF($AG1509="","",INDEX('TMP Paste'!$B$2:$B$1601,$AG1509)) | B1509: =IF($AG1509="","",Config!$B$14) | C1509: =IF($AG1509="","",Config!$B$15) | D1509: =IF($AG1509="","",INDEX('TMP Paste'!$B$2:$B$1601,$AG1509)) | E1509: =IF($AG1509="","",Config!$B$27) | F1509: =IF($AG1509="","",Config!$B$9) | G1509: =IF($AG1509="","",Config!$B$10) | H1509: =IF($AG1509="","",Config!$B$11) | I1509: =IF($AG1509="","",Config!$B$16) | J1509: =IF($AG1509="","",INDEX('TMP Paste'!$A$2:$A$1601,$AG1509)) | K1509: =IF($AG1509="","",INDEX('TMP Paste'!$L$2:$L$1601,$AG1509)) | L1509: =IF($AG1509="","",INDEX('TMP Paste'!$I$2:$I$1601,$AG1509)) | M1509: =IF($AG1509="","",Config!$B$16) | N1509: =IF($AG1509="","","") | O1509: =IF($AG1509="","",INDEX('TMP Paste'!$K$2:$K$1601,$AG1509)) | P1509: =IF($AG1509="","","") | Q1509: =IF($AG1509="","",INDEX('TMP Paste'!$J$2:$J$1601,$AG1509)) | R1509: =IF($AG1509="","",Config!$B$24) | S1509: =IF($AG1509="","",TEXT(Config!$B$4,"yyyy-mm-dd")) | T1509: =IF($AG1509="","",Config!$B$17) | U1509: =IF($AG1509="","",Config!$B$18) | V1509: =IF($AG1509="","",Config!$B$19) | W1509: =IF($AG1509="","",INDEX('TMP Paste'!$C$2:$C$1601,$AG1509)) | X1509: =IF($AG1509="","",Config!$B$29) | Y1509: =IF($AH1509="","",INDEX(Calc!$I$2:$I$1601,$AH1509)&" - "&INDEX(Calc!$D$2:$D$1601,$AH1509)&" koli") | Z1509: =IF($AG1509="","",Config!$B$21) | AA1509: =IF($AG1509="","",Config!$B$22) | AB1509: =IF($AH1509="","",INDEX(Calc!$D$2:$D$1601,$AH1509)) | AC1509: =IF($AH1509="","",INDEX(Calc!$G$2:$G$1601,$AH1509)) | AD1509: =IF($AG1509="","",Config!$B$23) | AE1509: =IF($AG1509="","",Config!$B$28) | AG1509: =IFERROR(MATCH(ROW()-1,Calc!$J$2:$J$1601,0),"") | AH1509: =IFERROR(MATCH(ROW()-1,Calc!$K$2:$K$1601,0),"") | AQ1509: =IF($AG1509="","",TRIM(IF(COUNTIFS(Calc!$B$2:$B$1601,ROW()-1,Calc!$C$2:$C$1601,"<1")>0,"Ada PO tanpa Koli - cek TMP. ","")&IF(LEN($R1509)>500,"R > 500 karakter.","")))
A1510: =IF($AG1510="","",INDEX('TMP Paste'!$B$2:$B$1601,$AG1510)) | B1510: =IF($AG1510="","",Config!$B$14) | C1510: =IF($AG1510="","",Config!$B$15) | D1510: =IF($AG1510="","",INDEX('TMP Paste'!$B$2:$B$1601,$AG1510)) | E1510: =IF($AG1510="","",Config!$B$27) | F1510: =IF($AG1510="","",Config!$B$9) | G1510: =IF($AG1510="","",Config!$B$10) | H1510: =IF($AG1510="","",Config!$B$11) | I1510: =IF($AG1510="","",Config!$B$16) | J1510: =IF($AG1510="","",INDEX('TMP Paste'!$A$2:$A$1601,$AG1510)) | K1510: =IF($AG1510="","",INDEX('TMP Paste'!$L$2:$L$1601,$AG1510)) | L1510: =IF($AG1510="","",INDEX('TMP Paste'!$I$2:$I$1601,$AG1510)) | M1510: =IF($AG1510="","",Config!$B$16) | N1510: =IF($AG1510="","","") | O1510: =IF($AG1510="","",INDEX('TMP Paste'!$K$2:$K$1601,$AG1510)) | P1510: =IF($AG1510="","","") | Q1510: =IF($AG1510="","",INDEX('TMP Paste'!$J$2:$J$1601,$AG1510)) | R1510: =IF($AG1510="","",Config!$B$24) | S1510: =IF($AG1510="","",TEXT(Config!$B$4,"yyyy-mm-dd")) | T1510: =IF($AG1510="","",Config!$B$17) | U1510: =IF($AG1510="","",Config!$B$18) | V1510: =IF($AG1510="","",Config!$B$19) | W1510: =IF($AG1510="","",INDEX('TMP Paste'!$C$2:$C$1601,$AG1510)) | X1510: =IF($AG1510="","",Config!$B$29) | Y1510: =IF($AH1510="","",INDEX(Calc!$I$2:$I$1601,$AH1510)&" - "&INDEX(Calc!$D$2:$D$1601,$AH1510)&" koli") | Z1510: =IF($AG1510="","",Config!$B$21) | AA1510: =IF($AG1510="","",Config!$B$22) | AB1510: =IF($AH1510="","",INDEX(Calc!$D$2:$D$1601,$AH1510)) | AC1510: =IF($AH1510="","",INDEX(Calc!$G$2:$G$1601,$AH1510)) | AD1510: =IF($AG1510="","",Config!$B$23) | AE1510: =IF($AG1510="","",Config!$B$28) | AG1510: =IFERROR(MATCH(ROW()-1,Calc!$J$2:$J$1601,0),"") | AH1510: =IFERROR(MATCH(ROW()-1,Calc!$K$2:$K$1601,0),"") | AQ1510: =IF($AG1510="","",TRIM(IF(COUNTIFS(Calc!$B$2:$B$1601,ROW()-1,Calc!$C$2:$C$1601,"<1")>0,"Ada PO tanpa Koli - cek TMP. ","")&IF(LEN($R1510)>500,"R > 500 karakter.","")))
