Workbook

Sheet Petunjuk
B1: Konverter TMP SwipeRx -> Upload OC Ninja Van (v5, 10 Agu 2026)
B2: Tanpa makro. Cukup tempel data TMP dan pilih layanan â€” kolom otomatis terisi rumus.
B4: CARA PAKAI
B5: 1. Buka file TMP dari SwipeRx (file '[Template Swipe ...] TMP Batch'). Pilih SELURUH Sheet1 (Ctrl+A), Copy.
B6: 2. Ke sheet 'TMP Paste', tempel di sel A1 (Paste Values boleh). Data mulai baris 2 (1 baris judul).
B7: 3. Ke sheet 'Config' (sel kuning): pilih Layanan (S1/S2/S3), atur tanggal kirim dan gudang asal.
B8: 4. Buka sheet 'OC Upload'. Baris terisi otomatis. Salin kolom A sampai AE + semua baris terisi, tempel ke sistem Ninja Van.
B9: (Kolom setelah AE hanya bantuan/CEK â€” JANGAN ikut di-upload.)
B11: STRUKTUR OUTPUT (acuan: template tech team 'Bulk_Upload_MPS_RDO')
B12: • SATU BARIS = SATU SwipeAWB (satu MPS order). Bukan satu baris per PO.
B13: • A requested_tracking_number = SwipeAWB (MPS Tracking ID) = D merchant_order_number. 1 WP = 1 MPS TRID = 1 SwipeAWB.
B14: • AC = seluruh TRID anak milik MPS tsb. PREFIX WAJIB SAMA PERSIS dengan kolom A (SwipeAWB), 2 digit, mulai dari -01 di tiap AWB, dipisah ", ". Contoh AWB dgn 3 PO (PO1 = 2 koli):
... B23: Baris PO lanjutan hanya berisi E..M (A/B/C kosong). Jika SwipeRx mengubah urutan kolom lagi, rumus harus disesuaikan.

Sheet Config
A1: CONFIG â€” atur sebelum baca OC Upload
A3: Layanan (pilih) | B3: S1 - Regular (STANDARD) | D3: Layanan | E3: service_level | F3: branch | G3: pickup
A4: Tanggal kirim | B4: =TODAY() -> 46252 | D4: S1 - Regular (STANDARD) | E4: STANDARD | F4: 1 | G4: FALSE
D5: S2 - Sameday (SAMEDAY) | E5: SAMEDAY | F5: 3 | G5: FALSE
D6: S3 - POD Return | E6: STANDARD | F6: 2 | G6: TRUE
A8: GUDANG ASAL (from.*) | D8: REFERENSI SHIPPER ID (info — B selalu master 11398423)
A9: from.name (F) | B9: PT Teknologi Medika Pratama (SwipeRx) (B2BR) | D9: Shipper ID | E9: Shipper Name | F9: Layanan / Branch
A10: from.phone_number (G) | B10: 087733785699 | D10: 11398423 | E10: PT Teknologi Medika Pratama (B2BR) | F10: MASTER — selalu di kolom B
A11: from.address.address1 (H) | B11: Jl. Tugu Raya, Tugu, Kec. Cimanggis, Kota Depok, Jawa Barat 16451,KUBIK LOGISTICS - Kompleks Pergudangan,Gudang E1 | D11: 11398224 | E11: PT Teknologi Medika Pratama HW (B2BR) | F11: S1 Regular — branch 1
D12: 11549046 | E12: PT Teknologi Medika Pratama Sameday CTM (B2BR) | F12: S2 Sameday — branch 3
A13: KONSTANTA TERKUNCI (jangan diubah) | D13: 11398434 | E13: PT Teknologi Medika Pratama HW - RTS Account (B2BR) | F13: S3 Return/POD — branch 2
A14: global_shipper_id (B) master | B14: 11398423
A15: service_type (C) | B15: Corporate B2B Bundle
A16: country (I / M) | B16: ID
A17: timeslot mulai (T) | B17: 09:00
A18: timeslot selesai (U) | B18: 22:00
A19: timezone (V) | B19: Asia/Jakarta
A20: (cadangan)
A21: is_dangerous_good (Z) | B21: FALSE
A22: documents_required (AA) | B22: RDO
A23: insured_value (AD) | B23: 0
A24: Teks instruksi RDO (R) | B24: Delivery Note wajib ada nama penerima, ditandatangani dan distempel penerima. Jika di label tertera "SP Manual", maka dokumen SP Manual harus diminta ke penerima sesuai dengan jumlah PO yang butuh SP Manual. Apabila ada retur, catat di Delivery Note dan update ke IC
A27: service_level (E) | B27: =VLOOKUP($B$3,$D$4:$G$6,2,FALSE) -> STANDARD
A28: branch_id (AE) | B28: =VLOOKUP($B$3,$D$4:$G$6,3,FALSE) -> 1
A29: is_pickup_required (X) | B29: =VLOOKUP($B$3,$D$4:$G$6,4,FALSE) -> FALSE

Sheet TMP Paste
A1: Pharmacy Name | B1: SwipeAWB | C1: Total Weight per AWB (kg) | D1: Total Volume per AWB (m3) | E1: PO Number | F1: Pharmacy's Id | G1: Note's | H1: Picking Priority | I1: Pharmacy's Id - Address | J1: Zip Code | K1: City | L1: Phone | M1: Koli
A2: Apotek Afia | B2: AWB02WJVH | C2: 0.3 | D2: 0.001423 | E2: 26072713473538DTjozNXFa | F2: 3062 | G2: 26072713473538DTjozNXFa | H2: P4N | I2: 3062-Jalan MI Ridwan Rais No.3 RT 002 RW 006 Kelurahan Beji Timur Kecamatan Beji Kota Depok 16422 | J2: 16422 | K2: Kota Depok | L2: 895808010200 | M2: 1
A3: Apotek Alam Sehat Farma | B3: AWB02WJ90 | C3: 1.2 | D3: 0.002902 | E3: 26072707484936JExQscwbq | F3: 836 | G3: 26072707484936JExQscwbq | H3: P4N | I3: 836-Jalan Anggrek Raya No. 27-28 RT 002/004 Kelurahan Depok Jaya Kecamatan Pancoran Mas 16432 | J3: 16432 | K3: Kota Depok | L3: 81382701345 | M3: 1
A4: Apotek Ben Waras 19 | B4: AWB02WL4S | C4: 0.46 | D4: 0.001794 | E4: 26072802143715UaH54d1OD | F4: 903 | G4: 26072802143715UaH54d1OD | H4: P4N | I4: 903-Jalan Karya Ruko Tugu Bedahan No. 10 RT.001 RW.16 Kelurahan Bedahan, Kecamatan Sawangan, Kota Depok, Jawa Barat 16519 | J4: 16519 | K4: Kota Depok | L4: 6289510341165 | M4: 1
A5: Apotek Berkah 9 | B5: AWB02WKTT | C5: 3.04 | D5: 0.009864 | E5: 26072801412330Cygue4Ku6 | F5: 3479 | G5: 26072801412330Cygue4Ku6-26072802554064GKk0wdiYh-26072802554064ljldqS88pC | H5: P4N | I5: 3479-Jalan Raya Pasir Putih Ruko Cahaya Garuda No. 6 RT 005 RW 009 Sawangan Permai Kelurahan Pasir Putih Kecamatan Sawangan Kota Depok 16519 | J5: 16519 | K5: Kota Depok | L5: 8979743443 | M5: 1
E6: 26072802554064GKk0wdiYh | M6: 1
E7: 26072802554064ljldqS88pC | M7: 1
A8: Apotek Berlian Farma | B8: AWB02WKFU | C8: 7.9 | D8: 0.023541 | E8: 26072800444949VmLEmOlB9 | F8: 667 | G8: 26072800444949VmLEmOlB9-260728010345500SexiSn1Av-26072801034550trixNIPaR-26072801473602jTFSiKfF | H8: P4N | I8: 667-Komplek Permata Jasindo Lestari Blok A6/14 RT.007 RW.004 Kelurahan Mekarsari, Kecamatan Cimanggis, Kota Depok 16452 | J8: 16452 | K8: Kota Depok | L8: 85374101944 | M8: 1
E9: 260728010345500SexiSn1Av | M9: 1
E10: 26072801034550trixNIPaR | M10: 1
E11: 26072801473602jTFSiKfF | M11: 1
A12: Apotek Berlian Farma Rasamala Bakti Jaya Sukmajaya | B12: AWB02WGVD | C12: 7.4 | D12: 0.023336 | E12: 26072703245809wQimRVF1 | F12: 11437 | G12: 26072703245809wQimRVF1-26072802522246IUjxQvWbh-26072802592265RiGBF708N-26072802592265wqZCVet0V | H12: P4N | I12: 11437-Jl. Rasamala Raya No. 423 Kel. Baktijaya Kec. Sukmajaya Kota Depok 16418 | J12: 16418 | K12: Kota Depok | L12: 6285374101944 | M12: 1
E13: 26072802522246IUjxQvWbh | M13: 1
E14: 26072802592265RiGBF708N | M14: 1
E15: 26072802592265wqZCVet0V | M15: 1
A16: Apotek Bersama Plus Jatimulya Cilodong | B16: AWB02WJRN | C16: 7.31 | D16: 0.035554 | E16: 26072712475211w4O3Py9yv | F16: 15120 | G16: 26072712475211w4O3Py9yv-260727124752122dYBQKGDe-26072712475212Ec78WQpCrD-26072712475212XTxGNiHixm | H16: P4N | I16: 15120-Jalan Pondok Rajeg RT 01 RW 01 NO 79, Desa/Kelurahan Jatimulya, Kec. Cilodong, Kota Depok, Provinsi Jawa Barat, | J16: 16413 | K16: Kota Depok | L16: 6285282565256 | M16: 1
E17: 260727124752122dYBQKGDe | M17: 1
E18: 26072712475212Ec78WQpCrD | M18: 1
E19: 26072712475212XTxGNiHixm | M19: 1
A20: Apotek Bersama Pondok Ranggon Cipayung | B20: AWB02WKH1 | C20: 0.53 | D20: 0.001416 | E20: 26072800513343zU8ph3SKJ | F20: 12430 | G20: 26072800513343zU8ph3SKJ | H20: P4N | I20: 12430-Jl Raya Pondok Ranggon RT 006 RW 004 Kel. Pondok Ranggon Kec. Cipayung, Jakarta Timur | J20: 13860 | K20: Kota Jakarta Timur | L20: 6289529655094 | M20: 1
A21: Apotek Bumi Sehat Serua Bojongsari | B21: AWB02WJ9B | C21: 0.44 | D21: 0.002296 | E21: 26072707523848Dhpuftwa | F21: 11084 | G21: 26072707523848Dhpuftwa | H21: P4N | I21: 11084-Jl. Serua Raya, Kel Serua Kec. Bojongsari, Kota Depok, 16517 | J21: 16517 | K21: Kota Depok | L21: 6281934028112 | M21: 1
A22: Apotek Bunda Bedahan Sawangan | B22: AWB02WJJX | C22: 1.05 | D22: 0.002578 | E22: 26072710184801AQgMPUJcI | F22: 13593 | G22: 26072710184801AQgMPUJcI | H22: P4N | I22: 13593-Jl. H. Sulaiman No.06, RT004/RW007, Desa/Kelurahan Bedahan, Kec. Sawangan, Kota Depok | J22: 16519 | K22: Kota Depok | L22: 6281382843554 | M22: 1
A23: Apotek Cipayung 1 | B23: AWB02WKTX | C23: 9.89 | D23: 0.035966 | E23: 260728014140360ppVZvbV | F23: 8251 | G23: 260728014140360ppVZvbV-26072801414037XH6dCj30sh-260728015619662gr5Ce0Coa-26072801561966LCCsOJtss | H23: P4N | I23: 8251-Jl. Raya Jembatan Serong Blok Sawo No. 115 RT. 002 RW. 003 Kel. Cipayung Kec. Cipayung Kota Depok | J23: 16437 | K23: Kota Depok | L23: 81264043044 | M23: 1
E24: 26072801414037XH6dCj30sh | M24: 1
E25: 260728015619662gr5Ce0Coa | M25: 1
E26: 26072801561966LCCsOJtss | M26: 1
A27: Apotek Cita Sehat Curug Bojongsari | B27: AWB02WJMZ | C27: 7.39 | D27: 0.035216 | E27: 26072711371829bD90OfAG | F27: 13096 | G27: 26072711371829bD90OfAG-26072711371829hZImrWHPpe-26072711371829MedkSjEjj | H27: P4N | I27: 13096-Jl. Raya Curug Ciputat RT 001 RW 002 Kel. Curug Kec. Bojongsari Kota Depok | J27: 16517 | K27: Kota Depok | L27: 6285220978760 | M27: 1
E28: 26072711371829hZImrWHPpe | M28: 1
E29: 26072711371829MedkSjEjj | M29: 1
A30: Apotek Clara Jaya | B30: AWB02WJ03 | C30: 0.21 | D30: 0.001617 | E30: 260727060846087GrvfxYt | F30: 2649 | G30: 260727060846087GrvfxYt | H30: P4N | I30: 2649-Jalan Monumen Pancasila Sakti RT 007 RW 002 Kelurahan Lubang Buaya Kecamatan Cipayung Jakarta Timur 13810 | J30: 13810 | K30: Kota Jakarta Timur | L30: 6285748601748 | M30: 1
A31: Apotek Dafa Cipayung Cipayung | B31: AWB02WJ9T | C31: 11.51 | D31: 0.040022 | E31: 26072707560190rhBnVpiLi | F31: 13177 | G31: 26072707560190rhBnVpiLi-26072707560190ymqgVdWPi | H31: P4N | I31: 13177-Jl. Jembatan Serong RT 006 RW 002 Kel. Cipayung Kec. Cipayung Kota Depok | J31: 16437 | K31: Kota Depok | L31: 6282364343108 | M31: 2
E32: 26072707560190ymqgVdWPi | M32: 1
A33: Apotek Damai | B33: AWB02WJC8 | C33: 0.25 | D33: 0.00168 | E33: 26072708294775X2jgOh7r | F33: 317 | G33: 26072708294775X2jgOh7r | H33: P4N | I33: 317-Jl. Menpor No. 12, Palsigunung, RT. 007 / RW. 003, Kelurahan Tugu, Kecamatan Cimanggis, Depok, Jawa Barat 16451 | J33: 16451 | K33: Kota Depok | L33: 81296144347 | M33: 1
A34: Apotek Dewi Farma | B34: AWB02WJ7E | C34: 3.67 | D34: 0.009967 | E34: 26072707241110QJcTk8YNC | F34: 724 | G34: 26072707241110QJcTk8YNC | H34: P4N | I34: 724-Jalan Mess AL Kranggan Wetan RT.001/RW.012, Kelurahan Jatirangga, Kecamatan Jatisampurna, Kota Bekasi 17434 | J34: 17434 | K34: Kota Bekasi | L34: 85283705505 | M34: 2
A35: Apotek Faisal | B35: AWB02WKEL | C35: 1.11 | D35: 0.003461 | E35: 26072800322508vKhc2TWx9 | F35: 1442 | G35: 26072800322508vKhc2TWx9 | H35: P4N | I35: 1442-Jalan Tawangmangu Raya Blok C2 No. 4 RT 19 RW 07 Kelurahan Jati Cempaka Kecamatan Pondok Gede Kota Bekasi 17411 | J35: 17411 | K35: Kota Bekasi | L35: 87773506955 | M35: 1
A36: Apotek FarmaDok Jatiranggon Jatisampurna | B36: AWB02WJT2 | C36: 9.39 | D36: 0.031097 | E36: 260727130541123P9fwqGX8k | F36: 17703 | G36: 260727130541123P9fwqGX8k-26072713054112jKXG2Pgb2D-26072713054112VQ5BgPLP | H36: P4N | I36: 17703-Jl. Raya Kranggan No. 93 RT.006/RW.005, Desa/Kelurahan Jatiranggon, Kec. Jatisampurna, Kota Bekasi | J36: 17432 | K36: Kota Bekasi | L36: 6285885477255 | M36: 1
E37: 26072713054112jKXG2Pgb2D | M37: 2
E38: 26072713054112VQ5BgPLP | M38: 1
A39: Apotek Fatih Jatibening Baru Pondok Gede | B39: AWB02WJMV | C39: 9.83 | D39: 0.021641 | E39: 26072711350898koIZhWruw | F39: 16587 | G39: 26072711350898koIZhWruw-26072711350899gtRmMQ5NSR-26072711471783EBYJf2XQ8B-26072711471783v1Ybwtvm | H39: P4N | I39: 16587-Jl. Lampiri Raya No.108 B Desa/Kelurahan Jatibening Baru,Kecamatan Pondok Gede, Kota Bekasi, Jawa Barat, 17412 | J39: 17412 | K39: Kota Bekasi | L39: 6281214148920 | M39: 1
E40: 26072711350899gtRmMQ5NSR | M40: 1
...

Sheet OC Upload
A1: requested_tracking_number | B1: global_shipper_id | C1: service_type | D1: reference.merchant_order_number | E1: service_level | F1: from.name | G1: from.phone_number | H1: from.address.address1 | I1: from.address.country | J1: to.name | K1: to.phone_number | L1: to.address.address1 | M1: to.address.country | N1: to.address.kecamatan | O1: to.address.city | P1: to.address.province | Q1: to.address.postcode | R1: parcel_job.delivery_instructions | S1: parcel_job.delivery_start_date | T1: parcel_job.delivery_timeslot.start_time | U1: parcel_job.delivery_timeslot.end_time | V1: parcel_job.delivery_timeslot.timezone | W1: parcel_job.dimensions.weight | X1: parcel_job.is_pickup_required | Y1: parcel_job.items.0.item_description | Z1: parcel_job.items.0.is_dangerous_good | AA1: b2b.documents_required | AB1: bundle_information.total_quantity | AC1: bundle_information.requested_piece_tracking_numbers | AD1: parcel_job.insured_value | AE1: corporate.branch_id | AF1: parcel_job.dimensions.height | AG1: parcel_job.dimensions.length | AH1: parcel_job.dimensions.width | AQ1: CEK (jangan upload)
A2: =IF($AS2="","",INDEX('TMP Paste'!$B$2:$B$1601,$AS2)) -> AWB02WJVH | B2: =IF($AS2="","",Config!$B$14) -> 11398423 | C2: =IF($AS2="","",Config!$B$15) -> Corporate B2B Bundle | D2: =IF($AS2="","",INDEX('TMP Paste'!$B$2:$B$1601,$AS2)) -> AWB02WJVH | E2: =IF($AS2="","",Config!$B$27) -> STANDARD | F2: =IF($AS2="","",Config!$B$9) -> PT Teknologi Medika Pratama (SwipeRx) (B2BR) | G2: =IF($AS2="","",Config!$B$10) -> 087733785699 | H2: =IF($AS2="","",Config!$B$11) -> Jl. Tugu Raya, Tugu, Kec. Cimanggis, Kota Depok, Jawa Barat 16451,KUBIK LOGISTICS - Kompleks Pergudangan,Gudang E1 | I2: =IF($AS2="","",Config!$B$16) -> ID | J2: =IF($AS2="","",INDEX('TMP Paste'!$A$2:$A$1601,$AS2)) -> Apotek Afia | K2: =IF($AS2="","",INDEX('TMP Paste'!$L$2:$L$1601,$AS2)) -> 895808010200 | L2: =IF($AS2="","",INDEX('TMP Paste'!$I$2:$I$1601,$AS2)) -> 3062-Jalan MI Ridwan Rais No.3 RT 002 RW 006 Kelurahan Beji Timur Kecamatan Beji Kota Depok 16422 | M2: =IF($AS2="","",Config!$B$16) -> ID | N2: =IF($AS2="","","") | O2: =IF($AS2="","",INDEX('TMP Paste'!$K$2:$K$1601,$AS2)) -> Kota Depok | P2: =IF($AS2="","","") | Q2: =IF($AS2="","",INDEX('TMP Paste'!$J$2:$J$1601,$AS2)) -> 16422 | R2: =IF($AS2="","",Config!$B$24) -> Delivery Note wajib ada nama penerima, ditandatangani dan distempel penerima. Jika di label tertera "SP Manual", maka dokumen SP Manual harus diminta ke penerima sesuai dengan jumlah PO yang butuh SP Manual. Apabila ada retur, catat di Delivery Note dan update ke IC | S2: =IF($AS2="","",TEXT(Config!$B$4,"yyyy-mm-dd")) -> 2026-08-18 | T2: =IF($AS2="","",Config!$B$17) -> 09:00 | U2: =IF($AS2="","",Config!$B$18) -> 22:00 | V2: =IF($AS2="","",Config!$B$19) -> Asia/Jakarta | W2: =IF($AS2="","",INDEX('TMP Paste'!$C$2:$C$1601,$AS2)) -> 0.3 | X2: =IF($AS2="","",Config!$B$29) -> FALSE | Y2: =IF($AT2="","",INDEX(Calc!$I$2:$I$1601,$AT2)&" - "&INDEX(Calc!$D$2:$D$1601,$AT2)&" koli") -> 26072713473538DTjozNXFa (1) - 1 koli | Z2: =IF($AS2="","",Config!$B$21) -> FALSE | AA2: =IF($AS2="","",Config!$B$22) -> RDO | AB2: =IF($AT2="","",INDEX(Calc!$D$2:$D$1601,$AT2)) -> 1 | AC2: =IF($AT2="","",INDEX(Calc!$G$2:$G$1601,$AT2)) -> 26072713473538DTjozNXFa-01 | AD2: =IF($AS2="","",Config!$B$23) -> 0 | AE2: =IF($AS2="","",Config!$B$28) -> 1 | AF2: =IF($AS2="","",IF(OR($AU2="",$AU2<=0,$AU2>=1000000),"",IF($AU2<10000,10,100))) -> 10 | AG2: =IF($AS2="","",IF(OR($AU2="",$AU2<=0,$AU2>=1000000),"",IF($AU2<10000,$AU2/100,IF($AU2<100000,$AU2/1000,$AU2/10000)))) -> 14.23 | AH2: =IF($AS2="","",IF(OR($AU2="",$AU2<=0,$AU2>=1000000),"",IF($AU2<100000,10,100))) -> 10 | AI2: =IF($AG2="","",SUMIF($AG$2:$AG2,$AG2,$AH$2:$AH2)) -> 10 | AJ2: =IF('TMP Paste'!$F2="","",IF('TMP Paste'!$B2="",$AJ1,'TMP Paste'!$B2)) -> AWB02WJVH | AK2: =IF('TMP Paste'!$F2="","",N('TMP Paste'!$G2)) -> 0 | AL2: =IF('TMP Paste'!$F2="","",IF('TMP Paste'!$M2="",$AL1,'TMP Paste'!$M2)) -> 1 | AM2: =IF('TMP Paste'!$F2="","",IF('TMP Paste'!$N2="",$AM1,'TMP Paste'!$N2)) -> 0 | AN2: =IF('TMP Paste'!$F2="","",IF('TMP Paste'!$O2="",$AN1,'TMP Paste'!$O2)) -> 0 | AO2: =IF('TMP Paste'!$F2="","",IF('TMP Paste'!$P2="",$AO1,'TMP Paste'!$P2)) -> 0 | AP2: =IF($AG2="","",LEN($R2)) -> 266 | AQ2: =IF($AS2="","",TRIM(IF(COUNTIFS(Calc!$B$2:$B$1601,ROW()-1,Calc!$C$2:$C$1601,"<1")>0,"Ada PO tanpa Koli - cek TMP. ","")&IF(OR($AU2="",$AU2<=0),"Volume kosong/0 - dimensi dikosongkan. ","")&IF(AND($AU2<>"",$AU2>=1000000),"Volume >= 1.000.000 cm3 (di luar aturan) - dimensi dikosongkan. ","")&IF(LEN($R2)>500,"R > 500 karakter.",""))) | AS2: =IFERROR(MATCH(ROW()-1,Calc!$J$2:$J$1601,0),"") -> 1 | AT2: =IFERROR(MATCH(ROW()-1,Calc!$K$2:$K$1601,0),"") -> 1 | AU2: =IF($AS2="","",IFERROR(INDEX('TMP Paste'!$D$2:$D$1601,$AS2)*1000000/$AB2,"")) -> 1423
A3: =IF($AS3="","",INDEX('TMP Paste'!$B$2:$B$1601,$AS3)) -> AWB02WJ90 | B3: =IF($AS3="","",Config!$B$14) -> 11398423 | C3: =IF($AS3="","",Config!$B$15) -> Corporate B2B Bundle | D3: =IF($AS3="","",INDEX('TMP Paste'!$B$2:$B$1601,$AS3)) -> AWB02WJ90 | E3: =IF($AS3="","",Config!$B$27) -> STANDARD | F3: =IF($AS3="","",Config!$B$9) -> PT Teknologi Medika Pratama (SwipeRx) (B2BR) | G3: =IF($AS3="","",Config!$B$10) -> 087733785699 | H3: =IF($AS3="","",Config!$B$11) -> Jl. Tugu Raya, Tugu, Kec. Cimanggis, Kota Depok, Jawa Barat 16451,KUBIK LOGISTICS - Kompleks Pergudangan,Gudang E1 | I3: =IF($AS3="","",Config!$B$16) -> ID | J3: =IF($AS3="","",INDEX('TMP Paste'!$A$2:$A$1601,$AS3)) -> Apotek Alam Sehat Farma | K3: =IF($AS3="","",INDEX('TMP Paste'!$L$2:$L$1601,$AS3)) -> 81382701345 | L3: =IF($AS3="","",INDEX('TMP Paste'!$I$2:$I$1601,$AS3)) -> 836-Jalan Anggrek Raya No. 27-28 RT 002/004 Kelurahan Depok Jaya Kecamatan Pancoran Mas 16432 | M3: =IF($AS3="","",Config!$B$16) -> ID | N3: =IF($AS3="","","") | O3: =IF($AS3="","",INDEX('TMP Paste'!$K$2:$K$1601,$AS3)) -> Kota Depok | P3: =IF($AS3="","","") | Q3: =IF($AS3="","",INDEX('TMP Paste'!$J$2:$J$1601,$AS3)) -> 16432 | R3: =IF($AS3="","",Config!$B$24) -> Delivery Note wajib ada nama penerima, ditandatangani dan distempel penerima. Jika di label tertera "SP Manual", maka dokumen SP Manual harus diminta ke penerima sesuai dengan jumlah PO yang butuh SP Manual. Apabila ada retur, catat di Delivery Note dan update ke IC | S3: =IF($AS3="","",TEXT(Config!$B$4,"yyyy-mm-dd")) -> 2026-08-18 | T3: =IF($AS3="","",Config!$B$17) -> 09:00 | U3: =IF($AS3="","",Config!$B$18) -> 22:00 | V3: =IF($AS3="","",Config!$B$19) -> Asia/Jakarta | W3: =IF($AS3="","",INDEX('TMP Paste'!$C$2:$C$1601,$AS3)) -> 1.2 | X3: =IF($AS3="","",Config!$B$29) -> FALSE | Y3: =IF($AT3="","",INDEX(Calc!$I$2:$I$1601,$AT3)&" - "&INDEX(Calc!$D$2:$D$1601,$AT3)&" koli") -> 26072707484936JExQscwbq (1) - 1 koli | Z3: =IF($AS3="","",Config!$B$21) -> FALSE | AA3: =IF($AS3="","",Config!$B$22) -> RDO | AB3: =IF($AT3="","",INDEX(Calc!$D$2:$D$1601,$AT3)) -> 1 | AC3: =IF($AT3="","",INDEX(Calc!$G$2:$G$1601,$AT3)) -> 26072707484936JExQscwbq-01 | AD3: =IF($AS3="","",Config!$B$23) -> 0 | AE3: =IF($AS3="","",Config!$B$28) -> 1 | AF3: =IF($AS3="","",IF(OR($AU3="",$AU3<=0,$AU3>=1000000),"",IF($AU3<10000,10,100))) -> 10 | AG3: =IF($AS3="","",IF(OR($AU3="",$AU3<=0,$AU3>=1000000),"",IF($AU3<10000,$AU3/100,IF($AU3<100000,$AU3/1000,$AU3/10000)))) -> 29.02 | AH3: =IF($AS3="","",IF(OR($AU3="",$AU3<=0,$AU3>=1000000),"",IF($AU3<100000,10,100))) -> 10 | AI3: =IF($AG3="","",SUMIF($AG$2:$AG3,$AG3,$AH$2:$AH3)) -> 10 | AJ3: =IF('TMP Paste'!$F3="","",IF('TMP Paste'!$B3="",$AJ2,'TMP Paste'!$B3)) -> AWB02WJ90 | AK3: =IF('TMP Paste'!$F3="","",N('TMP Paste'!$G3)) -> 0 | AL3: =IF('TMP Paste'!$F3="","",IF('TMP Paste'!$M3="",$AL2,'TMP Paste'!$M3)) -> 1 | AM3: =IF('TMP Paste'!$F3="","",IF('TMP Paste'!$N3="",$AM2,'TMP Paste'!$N3)) -> 0 | AN3: =IF('TMP Paste'!$F3="","",IF('TMP Paste'!$O3="",$AN2,'TMP Paste'!$O3)) -> 0 | AO3: =IF('TMP Paste'!$F3="","",IF('TMP Paste'!$P3="",$AO2,'TMP Paste'!$P3)) -> 0 | AP3: =IF($AG3="","",LEN($R3)) -> 266 | AQ3: =IF($AS3="","",TRIM(IF(COUNTIFS(Calc!$B$2:$B$1601,ROW()-1,Calc!$C$2:$C$1601,"<1")>0,"Ada PO tanpa Koli - cek TMP. ","")&IF(OR($AU3="",$AU3<=0),"Volume kosong/0 - dimensi dikosongkan. ","")&IF(AND($AU3<>"",$AU3>=1000000),"Volume >= 1.000.000 cm3 (di luar aturan) - dimensi dikosongkan. ","")&IF(LEN($R3)>500,"R > 500 karakter.",""))) | AS3: =IFERROR(MATCH(ROW()-1,Calc!$J$2:$J$1601,0),"") -> 2 | AT3: =IFERROR(MATCH(ROW()-1,Calc!$K$2:$K$1601,0),"") -> 2 | AU3: =IF($AS3="","",IFERROR(INDEX('TMP Paste'!$D$2:$D$1601,$AS3)*1000000/$AB3,"")) -> 2902
A4: =IF($AS4="","",INDEX('TMP Paste'!$B$2:$B$1601,$AS4)) -> AWB02WL4S | B4: =IF($AS4="","",Config!$B$14) -> 11398423 | C4: =IF($AS4="","",Config!$B$15) -> Corporate B2B Bundle | D4: =IF($AS4="","",INDEX('TMP Paste'!$B$2:$B$1601,$AS4)) -> AWB02WL4S | E4: =IF($AS4="","",Config!$B$27) -> STANDARD | F4: =IF($AS4="","",Config!$B$9) -> PT Teknologi Medika Pratama (SwipeRx) (B2BR) | G4: =IF($AS4="","",Config!$B$10) -> 087733785699 | H4: =IF($AS4="","",Config!$B$11) -> Jl. Tugu Raya, Tugu, Kec. Cimanggis, Kota Depok, Jawa Barat 16451,KUBIK LOGISTICS - Kompleks Pergudangan,Gudang E1 | I4: =IF($AS4="","",Config!$B$16) -> ID | J4: =IF($AS4="","",INDEX('TMP Paste'!$A$2:$A$1601,$AS4)) -> Apotek Ben Waras 19 | K4: =IF($AS4="","",INDEX('TMP Paste'!$L$2:$L$1601,$AS4)) -> 6289510341165 | L4: =IF($AS4="","",INDEX('TMP Paste'!$I$2:$I$1601,$AS4)) -> 903-Jalan Karya Ruko Tugu Bedahan No. 10 RT.001 RW.16 Kelurahan Bedahan, Kecamatan Sawangan, Kota Depok, Jawa Barat 16519 | M4: =IF($AS4="","",Config!$B$16) -> ID | N4: =IF($AS4="","","") | O4: =IF($AS4="","",INDEX('TMP Paste'!$K$2:$K$1601,$AS4)) -> Kota Depok | P4: =IF($AS4="","","") | Q4: =IF($AS4="","",INDEX('TMP Paste'!$J$2:$J$1601,$AS4)) -> 16519 | R4: =IF($AS4="","",Config!$B$24) -> Delivery Note wajib ada nama penerima, ditandatangani dan distempel penerima. Jika di label tertera "SP Manual", maka dokumen SP Manual harus diminta ke penerima sesuai dengan jumlah PO yang butuh SP Manual. Apabila ada retur, catat di Delivery Note dan update ke IC | S4: =IF($AS4="","",TEXT(Config!$B$4,"yyyy-mm-dd")) -> 2026-08-18 | T4: =IF($AS4="","",Config!$B$17) -> 09:00 | U4: =IF($AS4="","",Config!$B$18) -> 22:00 | V4: =IF($AS4="","",Config!$B$19) -> Asia/Jakarta | W4: =IF($AS4="","",INDEX('TMP Paste'!$C$2:$C$1601,$AS4)) -> 0.46 | X4: =IF($AS4="","",Config!$B$29) -> FALSE | Y4: =IF($AT4="","",INDEX(Calc!$I$2:$I$1601,$AT4)&" - "&INDEX(Calc!$D$2:$D$1601,$AT4)&" koli") -> 26072802143715UaH54d1OD (1) - 1 koli | Z4: =IF($AS4="","",Config!$B$21) -> FALSE | AA4: =IF($AS4="","",Config!$B$22) -> RDO | AB4: =IF($AT4="","",INDEX(Calc!$D$2:$D$1601,$AT4)) -> 1 | AC4: =IF($AT4="","",INDEX(Calc!$G$2:$G$1601,$AT4)) -> 26072802143715UaH54d1OD-01 | AD4: =IF($AS4="","",Config!$B$23) -> 0 | AE4: =IF($AS4="","",Config!$B$28) -> 1 | AF4: =IF($AS4="","",IF(OR($AU4="",$AU4<=0,$AU4>=1000000),"",IF($AU4<10000,10,100))) -> 10 | AG4: =IF($AS4="","",IF(OR($AU4="",$AU4<=0,$AU4>=1000000),"",IF($AU4<10000,$AU4/100,IF($AU4<100000,$AU4/1000,$AU4/10000)))) -> 17.94 | AH4: =IF($AS4="","",IF(OR($AU4="",$AU4<=0,$AU4>=1000000),"",IF($AU4<100000,10,100))) -> 10 | AI4: =IF($AG4="","",SUMIF($AG$2:$AG4,$AG4,$AH$2:$AH4)) -> 10 | AJ4: =IF('TMP Paste'!$F4="","",IF('TMP Paste'!$B4="",$AJ3,'TMP Paste'!$B4)) -> AWB02WL4S | AK4: =IF('TMP Paste'!$F4="","",N('TMP Paste'!$G4)) -> 0 | AL4: =IF('TMP Paste'!$F4="","",IF('TMP Paste'!$M4="",$AL3,'TMP Paste'!$M4)) -> 1 | AM4: =IF('TMP Paste'!$F4="","",IF('TMP Paste'!$N4="",$AM3,'TMP Paste'!$N4)) -> 0 | AN4: =IF('TMP Paste'!$F4="","",IF('TMP Paste'!$O4="",$AN3,'TMP Paste'!$O4)) -> 0 | AO4: =IF('TMP Paste'!$F4="","",IF('TMP Paste'!$P4="",$AO3,'TMP Paste'!$P4)) -> 0 | AP4: =IF($AG4="","",LEN($R4)) -> 266 | AQ4: =IF($AS4="","",TRIM(IF(COUNTIFS(Calc!$B$2:$B$1601,ROW()-1,Calc!$C$2:$C$1601,"<1")>0,"Ada PO tanpa Koli - cek TMP. ","")&IF(OR($AU4="",$AU4<=0),"Volume kosong/0 - dimensi dikosongkan. ","")&IF(AND($AU4<>"",$AU4>=1000000),"Volume >= 1.000.000 cm3 (di luar aturan) - dimensi dikosongkan. ","")&IF(LEN($R4)>500,"R > 500 karakter.",""))) | AS4: =IFERROR(MATCH(ROW()-1,Calc!$J$2:$J$1601,0),"") -> 3 | AT4: =IFERROR(MATCH(ROW()-1,Calc!$K$2:$K$1601,0),"") -> 3 | AU4: =IF($AS4="","",IFERROR(INDEX('TMP Paste'!$D$2:$D$1601,$AS4)*1000000/$AB4,"")) -> 1794
A5: =IF($AS5="","",INDEX('TMP Paste'!$B$2:$B$1601,$AS5)) -> AWB02WKTT | B5: =IF($AS5="","",Config!$B$14) -> 11398423 | C5: =IF($AS5="","",Config!$B$15) -> Corporate B2B Bundle | D5: =IF($AS5="","",INDEX('TMP Paste'!$B$2:$B$1601,$AS5)) -> AWB02WKTT | E5: =IF($AS5="","",Config!$B$27) -> STANDARD | F5: =IF($AS5="","",Config!$B$9) -> PT Teknologi Medika Pratama (SwipeRx) (B2BR) | G5: =IF($AS5="","",Config!$B$10) -> 087733785699 | H5: =IF($AS5="","",Config!$B$11) -> Jl. Tugu Raya, Tugu, Kec. Cimanggis, Kota Depok, Jawa Barat 16451,KUBIK LOGISTICS - Kompleks Pergudangan,Gudang E1 | I5: =IF($AS5="","",Config!$B$16) -> ID | J5: =IF($AS5="","",INDEX('TMP Paste'!$A$2:$A$1601,$AS5)) -> Apotek Berkah 9 | K5: =IF($AS5="","",INDEX('TMP Paste'!$L$2:$L$1601,$AS5)) -> 8979743443 | L5: =IF($AS5="","",INDEX('TMP Paste'!$I$2:$I$1601,$AS5)) -> 3479-Jalan Raya Pasir Putih Ruko Cahaya Garuda No. 6 RT 005 RW 009 Sawangan Permai Kelurahan Pasir Putih Kecamatan Sawangan Kota Depok 16519 | M5: =IF($AS5="","",Config!$B$16) -> ID | N5: =IF($AS5="","","") | O5: =IF($AS5="","",INDEX('TMP Paste'!$K$2:$K$1601,$AS5)) -> Kota Depok | P5: =IF($AS5="","","") | Q5: =IF($AS5="","",INDEX('TMP Paste'!$J$2:$J$1601,$AS5)) -> 16519 | R5: =IF($AS5="","",Config!$B$24) -> Delivery Note wajib ada nama penerima, ditandatangani dan distempel penerima. Jika di label tertera "SP Manual", maka dokumen SP Manual harus diminta ke penerima sesuai dengan jumlah PO yang butuh SP Manual. Apabila ada retur, catat di Delivery Note dan update ke IC | S5: =IF($AS5="","",TEXT(Config!$B$4,"yyyy-mm-dd")) -> 2026-08-18 | T5: =IF($AS5="","",Config!$B$17) -> 09:00 | U5: =IF($AS5="","",Config!$B$18) -> 22:00 | V5: =IF($AS5="","",Config!$B$19) -> Asia/Jakarta | W5: =IF($AS5="","",INDEX('TMP Paste'!$C$2:$C$1601,$AS5)) -> 3.04 | X5: =IF($AS5="","",Config!$B$29) -> FALSE | Y5: =IF($AT5="","",INDEX(Calc!$I$2:$I$1601,$AT5)&" - "&INDEX(Calc!$D$2:$D$1601,$AT5)&" koli") -> 26072801412330Cygue4Ku6 (1), 26072802554064GKk0wdiYh (1), 26072802554064ljldqS88pC (1) - 3 koli | Z5: =IF($AS5="","",Config!$B$21) -> FALSE | AA5: =IF($AS5="","",Config!$B$22) -> RDO | AB5: =IF($AT5="","",INDEX(Calc!$D$2:$D$1601,$AT5)) -> 3 | AC5: =IF($AT5="","",INDEX(Calc!$G$2:$G$1601,$AT5)) -> 26072801412330Cygue4Ku6-01, 26072802554064GKk0wdiYh-02, 26072802554064ljldqS88pC-03 | AD5: =IF($AS5="","",Config!$B$23) -> 0 | AE5: =IF($AS5="","",Config!$B$28) -> 1 | AF5: =IF($AS5="","",IF(OR($AU5="",$AU5<=0,$AU5>=1000000),"",IF($AU5<10000,10,100))) -> 10 | AG5: =IF($AS5="","",IF(OR($AU5="",$AU5<=0,$AU5>=1000000),"",IF($AU5<10000,$AU5/100,IF($AU5<100000,$AU5/1000,$AU5/10000)))) -> 32.88 | AH5: =IF($AS5="","",IF(OR($AU5="",$AU5<=0,$AU5>=1000000),"",IF($AU5<100000,10,100))) -> 10 | AI5: =IF($AG5="","",SUMIF($AG$2:$AG5,$AG5,$AH$2:$AH5)) -> 10 | AJ5: =IF('TMP Paste'!$F5="","",IF('TMP Paste'!$B5="",$AJ4,'TMP Paste'!$B5)) -> AWB02WKTT | AK5: =IF('TMP Paste'!$F5="","",N('TMP Paste'!$G5)) -> 0 | AL5: =IF('TMP Paste'!$F5="","",IF('TMP Paste'!$M5="",$AL4,'TMP Paste'!$M5)) -> 1 | AM5: =IF('TMP Paste'!$F5="","",IF('TMP Paste'!$N5="",$AM4,'TMP Paste'!$N5)) -> 0 | AN5: =IF('TMP Paste'!$F5="","",IF('TMP Paste'!$O5="",$AN4,'TMP Paste'!$O5)) -> 0 | AO5: =IF('TMP Paste'!$F5="","",IF('TMP Paste'!$P5="",$AO4,'TMP Paste'!$P5)) -> 0 | AP5: =IF($AG5="","",LEN($R5)) -> 266 | AQ5: =IF($AS5="","",TRIM(IF(COUNTIFS(Calc!$B$2:$B$1601,ROW()-1,Calc!$C$2:$C$1601,"<1")>0,"Ada PO tanpa Koli - cek TMP. ","")&IF(OR($AU5="",$AU5<=0),"Volume kosong/0 - dimensi dikosongkan. ","")&IF(AND($AU5<>"",$AU5>=1000000),"Volume >= 1.000.000 cm3 (di luar aturan) - dimensi dikosongkan. ","")&IF(LEN($R5)>500,"R > 500 karakter.",""))) | AS5: =IFERROR(MATCH(ROW()-1,Calc!$J$2:$J$1601,0),"") -> 4 | AT5: =IFERROR(MATCH(ROW()-1,Calc!$K$2:$K$1601,0),"") -> 6 | AU5: =IF($AS5="","",IFERROR(INDEX('TMP Paste'!$D$2:$D$1601,$AS5)*1000000/$AB5,"")) -> 3288
A6: =IF($AS6="","",INDEX('TMP Paste'!$B$2:$B$1601,$AS6)) -> AWB02WKFU | B6: =IF($AS6="","",Config!$B$14) -> 11398423 | C6: =IF($AS6="","",Config!$B$15) -> Corporate B2B Bundle | D6: =IF($AS6="","",INDEX('TMP Paste'!$B$2:$B$1601,$AS6)) -> AWB02WKFU | E6: =IF($AS6="","",Config!$B$27) -> STANDARD | F6: =IF($AS6="","",Config!$B$9) -> PT Teknologi Medika Pratama (SwipeRx) (B2BR) | G6: =IF($AS6="","",Config!$B$10) -> 087733785699 | H6: =IF($AS6="","",Config!$B$11) -> Jl. Tugu Raya, Tugu, Kec. Cimanggis, Kota Depok, Jawa Barat 16451,KUBIK LOGISTICS - Kompleks Pergudangan,Gudang E1 | I6: =IF($AS6="","",Config!$B$16) -> ID | J6: =IF($AS6="","",INDEX('TMP Paste'!$A$2:$A$1601,$AS6)) -> Apotek Berlian Farma | K6: =IF($AS6="","",INDEX('TMP Paste'!$L$2:$L$1601,$AS6)) -> 85374101944 | L6: =IF($AS6="","",INDEX('TMP Paste'!$I$2:$I$1601,$AS6)) -> 667-Komplek Permata Jasindo Lestari Blok A6/14 RT.007 RW.004 Kelurahan Mekarsari, Kecamatan Cimanggis, Kota Depok 16452 | M6: =IF($AS6="","",Config!$B$16) -> ID | N6: =IF($AS6="","","") | O6: =IF($AS6="","",INDEX('TMP Paste'!$K$2:$K$1601,$AS6)) -> Kota Depok | P6: =IF($AS6="","","") | Q6: =IF($AS6="","",INDEX('TMP Paste'!$J$2:$J$1601,$AS6)) -> 16452 | R6: =IF($AS6="","",Config!$B$24) -> Delivery Note wajib ada nama penerima, ditandatangani dan distempel penerima. Jika di label tertera "SP Manual", maka dokumen SP Manual harus diminta ke penerima sesuai dengan jumlah PO yang butuh SP Manual. Apabila ada retur, catat di Delivery Note dan update ke IC | S6: =IF($AS6="","",TEXT(Config!$B$4,"yyyy-mm-dd")) -> 2026-08-18 | T6: =IF($AS6="","",Config!$B$17) -> 09:00 | U6: =IF($AS6="","",Config!$B$18) -> 22:00 | V6: =IF($AS6="","",Config!$B$19) -> Asia/Jakarta | W6: =IF($AS6="","",INDEX('TMP Paste'!$C$2:$C$1601,$AS6)) -> 7.9 | X6: =IF($AS6="","",Config!$B$29) -> FALSE | Y6: =IF($AT6="","",INDEX(Calc!$I$2:$I$1601,$AT6)&" - "&INDEX(Calc!$D$2:$D$1601,$AT6)&" koli") -> 26072800444949VmLEmOlB9 (1), 260728010345500SexiSn1Av (1), 26072801034550trixNIPaR (1), 26072801473602jTFSiKfF (1) - 4 koli | Z6: =IF($AS6="","",Config!$B$21) -> FALSE | AA6: =IF($AS6="","",Config!$B$22) -> RDO | AB6: =IF($AT6="","",INDEX(Calc!$D$2:$D$1601,$AT6)) -> 4 | AC6: =IF($AT6="","",INDEX(Calc!$G$2:$G$1601,$AT6)) -> 26072800444949VmLEmOlB9-01, 260728010345500SexiSn1Av-02, 26072801034550trixNIPaR-03, 26072801473602jTFSiKfF-04 | AD6: =IF($AS6="","",Config!$B$23) -> 0 | AE6: =IF($AS6="","",Config!$B$28) -> 1 | AF6: =IF($AS6="","",IF(OR($AU6="",$AU6<=0,$AU6>=1000000),"",IF($AU6<10000,10,100))) -> 10 | AG6: =IF($AS6="","",IF(OR($AU6="",$AU6<=0,$AU6>=1000000),"",IF($AU6<10000,$AU6/100,IF($AU6<100000,$AU6/1000,$AU6/10000)))) -> 58.8525 | AH6: =IF($AS6="","",IF(OR($AU6="",$AU6<=0,$AU6>=1000000),"",IF($AU6<100000,10,100))) -> 10 | AI6: =IF($AG6="","",SUMIF($AG$2:$AG6,$AG6,$AH$2:$AH6)) -> 10 | AJ6: =IF('TMP Paste'!$F6="","",IF('TMP Paste'!$B6="",$AJ5,'TMP Paste'!$B6)) | AK6: =IF('TMP Paste'!$F6="","",N('TMP Paste'!$G6)) | AL6: =IF('TMP Paste'!$F6="","",IF('TMP Paste'!$M6="",$AL5,'TMP Paste'!$M6)) | AM6: =IF('TMP Paste'!$F6="","",IF('TMP Paste'!$N6="",$AM5,'TMP Paste'!$N6)) | AN6: =IF('TMP Paste'!$F6="","",IF('TMP Paste'!$O6="",$AN5,'TMP Paste'!$O6)) | AO6: =IF('TMP Paste'!$F6="","",IF('TMP Paste'!$P6="",$AO5,'TMP Paste'!$P6)) | AP6: =IF($AG6="","",LEN($R6)) -> 266 | AQ6: =IF($AS6="","",TRIM(IF(COUNTIFS(Calc!$B$2:$B$1601,ROW()-1,Calc!$C$2:$C$1601,"<1")>0,"Ada PO tanpa Koli - cek TMP. ","")&IF(OR($AU6="",$AU6<=0),"Volume kosong/0 - dimensi dikosongkan. ","")&IF(AND($AU6<>"",$AU6>=1000000),"Volume >= 1.000.000 cm3 (di luar aturan) - dimensi dikosongkan. ","")&IF(LEN($R6)>500,"R > 500 karakter.",""))) | AS6: =IFERROR(MATCH(ROW()-1,Calc!$J$2:$J$1601,0),"") -> 7 | AT6: =IFERROR(MATCH(ROW()-1,Calc!$K$2:$K$1601,0),"") -> 10 | AU6: =IF($AS6="","",IFERROR(INDEX('TMP Paste'!$D$2:$D$1601,$AS6)*1000000/$AB6,"")) -> 5885.25
A7: =IF($AS7="","",INDEX('TMP Paste'!$B$2:$B$1601,$AS7)) -> AWB02WGVD | B7: =IF($AS7="","",Config!$B$14) -> 11398423 | C7: =IF($AS7="","",Config!$B$15) -> Corporate B2B Bundle | D7: =IF($AS7="","",INDEX('TMP Paste'!$B$2:$B$1601,$AS7)) -> AWB02WGVD | E7: =IF($AS7="","",Config!$B$27) -> STANDARD | F7: =IF($AS7="","",Config!$B$9) -> PT Teknologi Medika Pratama (SwipeRx) (B2BR) | G7: =IF($AS7="","",Config!$B$10) -> 087733785699 | H7: =IF($AS7="","",Config!$B$11) -> Jl. Tugu Raya, Tugu, Kec. Cimanggis, Kota Depok, Jawa Barat 16451,KUBIK LOGISTICS - Kompleks Pergudangan,Gudang E1 | I7: =IF($AS7="","",Config!$B$16) -> ID | J7: =IF($AS7="","",INDEX('TMP Paste'!$A$2:$A$1601,$AS7)) -> Apotek Berlian Farma Rasamala Bakti Jaya Sukmajaya | K7: =IF($AS7="","",INDEX('TMP Paste'!$L$2:$L$1601,$AS7)) -> 6285374101944 | L7: =IF($AS7="","",INDEX('TMP Paste'!$I$2:$I$1601,$AS7)) -> 11437-Jl. Rasamala Raya No. 423 Kel. Baktijaya Kec. Sukmajaya Kota Depok 16418 | M7: =IF($AS7="","",Config!$B$16) -> ID | N7: =IF($AS7="","","") | O7: =IF($AS7="","",INDEX('TMP Paste'!$K$2:$K$1601,$AS7)) -> Kota Depok | P7: =IF($AS7="","","") | Q7: =IF($AS7="","",INDEX('TMP Paste'!$J$2:$J$1601,$AS7)) -> 16418 | R7: =IF($AS7="","",Config!$B$24) -> Delivery Note wajib ada nama penerima, ditandatangani dan distempel penerima. Jika di label tertera "SP Manual", maka dokumen SP Manual harus diminta ke penerima sesuai dengan jumlah PO yang butuh SP Manual. Apabila ada retur, catat di Delivery Note dan update ke IC | S7: =IF($AS7="","",TEXT(Config!$B$4,"yyyy-mm-dd")) -> 2026-08-18 | T7: =IF($AS7="","",Config!$B$17) -> 09:00 | U7: =IF($AS7="","",Config!$B$18) -> 22:00 | V7: =IF($AS7="","",Config!$B$19) -> Asia/Jakarta | W7: =IF($AS7="","",INDEX('TMP Paste'!$C$2:$C$1601,$AS7)) -> 7.4 | X7: =IF($AS7="","",Config!$B$29) -> FALSE | Y7: =IF($AT7="","",INDEX(Calc!$I$2:$I$1601,$AT7)&" - "&INDEX(Calc!$D$2:$D$1601,$AT7)&" koli") -> 26072703245809wQimRVF1 (1), 26072802522246IUjxQvWbh (1), 26072802592265RiGBF708N (1), 26072802592265wqZCVet0V (1) - 4 koli | Z7: =IF($AS7="","",Config!$B$21) -> FALSE | AA7: =IF($AS7="","",Config!$B$22) -> RDO | AB7: =IF($AT7="","",INDEX(Calc!$D$2:$D$1601,$AT7)) -> 4 | AC7: =IF($AT7="","",INDEX(Calc!$G$2:$G$1601,$AT7)) -> 26072703245809wQimRVF1-01, 26072802522246IUjxQvWbh-02, 26072802592265RiGBF708N-03, 26072802592265wqZCVet0V-04 | AD7: =IF($AS7="","",Config!$B$23) -> 0 | AE7: =IF($AS7="","",Config!$B$28) -> 1 | AF7: =IF($AS7="","",IF(OR($AU7="",$AU7<=0,$AU7>=1000000),"",IF($AU7<10000,10,100))) -> 10 | AG7: =IF($AS7="","",IF(OR($AU7="",$AU7<=0,$AU7>=1000000),"",IF($AU7<10000,$AU7/100,IF($AU7<100000,$AU7/1000,$AU7/10000)))) -> 58.34 | AH7: =IF($AS7="","",IF(OR($AU7="",$AU7<=0,$AU7>=1000000),"",IF($AU7<100000,10,100))) -> 10 | AI7: =IF($AG7="","",SUMIF($AG$2:$AG7,$AG7,$AH$2:$AH7)) -> 10 | AJ7: =IF('TMP Paste'!$F7="","",IF('TMP Paste'!$B7="",$AJ6,'TMP Paste'!$B7)) | AK7: =IF('TMP Paste'!$F7="","",N('TMP Paste'!$G7)) | AL7: =IF('TMP Paste'!$F7="","",IF('TMP Paste'!$M7="",$AL6,'TMP Paste'!$M7)) | AM7: =IF('TMP Paste'!$F7="","",IF('TMP Paste'!$N7="",$AM6,'TMP Paste'!$N7)) | AN7: =IF('TMP Paste'!$F7="","",IF('TMP Paste'!$O7="",$AN6,'TMP Paste'!$O7)) | AO7: =IF('TMP Paste'!$F7="","",IF('TMP Paste'!$P7="",$AO6,'TMP Paste'!$P7)) | AP7: =IF($AG7="","",LEN($R7)) -> 266 | AQ7: =IF($AS7="","",TRIM(IF(COUNTIFS(Calc!$B$2:$B$1601,ROW()-1,Calc!$C$2:$C$1601,"<1")>0,"Ada PO tanpa Koli - cek TMP. ","")&IF(OR($AU7="",$AU7<=0),"Volume kosong/0 - dimensi dikosongkan. ","")&IF(AND($AU7<>"",$AU7>=1000000),"Volume >= 1.000.000 cm3 (di luar aturan) - dimensi dikosongkan. ","")&IF(LEN($R7)>500,"R > 500 karakter.",""))) | AS7: =IFERROR(MATCH(ROW()-1,Calc!$J$2:$J$1601,0),"") -> 11 | AT7: =IFERROR(MATCH(ROW()-1,Calc!$K$2:$K$1601,0),"") -> 14 | AU7: =IF($AS7="","",IFERROR(INDEX('TMP Paste'!$D$2:$D$1601,$AS7)*1000000/$AB7,"")) -> 5834
A8: =IF($AS8="","",INDEX('TMP Paste'!$B$2:$B$1601,$AS8)) -> AWB02WJRN | B8: =IF($AS8="","",Config!$B$14) -> 11398423 | C8: =IF($AS8="","",Config!$B$15) -> Corporate B2B Bundle | D8: =IF($AS8="","",INDEX('TMP Paste'!$B$2:$B$1601,$AS8)) -> AWB02WJRN | E8: =IF($AS8="","",Config!$B$27) -> STANDARD | F8: =IF($AS8="","",Config!$B$9) -> PT Teknologi Medika Pratama (SwipeRx) (B2BR) | G8: =IF($AS8="","",Config!$B$10) -> 087733785699 | H8: =IF($AS8="","",Config!$B$11) -> Jl. Tugu Raya, Tugu, Kec. Cimanggis, Kota Depok, Jawa Barat 16451,KUBIK LOGISTICS - Kompleks Pergudangan,Gudang E1 | I8: =IF($AS8="","",Config!$B$16) -> ID | J8: =IF($AS8="","",INDEX('TMP Paste'!$A$2:$A$1601,$AS8)) -> Apotek Bersama Plus Jatimulya Cilodong | K8: =IF($AS8="","",INDEX('TMP Paste'!$L$2:$L$1601,$AS8)) -> 6285282565256 | L8: =IF($AS8="","",INDEX('TMP Paste'!$I$2:$I$1601,$AS8)) -> 15120-Jalan Pondok Rajeg RT 01 RW 01 NO 79, Desa/Kelurahan Jatimulya, Kec. Cilodong, Kota Depok, Provinsi Jawa Barat, | M8: =IF($AS8="","",Config!$B$16) -> ID | N8: =IF($AS8="","","") | O8: =IF($AS8="","",INDEX('TMP Paste'!$K$2:$K$1601,$AS8)) -> Kota Depok | P8: =IF($AS8="","","") | Q8: =IF($AS8="","",INDEX('TMP Paste'!$J$2:$J$1601,$AS8)) -> 16413 | R8: =IF($AS8="","",Config!$B$24) -> Delivery Note wajib ada nama penerima, ditandatangani dan distempel penerima. Jika di label tertera "SP Manual", maka dokumen SP Manual harus diminta ke penerima sesuai dengan jumlah PO yang butuh SP Manual. Apabila ada retur, catat di Delivery Note dan update ke IC | S8: =IF($AS8="","",TEXT(Config!$B$4,"yyyy-mm-dd")) -> 2026-08-18 | T8: =IF($AS8="","",Config!$B$17) -> 09:00 | U8: =IF($AS8="","",Config!$B$18) -> 22:00 | V8: =IF($AS8="","",Config!$B$19) -> Asia/Jakarta | W8: =IF($AS8="","",INDEX('TMP Paste'!$C$2:$C$1601,$AS8)) -> 7.31 | X8: =IF($AS8="","",Config!$B$29) -> FALSE | Y8: =IF($AT8="","",INDEX(Calc!$I$2:$I$1601,$AT8)&" - "&INDEX(Calc!$D$2:$D$1601,$AT8)&" koli") -> 26072712475211w4O3Py9yv (1), 260727124752122dYBQKGDe (1), 26072712475212Ec78WQpCrD (1), 26072712475212XTxGNiHixm (1) - 4 koli | Z8: =IF($AS8="","",Config!$B$21) -> FALSE | AA8: =IF($AS8="","",Config!$B$22) -> RDO | AB8: =IF($AT8="","",INDEX(Calc!$D$2:$D$1601,$AT8)) -> 4 | AC8: =IF($AT8="","",INDEX(Calc!$G$2:$G$1601,$AT8)) -> 26072712475211w4O3Py9yv-01, 260727124752122dYBQKGDe-02, 26072712475212Ec78WQpCrD-03, 26072712475212XTxGNiHixm-04 | AD8: =IF($AS8="","",Config!$B$23) -> 0 | AE8: =IF($AS8="","",Config!$B$28) -> 1 | AF8: =IF($AS8="","",IF(OR($AU8="",$AU8<=0,$AU8>=1000000),"",IF($AU8<10000,10,100))) -> 10 | AG8: =IF($AS8="","",IF(OR($AU8="",$AU8<=0,$AU8>=1000000),"",IF($AU8<10000,$AU8/100,IF($AU8<100000,$AU8/1000,$AU8/10000)))) -> 88.885 | AH8: =IF($AS8="","",IF(OR($AU8="",$AU8<=0,$AU8>=1000000),"",IF($AU8<100000,10,100))) -> 10 | AI8: =IF($AG8="","",SUMIF($AG$2:$AG8,$AG8,$AH$2:$AH8)) -> 10 | AJ8: =IF('TMP Paste'!$F8="","",IF('TMP Paste'!$B8="",$AJ7,'TMP Paste'!$B8)) -> AWB02WKFU | AK8: =IF('TMP Paste'!$F8="","",N('TMP Paste'!$G8)) -> 0 | AL8: =IF('TMP Paste'!$F8="","",IF('TMP Paste'!$M8="",$AL7,'TMP Paste'!$M8)) -> 1 | AM8: =IF('TMP Paste'!$F8="","",IF('TMP Paste'!$N8="",$AM7,'TMP Paste'!$N8)) | AN8: =IF('TMP Paste'!$F8="","",IF('TMP Paste'!$O8="",$AN7,'TMP Paste'!$O8)) | AO8: =IF('TMP Paste'!$F8="","",IF('TMP Paste'!$P8="",$AO7,'TMP Paste'!$P8)) | AP8: =IF($AG8="","",LEN($R8)) -> 266 | AQ8: =IF($AS8="","",TRIM(IF(COUNTIFS(Calc!$B$2:$B$1601,ROW()-1,Calc!$C$2:$C$1601,"<1")>0,"Ada PO tanpa Koli - cek TMP. ","")&IF(OR($AU8="",$AU8<=0),"Volume kosong/0 - dimensi dikosongkan. ","")&IF(AND($AU8<>"",$AU8>=1000000),"Volume >= 1.000.000 cm3 (di luar aturan) - dimensi dikosongkan. ","")&IF(LEN($R8)>500,"R > 500 karakter.",""))) | AS8: =IFERROR(MATCH(ROW()-1,Calc!$J$2:$J$1601,0),"") -> 15 | AT8: =IFERROR(MATCH(ROW()-1,Calc!$K$2:$K$1601,0),"") -> 18 | AU8: =IF($AS8="","",IFERROR(INDEX('TMP Paste'!$D$2:$D$1601,$AS8)*1000000/$AB8,"")) -> 8888.5
A9: =IF($AS9="","",INDEX('TMP Paste'!$B$2:$B$1601,$AS9)) -> AWB02WKH1 | B9: =IF($AS9="","",Config!$B$14) -> 11398423 | C9: =IF($AS9="","",Config!$B$15) -> Corporate B2B Bundle | D9: =IF($AS9="","",INDEX('TMP Paste'!$B$2:$B$1601,$AS9)) -> AWB02WKH1 | E9: =IF($AS9="","",Config!$B$27) -> STANDARD | F9: =IF($AS9="","",Config!$B$9) -> PT Teknologi Medika Pratama (SwipeRx) (B2BR) | G9: =IF($AS9="","",Config!$B$10) -> 087733785699 | H9: =IF($AS9="","",Config!$B$11) -> Jl. Tugu Raya, Tugu, Kec. Cimanggis, Kota Depok, Jawa Barat 16451,KUBIK LOGISTICS - Kompleks Pergudangan,Gudang E1 | I9: =IF($AS9="","",Config!$B$16) -> ID | J9: =IF($AS9="","",INDEX('TMP Paste'!$A$2:$A$1601,$AS9)) -> Apotek Bersama Pondok Ranggon Cipayung | K9: =IF($AS9="","",INDEX('TMP Paste'!$L$2:$L$1601,$AS9)) -> 6289529655094 | L9: =IF($AS9="","",INDEX('TMP Paste'!$I$2:$I$1601,$AS9)) -> 12430-Jl Raya Pondok Ranggon RT 006 RW 004 Kel. Pondok Ranggon Kec. Cipayung, Jakarta Timur | M9: =IF($AS9="","",Config!$B$16) -> ID | N9: =IF($AS9="","","") | O9: =IF($AS9="","",INDEX('TMP Paste'!$K$2:$K$1601,$AS9)) -> Kota Jakarta Timur | P9: =IF($AS9="","","") | Q9: =IF($AS9="","",INDEX('TMP Paste'!$J$2:$J$1601,$AS9)) -> 13860 | R9: =IF($AS9="","",Config!$B$24) -> Delivery Note wajib ada nama penerima, ditandatangani dan distempel penerima. Jika di label tertera "SP Manual", maka dokumen SP Manual harus diminta ke penerima sesuai dengan jumlah PO yang butuh SP Manual. Apabila ada retur, catat di Delivery Note dan update ke IC | S9: =IF($AS9="","",TEXT(Config!$B$4,"yyyy-mm-dd")) -> 2026-08-18 | T9: =IF($AS9="","",Config!$B$17) -> 09:00 | U9: =IF($AS9="","",Config!$B$18) -> 22:00 | V9: =IF($AS9="","",Config!$B$19) -> Asia/Jakarta | W9: =IF($AS9="","",INDEX('TMP Paste'!$C$2:$C$1601,$AS9)) -> 0.53 | X9: =IF($AS9="","",Config!$B$29) -> FALSE | Y9: =IF($AT9="","",INDEX(Calc!$I$2:$I$1601,$AT9)&" - "&INDEX(Calc!$D$2:$D$1601,$AT9)&" koli") -> 26072800513343zU8ph3SKJ (1) - 1 koli | Z9: =IF($AS9="","",Config!$B$21) -> FALSE | AA9: =IF($AS9="","",Config!$B$22) -> RDO | AB9: =IF($AT9="","",INDEX(Calc!$D$2:$D$1601,$AT9)) -> 1 | AC9: =IF($AT9="","",INDEX(Calc!$G$2:$G$1601,$AT9)) -> 26072800513343zU8ph3SKJ-01 | AD9: =IF($AS9="","",Config!$B$23) -> 0 | AE9: =IF($AS9="","",Config!$B$28) -> 1 | AF9: =IF($AS9="","",IF(OR($AU9="",$AU9<=0,$AU9>=1000000),"",IF($AU9<10000,10,100))) -> 10 | AG9: =IF($AS9="","",IF(OR($AU9="",$AU9<=0,$AU9>=1000000),"",IF($AU9<10000,$AU9/100,IF($AU9<100000,$AU9/1000,$AU9/10000)))) -> 14.16 | AH9: =IF($AS9="","",IF(OR($AU9="",$AU9<=0,$AU9>=1000000),"",IF($AU9<100000,10,100))) -> 10 | AI9: =IF($AG9="","",SUMIF($AG$2:$AG9,$AG9,$AH$2:$AH9)) -> 10 | AJ9: =IF('TMP Paste'!$F9="","",IF('TMP Paste'!$B9="",$AJ8,'TMP Paste'!$B9)) | AK9: =IF('TMP Paste'!$F9="","",N('TMP Paste'!$G9)) | AL9: =IF('TMP Paste'!$F9="","",IF('TMP Paste'!$M9="",$AL8,'TMP Paste'!$M9)) | AM9: =IF('TMP Paste'!$F9="","",IF('TMP Paste'!$N9="",$AM8,'TMP Paste'!$N9)) | AN9: =IF('TMP Paste'!$F9="","",IF('TMP Paste'!$O9="",$AN8,'TMP Paste'!$O9)) | AO9: =IF('TMP Paste'!$F9="","",IF('TMP Paste'!$P9="",$AO8,'TMP Paste'!$P9)) | AP9: =IF($AG9="","",LEN($R9)) -> 266 | AQ9: =IF($AS9="","",TRIM(IF(COUNTIFS(Calc!$B$2:$B$1601,ROW()-1,Calc!$C$2:$C$1601,"<1")>0,"Ada PO tanpa Koli - cek TMP. ","")&IF(OR($AU9="",$AU9<=0),"Volume kosong/0 - dimensi dikosongkan. ","")&IF(AND($AU9<>"",$AU9>=1000000),"Volume >= 1.000.000 cm3 (di luar aturan) - dimensi dikosongkan. ","")&IF(LEN($R9)>500,"R > 500 karakter.",""))) | AS9: =IFERROR(MATCH(ROW()-1,Calc!$J$2:$J$1601,0),"") -> 19 | AT9: =IFERROR(MATCH(ROW()-1,Calc!$K$2:$K$1601,0),"") -> 19 | AU9: =IF($AS9="","",IFERROR(INDEX('TMP Paste'!$D$2:$D$1601,$AS9)*1000000/$AB9,"")) -> 1416
A10: =IF($AS10="","",INDEX('TMP Paste'!$B$2:$B$1601,$AS10)) -> AWB02WJ9B | B10: =IF($AS10="","",Config!$B$14) -> 11398423 | C10: =IF($AS10="","",Config!$B$15) -> Corporate B2B Bundle | D10: =IF($AS10="","",INDEX('TMP Paste'!$B$2:$B$1601,$AS10)) -> AWB02WJ9B | E10: =IF($AS10="","",Config!$B$27) -> STANDARD | F10: =IF($AS10="","",Config!$B$9) -> PT Teknologi Medika Pratama (SwipeRx) (B2BR) | G10: =IF($AS10="","",Config!$B$10) -> 087733785699 | H10: =IF($AS10="","",Config!$B$11) -> Jl. Tugu Raya, Tugu, Kec. Cimanggis, Kota Depok, Jawa Barat 16451,KUBIK LOGISTICS - Kompleks Pergudangan,Gudang E1 | I10: =IF($AS10="","",Config!$B$16) -> ID | J10: =IF($AS10="","",INDEX('TMP Paste'!$A$2:$A$1601,$AS10)) -> Apotek Bumi Sehat Serua Bojongsari | K10: =IF($AS10="","",INDEX('TMP Paste'!$L$2:$L$1601,$AS10)) -> 6281934028112 | L10: =IF($AS10="","",INDEX('TMP Paste'!$I$2:$I$1601,$AS10)) -> 11084-Jl. Serua Raya, Kel Serua Kec. Bojongsari, Kota Depok, 16517 | M10: =IF($AS10="","",Config!$B$16) -> ID | N10: =IF($AS10="","","") | O10: =IF($AS10="","",INDEX('TMP Paste'!$K$2:$K$1601,$AS10)) -> Kota Depok | P10: =IF($AS10="","","") | Q10: =IF($AS10="","",INDEX('TMP Paste'!$J$2:$J$1601,$AS10)) -> 16517 | R10: =IF($AS10="","",Config!$B$24) -> Delivery Note wajib ada nama penerima, ditandatangani dan distempel penerima. Jika di label tertera "SP Manual", maka dokumen SP Manual harus diminta ke penerima sesuai dengan jumlah PO yang butuh SP Manual. Apabila ada retur, catat di Delivery Note dan update ke IC | S10: =IF($AS10="","",TEXT(Config!$B$4,"yyyy-mm-dd")) -> 2026-08-18 | T10: =IF($AS10="","",Config!$B$17) -> 09:00 | U10: =IF($AS10="","",Config!$B$18) -> 22:00 | V10: =IF($AS10="","",Config!$B$19) -> Asia/Jakarta | W10: =IF($AS10="","",INDEX('TMP Paste'!$C$2:$C$1601,$AS10)) -> 0.44 | X10: =IF($AS10="","",Config!$B$29) -> FALSE | Y10: =IF($AT10="","",INDEX(Calc!$I$2:$I$1601,$AT10)&" - "&INDEX(Calc!$D$2:$D$1601,$AT10)&" koli") -> 26072707523848Dhpuftwa (1) - 1 koli | Z10: =IF($AS10="","",Config!$B$21) -> FALSE | AA10: =IF($AS10="","",Config!$B$22) -> RDO | AB10: =IF($AT10="","",INDEX(Calc!$D$2:$D$1601,$AT10)) -> 1 | AC10: =IF($AT10="","",INDEX(Calc!$G$2:$G$1601,$AT10)) -> 26072707523848Dhpuftwa-01 | AD10: =IF($AS10="","",Config!$B$23) -> 0 | AE10: =IF($AS10="","",Config!$B$28) -> 1 | AF10: =IF($AS10="","",IF(OR($AU10="",$AU10<=0,$AU10>=1000000),"",IF($AU10<10000,10,100))) -> 10 | AG10: =IF($AS10="","",IF(OR($AU10="",$AU10<=0,$AU10>=1000000),"",IF($AU10<10000,$AU10/100,IF($AU10<100000,$AU10/1000,$AU10/10000)))) -> 22.96 | AH10: =IF($AS10="","",IF(OR($AU10="",$AU10<=0,$AU10>=1000000),"",IF($AU10<100000,10,100))) -> 10 | AI10: =IF($AG10="","",SUMIF($AG$2:$AG10,$AG10,$AH$2:$AH10)) -> 10 | AJ10: =IF('TMP Paste'!$F10="","",IF('TMP Paste'!$B10="",$AJ9,'TMP Paste'!$B10)) | AK10: =IF('TMP Paste'!$F10="","",N('TMP Paste'!$G10)) | AL10: =IF('TMP Paste'!$F10="","",IF('TMP Paste'!$M10="",$AL9,'TMP Paste'!$M10)) | AM10: =IF('TMP Paste'!$F10="","",IF('TMP Paste'!$N10="",$AM9,'TMP Paste'!$N10)) | AN10: =IF('TMP Paste'!$F10="","",IF('TMP Paste'!$O10="",$AN9,'TMP Paste'!$O10)) | AO10: =IF('TMP Paste'!$F10="","",IF('TMP Paste'!$P10="",$AO9,'TMP Paste'!$P10)) | AP10: =IF($AG10="","",LEN($R10)) -> 266 | AQ10: =IF($AS10="","",TRIM(IF(COUNTIFS(Calc!$B$2:$B$1601,ROW()-1,Calc!$C$2:$C$1601,"<1")>0,"Ada PO tanpa Koli - cek TMP. ","")&IF(OR($AU10="",$AU10<=0),"Volume kosong/0 - dimensi dikosongkan. ","")&IF(AND($AU10<>"",$AU10>=1000000),"Volume >= 1.000.000 cm3 (di luar aturan) - dimensi dikosongkan. ","")&IF(LEN($R10)>500,"R > 500 karakter.",""))) | AS10: =IFERROR(MATCH(ROW()-1,Calc!$J$2:$J$1601,0),"") -> 20 | AT10: =IFERROR(MATCH(ROW()-1,Calc!$K$2:$K$1601,0),"") -> 20 | AU10: =IF($AS10="","",IFERROR(INDEX('TMP Paste'!$D$2:$D$1601,$AS10)*1000000/$AB10,"")) -> 2296
A11: =IF($AS11="","",INDEX('TMP Paste'!$B$2:$B$1601,$AS11)) -> AWB02WJJX | B11: =IF($AS11="","",Config!$B$14) -> 11398423 | C11: =IF($AS11="","",Config!$B$15) -> Corporate B2B Bundle | D11: =IF($AS11="","",INDEX('TMP Paste'!$B$2:$B$1601,$AS11)) -> AWB02WJJX | E11: =IF($AS11="","",Config!$B$27) -> STANDARD | F11: =IF($AS11="","",Config!$B$9) -> PT Teknologi Medika Pratama (SwipeRx) (B2BR) | G11: =IF($AS11="","",Config!$B$10) -> 087733785699 | H11: =IF($AS11="","",Config!$B$11) -> Jl. Tugu Raya, Tugu, Kec. Cimanggis, Kota Depok, Jawa Barat 16451,KUBIK LOGISTICS - Kompleks Pergudangan,Gudang E1 | I11: =IF($AS11="","",Config!$B$16) -> ID | J11: =IF($AS11="","",INDEX('TMP Paste'!$A$2:$A$1601,$AS11)) -> Apotek Bunda Bedahan Sawangan | K11: =IF($AS11="","",INDEX('TMP Paste'!$L$2:$L$1601,$AS11)) -> 6281382843554 | L11: =IF($AS11="","",INDEX('TMP Paste'!$I$2:$I$1601,$AS11)) -> 13593-Jl. H. Sulaiman No.06, RT004/RW007, Desa/Kelurahan Bedahan, Kec. Sawangan, Kota Depok | M11: =IF($AS11="","",Config!$B$16) -> ID | N11: =IF($AS11="","","") | O11: =IF($AS11="","",INDEX('TMP Paste'!$K$2:$K$1601,$AS11)) -> Kota Depok | P11: =IF($AS11="","","") | Q11: =IF($AS11="","",INDEX('TMP Paste'!$J$2:$J$1601,$AS11)) -> 16519 | R11: =IF($AS11="","",Config!$B$24) -> Delivery Note wajib ada nama penerima, ditandatangani dan distempel penerima. Jika di label tertera "SP Manual", maka dokumen SP Manual harus diminta ke penerima sesuai dengan jumlah PO yang butuh SP Manual. Apabila ada retur, catat di Delivery Note dan update ke IC | S11: =IF($AS11="","",TEXT(Config!$B$4,"yyyy-mm-dd")) -> 2026-08-18 | T11: =IF($AS11="","",Config!$B$17) -> 09:00 | U11: =IF($AS11="","",Config!$B$18) -> 22:00 | V11: =IF($AS11="","",Config!$B$19) -> Asia/Jakarta | W11: =IF($AS11="","",INDEX('TMP Paste'!$C$2:$C$1601,$AS11)) -> 1.05 | X11: =IF($AS11="","",Config!$B$29) -> FALSE | Y11: =IF($AT11="","",INDEX(Calc!$I$2:$I$1601,$AT11)&" - "&INDEX(Calc!$D$2:$D$1601,$AT11)&" koli") -> 26072710184801AQgMPUJcI (1) - 1 koli | Z11: =IF($AS11="","",Config!$B$21) -> FALSE | AA11: =IF($AS11="","",Config!$B$22) -> RDO | AB11: =IF($AT11="","",INDEX(Calc!$D$2:$D$1601,$AT11)) -> 1 | AC11: =IF($AT11="","",INDEX(Calc!$G$2:$G$1601,$AT11)) -> 26072710184801AQgMPUJcI-01 | AD11: =IF($AS11="","",Config!$B$23) -> 0 | AE11: =IF($AS11="","",Config!$B$28) -> 1 | AF11: =IF($AS11="","",IF(OR($AU11="",$AU11<=0,$AU11>=1000000),"",IF($AU11<10000,10,100))) -> 10 | AG11: =IF($AS11="","",IF(OR($AU11="",$AU11<=0,$AU11>=1000000),"",IF($AU11<10000,$AU11/100,IF($AU11<100000,$AU11/1000,$AU11/10000)))) -> 25.78 | AH11: =IF($AS11="","",IF(OR($AU11="",$AU11<=0,$AU11>=1000000),"",IF($AU11<100000,10,100))) -> 10 | AI11: =IF($AG11="","",SUMIF($AG$2:$AG11,$AG11,$AH$2:$AH11)) -> 10 | AJ11: =IF('TMP Paste'!$F11="","",IF('TMP Paste'!$B11="",$AJ10,'TMP Paste'!$B11)) | AK11: =IF('TMP Paste'!$F11="","",N('TMP Paste'!$G11)) | AL11: =IF('TMP Paste'!$F11="","",IF('TMP Paste'!$M11="",$AL10,'TMP Paste'!$M11)) | AM11: =IF('TMP Paste'!$F11="","",IF('TMP Paste'!$N11="",$AM10,'TMP Paste'!$N11)) | AN11: =IF('TMP Paste'!$F11="","",IF('TMP Paste'!$O11="",$AN10,'TMP Paste'!$O11)) | AO11: =IF('TMP Paste'!$F11="","",IF('TMP Paste'!$P11="",$AO10,'TMP Paste'!$P11)) | AP11: =IF($AG11="","",LEN($R11)) -> 266 | AQ11: =IF($AS11="","",TRIM(IF(COUNTIFS(Calc!$B$2:$B$1601,ROW()-1,Calc!$C$2:$C$1601,"<1")>0,"Ada PO tanpa Koli - cek TMP. ","")&IF(OR($AU11="",$AU11<=0),"Volume kosong/0 - dimensi dikosongkan. ","")&IF(AND($AU11<>"",$AU11>=1000000),"Volume >= 1.000.000 cm3 (di luar aturan) - dimensi dikosongkan. ","")&IF(LEN($R11)>500,"R > 500 karakter.",""))) | AS11: =IFERROR(MATCH(ROW()-1,Calc!$J$2:$J$1601,0),"") -> 21 | AT11: =IFERROR(MATCH(ROW()-1,Calc!$K$2:$K$1601,0),"") -> 21 | AU11: =IF($AS11="","",IFERROR(INDEX('TMP Paste'!$D$2:$D$1601,$AS11)*1000000/$AB11,"")) -> 2578
A12: =IF($AS12="","",INDEX('TMP Paste'!$B$2:$B$1601,$AS12)) -> AWB02WKTX | B12: =IF($AS12="","",Config!$B$14) -> 11398423 | C12: =IF($AS12="","",Config!$B$15) -> Corporate B2B Bundle | D12: =IF($AS12="","",INDEX('TMP Paste'!$B$2:$B$1601,$AS12)) -> AWB02WKTX | E12: =IF($AS12="","",Config!$B$27) -> STANDARD | F12: =IF($AS12="","",Config!$B$9) -> PT Teknologi Medika Pratama (SwipeRx) (B2BR) | G12: =IF($AS12="","",Config!$B$10) -> 087733785699 | H12: =IF($AS12="","",Config!$B$11) -> Jl. Tugu Raya, Tugu, Kec. Cimanggis, Kota Depok, Jawa Barat 16451,KUBIK LOGISTICS - Kompleks Pergudangan,Gudang E1 | I12: =IF($AS12="","",Config!$B$16) -> ID | J12: =IF($AS12="","",INDEX('TMP Paste'!$A$2:$A$1601,$AS12)) -> Apotek Cipayung 1 | K12: =IF($AS12="","",INDEX('TMP Paste'!$L$2:$L$1601,$AS12)) -> 81264043044 | L12: =IF($AS12="","",INDEX('TMP Paste'!$I$2:$I$1601,$AS12)) -> 8251-Jl. Raya Jembatan Serong Blok Sawo No. 115 RT. 002 RW. 003 Kel. Cipayung Kec. Cipayung Kota Depok | M12: =IF($AS12="","",Config!$B$16) -> ID | N12: =IF($AS12="","","") | O12: =IF($AS12="","",INDEX('TMP Paste'!$K$2:$K$1601,$AS12)) -> Kota Depok | P12: =IF($AS12="","","") | Q12: =IF($AS12="","",INDEX('TMP Paste'!$J$2:$J$1601,$AS12)) -> 16437 | R12: =IF($AS12="","",Config!$B$24) -> Delivery Note wajib ada nama penerima, ditandatangani dan distempel penerima. Jika di label tertera "SP Manual", maka dokumen SP Manual harus diminta ke penerima sesuai dengan jumlah PO yang butuh SP Manual. Apabila ada retur, catat di Delivery Note dan update ke IC | S12: =IF($AS12="","",TEXT(Config!$B$4,"yyyy-mm-dd")) -> 2026-08-18 | T12: =IF($AS12="","",Config!$B$17) -> 09:00 | U12: =IF($AS12="","",Config!$B$18) -> 22:00 | V12: =IF($AS12="","",Config!$B$19) -> Asia/Jakarta | W12: =IF($AS12="","",INDEX('TMP Paste'!$C$2:$C$1601,$AS12)) -> 9.89 | X12: =IF($AS12="","",Config!$B$29) -> FALSE | Y12: =IF($AT12="","",INDEX(Calc!$I$2:$I$1601,$AT12)&" - "&INDEX(Calc!$D$2:$D$1601,$AT12)&" koli") -> 260728014140360ppVZvbV (1), 26072801414037XH6dCj30sh (1), 260728015619662gr5Ce0Coa (1), 26072801561966LCCsOJtss (1) - 4 koli | Z12: =IF($AS12="","",Config!$B$21) -> FALSE | AA12: =IF($AS12="","",Config!$B$22) -> RDO | AB12: =IF($AT12="","",INDEX(Calc!$D$2:$D$1601,$AT12)) -> 4 | AC12: =IF($AT12="","",INDEX(Calc!$G$2:$G$1601,$AT12)) -> 260728014140360ppVZvbV-01, 26072801414037XH6dCj30sh-02, 260728015619662gr5Ce0Coa-03, 26072801561966LCCsOJtss-04 | AD12: =IF($AS12="","",Config!$B$23) -> 0 | AE12: =IF($AS12="","",Config!$B$28) -> 1 | AF12: =IF($AS12="","",IF(OR($AU12="",$AU12<=0,$AU12>=1000000),"",IF($AU12<10000,10,100))) -> 10 | AG12: =IF($AS12="","",IF(OR($AU12="",$AU12<=0,$AU12>=1000000),"",IF($AU12<10000,$AU12/100,IF($AU12<100000,$AU12/1000,$AU12/10000)))) -> 89.915 | AH12: =IF($AS12="","",IF(OR($AU12="",$AU12<=0,$AU12>=1000000),"",IF($AU12<100000,10,100))) -> 10 | AI12: =IF($AG12="","",SUMIF($AG$2:$AG12,$AG12,$AH$2:$AH12)) -> 10 | AJ12: =IF('TMP Paste'!$F12="","",IF('TMP Paste'!$B12="",$AJ11,'TMP Paste'!$B12)) -> AWB02WGVD | AK12: =IF('TMP Paste'!$F12="","",N('TMP Paste'!$G12)) -> 0 | AL12: =IF('TMP Paste'!$F12="","",IF('TMP Paste'!$M12="",$AL11,'TMP Paste'!$M12)) -> 1 | AM12: =IF('TMP Paste'!$F12="","",IF('TMP Paste'!$N12="",$AM11,'TMP Paste'!$N12)) | AN12: =IF('TMP Paste'!$F12="","",IF('TMP Paste'!$O12="",$AN11,'TMP Paste'!$O12)) | AO12: =IF('TMP Paste'!$F12="","",IF('TMP Paste'!$P12="",$AO11,'TMP Paste'!$P12)) | AP12: =IF($AG12="","",LEN($R12)) -> 266 | AQ12: =IF($AS12="","",TRIM(IF(COUNTIFS(Calc!$B$2:$B$1601,ROW()-1,Calc!$C$2:$C$1601,"<1")>0,"Ada PO tanpa Koli - cek TMP. ","")&IF(OR($AU12="",$AU12<=0),"Volume kosong/0 - dimensi dikosongkan. ","")&IF(AND($AU12<>"",$AU12>=1000000),"Volume >= 1.000.000 cm3 (di luar aturan) - dimensi dikosongkan. ","")&IF(LEN($R12)>500,"R > 500 karakter.",""))) | AS12: =IFERROR(MATCH(ROW()-1,Calc!$J$2:$J$1601,0),"") -> 22 | AT12: =IFERROR(MATCH(ROW()-1,Calc!$K$2:$K$1601,0),"") -> 25 | AU12: =IF($AS12="","",IFERROR(INDEX('TMP Paste'!$D$2:$D$1601,$AS12)*1000000/$AB12,"")) -> 8991.5
A13: =IF($AS13="","",INDEX('TMP Paste'!$B$2:$B$1601,$AS13)) -> AWB02WJMZ | B13: =IF($AS13="","",Config!$B$14) -> 11398423 | C13: =IF($AS13="","",Config!$B$15) -> Corporate B2B Bundle | D13: =IF($AS13="","",INDEX('TMP Paste'!$B$2:$B$1601,$AS13)) -> AWB02WJMZ | E13: =IF($AS13="","",Config!$B$27) -> STANDARD | F13: =IF($AS13="","",Config!$B$9) -> PT Teknologi Medika Pratama (SwipeRx) (B2BR) | G13: =IF($AS13="","",Config!$B$10) -> 087733785699 | H13: =IF($AS13="","",Config!$B$11) -> Jl. Tugu Raya, Tugu, Kec. Cimanggis, Kota Depok, Jawa Barat 16451,KUBIK LOGISTICS - Kompleks Pergudangan,Gudang E1 | I13: =IF($AS13="","",Config!$B$16) -> ID | J13: =IF($AS13="","",INDEX('TMP Paste'!$A$2:$A$1601,$AS13)) -> Apotek Cita Sehat Curug Bojongsari | K13: =IF($AS13="","",INDEX('TMP Paste'!$L$2:$L$1601,$AS13)) -> 6285220978760 | L13: =IF($AS13="","",INDEX('TMP Paste'!$I$2:$I$1601,$AS13)) -> 13096-Jl. Raya Curug Ciputat RT 001 RW 002 Kel. Curug Kec. Bojongsari Kota Depok | M13: =IF($AS13="","",Config!$B$16) -> ID | N13: =IF($AS13="","","") | O13: =IF($AS13="","",INDEX('TMP Paste'!$K$2:$K$1601,$AS13)) -> Kota Depok | P13: =IF($AS13="","","") | Q13: =IF($AS13="","",INDEX('TMP Paste'!$J$2:$J$1601,$AS13)) -> 16517 | R13: =IF($AS13="","",Config!$B$24) -> Delivery Note wajib ada nama penerima, ditandatangani dan distempel penerima. Jika di label tertera "SP Manual", maka dokumen SP Manual harus diminta ke penerima sesuai dengan jumlah PO yang butuh SP Manual. Apabila ada retur, catat di Delivery Note dan update ke IC | S13: =IF($AS13="","",TEXT(Config!$B$4,"yyyy-mm-dd")) -> 2026-08-18 | T13: =IF($AS13="","",Config!$B$17) -> 09:00 | U13: =IF($AS13="","",Config!$B$18) -> 22:00 | V13: =IF($AS13="","",Config!$B$19) -> Asia/Jakarta | W13: =IF($AS13="","",INDEX('TMP Paste'!$C$2:$C$1601,$AS13)) -> 7.39 | X13: =IF($AS13="","",Config!$B$29) -> FALSE | Y13: =IF($AT13="","",INDEX(Calc!$I$2:$I$1601,$AT13)&" - "&INDEX(Calc!$D$2:$D$1601,$AT13)&" koli") -> 26072711371829bD90OfAG (1), 26072711371829hZImrWHPpe (1), 26072711371829MedkSjEjj (1) - 3 koli | Z13: =IF($AS13="","",Config!$B$21) -> FALSE | AA13: =IF($AS13="","",Config!$B$22) -> RDO | AB13: =IF($AT13="","",INDEX(Calc!$D$2:$D$1601,$AT13)) -> 3 | AC13: =IF($AT13="","",INDEX(Calc!$G$2:$G$1601,$AT13)) -> 26072711371829bD90OfAG-01, 26072711371829hZImrWHPpe-02, 26072711371829MedkSjEjj-03 | AD13: =IF($AS13="","",Config!$B$23) -> 0 | AE13: =IF($AS13="","",Config!$B$28) -> 1 | AF13: =IF($AS13="","",IF(OR($AU13="",$AU13<=0,$AU13>=1000000),"",IF($AU13<10000,10,100))) -> 100 | AG13: =IF($AS13="","",IF(OR($AU13="",$AU13<=0,$AU13>=1000000),"",IF($AU13<10000,$AU13/100,IF($AU13<100000,$AU13/1000,$AU13/10000)))) -> 11.738667 | AH13: =IF($AS13="","",IF(OR($AU13="",$AU13<=0,$AU13>=1000000),"",IF($AU13<100000,10,100))) -> 10 | AI13: =IF($AG13="","",SUMIF($AG$2:$AG13,$AG13,$AH$2:$AH13)) -> 10 | AJ13: =IF('TMP Paste'!$F13="","",IF('TMP Paste'!$B13="",$AJ12,'TMP Paste'!$B13)) | AK13: =IF('TMP Paste'!$F13="","",N('TMP Paste'!$G13)) | AL13: =IF('TMP Paste'!$F13="","",IF('TMP Paste'!$M13="",$AL12,'TMP Paste'!$M13)) | AM13: =IF('TMP Paste'!$F13="","",IF('TMP Paste'!$N13="",$AM12,'TMP Paste'!$N13)) | AN13: =IF('TMP Paste'!$F13="","",IF('TMP Paste'!$O13="",$AN12,'TMP Paste'!$O13)) | AO13: =IF('TMP Paste'!$F13="","",IF('TMP Paste'!$P13="",$AO12,'TMP Paste'!$P13)) | AP13: =IF($AG13="","",LEN($R13)) -> 266 | AQ13: =IF($AS13="","",TRIM(IF(COUNTIFS(Calc!$B$2:$B$1601,ROW()-1,Calc!$C$2:$C$1601,"<1")>0,"Ada PO tanpa Koli - cek TMP. ","")&IF(OR($AU13="",$AU13<=0),"Volume kosong/0 - dimensi dikosongkan. ","")&IF(AND($AU13<>"",$AU13>=1000000),"Volume >= 1.000.000 cm3 (di luar aturan) - dimensi dikosongkan. ","")&IF(LEN($R13)>500,"R > 500 karakter.",""))) | AS13: =IFERROR(MATCH(ROW()-1,Calc!$J$2:$J$1601,0),"") -> 26 | AT13: =IFERROR(MATCH(ROW()-1,Calc!$K$2:$K$1601,0),"") -> 28 | AU13: =IF($AS13="","",IFERROR(INDEX('TMP Paste'!$D$2:$D$1601,$AS13)*1000000/$AB13,"")) -> 11738.667
